2022-01-18 13:22:59,832 - util.py[DEBUG]: Cloud-init v. 0.7.9 running 'init-local' at Tue, 18 Jan 2022 13:22:59 +0000. Up 7.58 seconds.
2022-01-18 13:22:59,837 - util.py[DEBUG]: Restoring selinux mode for /var/lib/cloud (recursive=False)
2022-01-18 13:22:59,838 - util.py[DEBUG]: Restoring selinux mode for /var/lib/cloud (recursive=True)
2022-01-18 13:22:59,838 - util.py[DEBUG]: Restoring selinux mode for /var/lib/cloud/scripts (recursive=False)
2022-01-18 13:22:59,839 - util.py[DEBUG]: Restoring selinux mode for /var/lib/cloud/scripts (recursive=True)
2022-01-18 13:22:59,840 - util.py[DEBUG]: Restoring selinux mode for /var/lib/cloud/scripts/per-instance (recursive=False)
2022-01-18 13:22:59,840 - util.py[DEBUG]: Restoring selinux mode for /var/lib/cloud/scripts (recursive=True)
2022-01-18 13:22:59,841 - util.py[DEBUG]: Restoring selinux mode for /var/lib/cloud/scripts/per-once (recursive=False)
2022-01-18 13:22:59,841 - util.py[DEBUG]: Restoring selinux mode for /var/lib/cloud/scripts (recursive=True)
2022-01-18 13:22:59,844 - util.py[DEBUG]: Restoring selinux mode for /var/lib/cloud/scripts/per-boot (recursive=False)
2022-01-18 13:22:59,845 - util.py[DEBUG]: Restoring selinux mode for /var/lib/cloud/scripts (recursive=True)
2022-01-18 13:22:59,846 - util.py[DEBUG]: Restoring selinux mode for /var/lib/cloud/scripts/vendor (recursive=False)
2022-01-18 13:22:59,847 - util.py[DEBUG]: Restoring selinux mode for /var/lib/cloud (recursive=True)
2022-01-18 13:22:59,848 - util.py[DEBUG]: Restoring selinux mode for /var/lib/cloud/seed (recursive=False)
2022-01-18 13:22:59,849 - util.py[DEBUG]: Restoring selinux mode for /var/lib/cloud (recursive=True)
2022-01-18 13:22:59,851 - util.py[DEBUG]: Restoring selinux mode for /var/lib/cloud/instances (recursive=False)
2022-01-18 13:22:59,851 - util.py[DEBUG]: Restoring selinux mode for /var/lib/cloud (recursive=True)
2022-01-18 13:22:59,853 - util.py[DEBUG]: Restoring selinux mode for /var/lib/cloud/handlers (recursive=False)
2022-01-18 13:22:59,853 - util.py[DEBUG]: Restoring selinux mode for /var/lib/cloud (recursive=True)
2022-01-18 13:22:59,855 - util.py[DEBUG]: Restoring selinux mode for /var/lib/cloud/sem (recursive=False)
2022-01-18 13:22:59,856 - util.py[DEBUG]: Restoring selinux mode for /var/lib/cloud/data (recursive=False)
2022-01-18 13:22:59,856 - util.py[DEBUG]: Writing to /var/log/cloud-init.log - ab: [384] 0 bytes
2022-01-18 13:22:59,857 - util.py[DEBUG]: Restoring selinux mode for /var/log/cloud-init.log (recursive=False)
2022-01-18 13:22:59,857 - util.py[DEBUG]: Restoring selinux mode for /var/log/cloud-init.log (recursive=False)
2022-01-18 13:22:59,858 - util.py[DEBUG]: Attempting to remove /var/lib/cloud/instance/boot-finished
2022-01-18 13:22:59,858 - util.py[DEBUG]: Attempting to remove /var/lib/cloud/data/no-net
2022-01-18 13:22:59,858 - handlers.py[DEBUG]: start: init-local/check-cache: attempting to read from cache [check]
2022-01-18 13:22:59,858 - util.py[DEBUG]: Reading from /var/lib/cloud/instance/obj.pkl (quiet=False)
2022-01-18 13:22:59,858 - stages.py[DEBUG]: no cache found
2022-01-18 13:22:59,858 - handlers.py[DEBUG]: finish: init-local/check-cache: SUCCESS: no cache found
2022-01-18 13:22:59,858 - util.py[DEBUG]: Attempting to remove /var/lib/cloud/instance
2022-01-18 13:22:59,879 - stages.py[DEBUG]: Using distro class <class 'cloudinit.distros.rhel.Distro'>
2022-01-18 13:22:59,879 - __init__.py[DEBUG]: Looking for for data source in: ['NoCloud', 'ConfigDrive', 'OpenNebula', 'DigitalOcean', 'Azure', 'AltCloud', 'OVF', 'MAAS', 'GCE', 'OpenStack', 'AliYun', 'Ec2', 'CloudSigma', 'CloudStack', 'SmartOS', 'Bigstep', 'None'], via packages ['', u'cloudinit.sources'] that matches dependencies ['FILESYSTEM']
2022-01-18 13:23:00,011 - __init__.py[DEBUG]: Searching for local data source in: [u'DataSourceNoCloud', u'DataSourceConfigDrive', u'DataSourceOpenNebula', u'DataSourceDigitalOcean', u'DataSourceOVF', u'DataSourceCloudSigma', u'DataSourceSmartOS']
2022-01-18 13:23:00,012 - handlers.py[DEBUG]: start: init-local/search-NoCloud: searching for local data from DataSourceNoCloud
2022-01-18 13:23:00,012 - __init__.py[DEBUG]: Seeing if we can get any data from <class 'cloudinit.sources.DataSourceNoCloud.DataSourceNoCloud'>
2022-01-18 13:23:00,012 - util.py[DEBUG]: Reading from /var/lib/cloud/seed/nocloud/user-data (quiet=False)
2022-01-18 13:23:00,012 - util.py[DEBUG]: Reading from /var/lib/cloud/seed/nocloud/meta-data (quiet=False)
2022-01-18 13:23:00,012 - util.py[DEBUG]: Reading from /var/lib/cloud/seed/nocloud/vendor-data (quiet=False)
2022-01-18 13:23:00,012 - util.py[DEBUG]: Reading from /var/lib/cloud/seed/nocloud/network-config (quiet=False)
2022-01-18 13:23:00,012 - util.py[DEBUG]: Reading from /var/lib/cloud/seed/nocloud-net/user-data (quiet=False)
2022-01-18 13:23:00,012 - util.py[DEBUG]: Reading from /var/lib/cloud/seed/nocloud-net/meta-data (quiet=False)
2022-01-18 13:23:00,013 - util.py[DEBUG]: Reading from /var/lib/cloud/seed/nocloud-net/vendor-data (quiet=False)
2022-01-18 13:23:00,013 - util.py[DEBUG]: Reading from /var/lib/cloud/seed/nocloud-net/network-config (quiet=False)
2022-01-18 13:23:00,013 - util.py[DEBUG]: Running command ['blkid', '-odevice', '/dev/sr0'] with allowed return codes [0, 2] (shell=False, capture=True)
2022-01-18 13:23:00,020 - util.py[DEBUG]: Running command ['blkid', '-odevice', '/dev/sr1'] with allowed return codes [0, 2] (shell=False, capture=True)
2022-01-18 13:23:00,022 - util.py[DEBUG]: Running command ['blkid', '-tTYPE=vfat', '-odevice'] with allowed return codes [0, 2] (shell=False, capture=True)
2022-01-18 13:23:00,051 - util.py[DEBUG]: Running command ['blkid', '-tTYPE=iso9660', '-odevice'] with allowed return codes [0, 2] (shell=False, capture=True)
2022-01-18 13:23:00,053 - util.py[DEBUG]: Running command ['blkid', '-tLABEL=cidata', '-odevice'] with allowed return codes [0, 2] (shell=False, capture=True)
2022-01-18 13:23:00,056 - handlers.py[DEBUG]: finish: init-local/search-NoCloud: SUCCESS: no local data found from DataSourceNoCloud
2022-01-18 13:23:00,056 - handlers.py[DEBUG]: start: init-local/search-ConfigDrive: searching for local data from DataSourceConfigDrive
2022-01-18 13:23:00,056 - __init__.py[DEBUG]: Seeing if we can get any data from <class 'cloudinit.sources.DataSourceConfigDrive.DataSourceConfigDrive'>
2022-01-18 13:23:00,056 - util.py[DEBUG]: Running command ['blkid', '-odevice', '/dev/sr0'] with allowed return codes [0, 2] (shell=False, capture=True)
2022-01-18 13:23:00,059 - util.py[DEBUG]: Running command ['blkid', '-odevice', '/dev/sr1'] with allowed return codes [0, 2] (shell=False, capture=True)
2022-01-18 13:23:00,061 - util.py[DEBUG]: Running command ['blkid', '-odevice', '/dev/cd0'] with allowed return codes [0, 2] (shell=False, capture=True)
2022-01-18 13:23:00,063 - util.py[DEBUG]: Running command ['blkid', '-odevice', '/dev/cd1'] with allowed return codes [0, 2] (shell=False, capture=True)
2022-01-18 13:23:00,065 - util.py[DEBUG]: Running command ['blkid', '-tTYPE=vfat', '-odevice'] with allowed return codes [0, 2] (shell=False, capture=True)
2022-01-18 13:23:00,068 - util.py[DEBUG]: Running command ['blkid', '-tTYPE=iso9660', '-odevice'] with allowed return codes [0, 2] (shell=False, capture=True)
2022-01-18 13:23:00,070 - util.py[DEBUG]: Running command ['blkid', '-tLABEL=config-2', '-odevice'] with allowed return codes [0, 2] (shell=False, capture=True)
2022-01-18 13:23:00,073 - handlers.py[DEBUG]: finish: init-local/search-ConfigDrive: SUCCESS: no local data found from DataSourceConfigDrive
2022-01-18 13:23:00,073 - handlers.py[DEBUG]: start: init-local/search-OpenNebula: searching for local data from DataSourceOpenNebula
2022-01-18 13:23:00,073 - __init__.py[DEBUG]: Seeing if we can get any data from <class 'cloudinit.sources.DataSourceOpenNebula.DataSourceOpenNebula'>
2022-01-18 13:23:00,073 - util.py[DEBUG]: Running command ['blkid', '-tLABEL=CONTEXT', '-odevice'] with allowed return codes [0, 2] (shell=False, capture=True)
2022-01-18 13:23:00,076 - util.py[DEBUG]: Running command ['blkid', '-tLABEL=CDROM', '-odevice'] with allowed return codes [0, 2] (shell=False, capture=True)
2022-01-18 13:23:00,078 - util.py[DEBUG]: Running command ['blkid', '-tTYPE=iso9660', '-odevice'] with allowed return codes [0, 2] (shell=False, capture=True)
2022-01-18 13:23:00,081 - handlers.py[DEBUG]: finish: init-local/search-OpenNebula: SUCCESS: no local data found from DataSourceOpenNebula
2022-01-18 13:23:00,082 - handlers.py[DEBUG]: start: init-local/search-DigitalOcean: searching for local data from DataSourceDigitalOcean
2022-01-18 13:23:00,082 - __init__.py[DEBUG]: Seeing if we can get any data from <class 'cloudinit.sources.DataSourceDigitalOcean.DataSourceDigitalOcean'>
2022-01-18 13:23:00,082 - util.py[DEBUG]: querying dmi data /sys/class/dmi/id/sys_vendor
2022-01-18 13:23:00,082 - util.py[DEBUG]: Reading from /sys/class/dmi/id/sys_vendor (quiet=False)
2022-01-18 13:23:00,082 - util.py[DEBUG]: Read 4 bytes from /sys/class/dmi/id/sys_vendor
2022-01-18 13:23:00,083 - util.py[DEBUG]: dmi data /sys/class/dmi/id/sys_vendor returned Xen
2022-01-18 13:23:00,083 - handlers.py[DEBUG]: finish: init-local/search-DigitalOcean: SUCCESS: no local data found from DataSourceDigitalOcean
2022-01-18 13:23:00,083 - handlers.py[DEBUG]: start: init-local/search-OVF: searching for local data from DataSourceOVF
2022-01-18 13:23:00,083 - __init__.py[DEBUG]: Seeing if we can get any data from <class 'cloudinit.sources.DataSourceOVF.DataSourceOVF'>
2022-01-18 13:23:00,083 - util.py[DEBUG]: querying dmi data /sys/class/dmi/id/product_name
2022-01-18 13:23:00,083 - util.py[DEBUG]: Reading from /sys/class/dmi/id/product_name (quiet=False)
2022-01-18 13:23:00,083 - util.py[DEBUG]: Read 9 bytes from /sys/class/dmi/id/product_name
2022-01-18 13:23:00,083 - util.py[DEBUG]: dmi data /sys/class/dmi/id/product_name returned HVM domU
2022-01-18 13:23:00,084 - util.py[DEBUG]: Reading from /proc/mounts (quiet=False)
2022-01-18 13:23:00,084 - util.py[DEBUG]: Read 2221 bytes from /proc/mounts
2022-01-18 13:23:00,084 - util.py[DEBUG]: Fetched {'configfs': {'mountpoint': '/sys/kernel/config', 'opts': 'rw,relatime', 'fstype': 'configfs'}, 'devpts': {'mountpoint': '/dev/pts', 'opts': 'rw,seclabel,nosuid,noexec,relatime,gid=5,mode=620,ptmxmode=000', 'fstype': 'devpts'}, 'debugfs': {'mountpoint': '/sys/kernel/debug', 'opts': 'rw,relatime', 'fstype': 'debugfs'}, 'securityfs': {'mountpoint': '/sys/kernel/security', 'opts': 'rw,nosuid,nodev,noexec,relatime', 'fstype': 'securityfs'}, 'sysfs': {'mountpoint': '/sys', 'opts': 'rw,seclabel,nosuid,nodev,noexec,relatime', 'fstype': 'sysfs'}, 'mqueue': {'mountpoint': '/dev/mqueue', 'opts': 'rw,seclabel,relatime', 'fstype': 'mqueue'}, 'pstore': {'mountpoint': '/sys/fs/pstore', 'opts': 'rw,nosuid,nodev,noexec,relatime', 'fstype': 'pstore'}, 'rpc_pipefs': {'mountpoint': '/var/lib/nfs/rpc_pipefs', 'opts': 'rw,relatime', 'fstype': 'rpc_pipefs'}, 'hugetlbfs': {'mountpoint': '/dev/hugepages', 'opts': 'rw,seclabel,relatime', 'fstype': 'hugetlbfs'}, '/dev/xvda1': {'mountpoint': '/', 'opts': 'rw,seclabel,relatime,attr2,inode64,noquota', 'fstype': 'xfs'}, 'systemd-1': {'mountpoint': '/proc/sys/fs/binfmt_misc', 'opts': 'rw,relatime,fd=32,pgrp=1,timeout=0,minproto=5,maxproto=5,direct,pipe_ino=13070', 'fstype': 'autofs'}, 'cgroup': {'mountpoint': '/sys/fs/cgroup/memory', 'opts': 'rw,seclabel,nosuid,nodev,noexec,relatime,memory', 'fstype': 'cgroup'}, 'tmpfs': {'mountpoint': '/sys/fs/cgroup', 'opts': 'ro,seclabel,nosuid,nodev,noexec,mode=755', 'fstype': 'tmpfs'}, 'proc': {'mountpoint': '/proc', 'opts': 'rw,nosuid,nodev,noexec,relatime', 'fstype': 'proc'}, 'devtmpfs': {'mountpoint': '/dev', 'opts': 'rw,seclabel,nosuid,size=226316k,nr_inodes=56579,mode=755', 'fstype': 'devtmpfs'}, 'selinuxfs': {'mountpoint': '/sys/fs/selinux', 'opts': 'rw,relatime', 'fstype': 'selinuxfs'}, 'rootfs': {'mountpoint': '/', 'opts': 'rw', 'fstype': 'rootfs'}} mounts from proc
2022-01-18 13:23:00,085 - util.py[DEBUG]: Peeking at /dev/xvda (max_bytes=512)
2022-01-18 13:23:00,085 - util.py[DEBUG]: Reading from /proc/mounts (quiet=False)
2022-01-18 13:23:00,085 - util.py[DEBUG]: Read 2221 bytes from /proc/mounts
2022-01-18 13:23:00,085 - util.py[DEBUG]: Fetched {'configfs': {'mountpoint': '/sys/kernel/config', 'opts': 'rw,relatime', 'fstype': 'configfs'}, 'devpts': {'mountpoint': '/dev/pts', 'opts': 'rw,seclabel,nosuid,noexec,relatime,gid=5,mode=620,ptmxmode=000', 'fstype': 'devpts'}, 'debugfs': {'mountpoint': '/sys/kernel/debug', 'opts': 'rw,relatime', 'fstype': 'debugfs'}, 'securityfs': {'mountpoint': '/sys/kernel/security', 'opts': 'rw,nosuid,nodev,noexec,relatime', 'fstype': 'securityfs'}, 'sysfs': {'mountpoint': '/sys', 'opts': 'rw,seclabel,nosuid,nodev,noexec,relatime', 'fstype': 'sysfs'}, 'mqueue': {'mountpoint': '/dev/mqueue', 'opts': 'rw,seclabel,relatime', 'fstype': 'mqueue'}, 'pstore': {'mountpoint': '/sys/fs/pstore', 'opts': 'rw,nosuid,nodev,noexec,relatime', 'fstype': 'pstore'}, 'rpc_pipefs': {'mountpoint': '/var/lib/nfs/rpc_pipefs', 'opts': 'rw,relatime', 'fstype': 'rpc_pipefs'}, 'hugetlbfs': {'mountpoint': '/dev/hugepages', 'opts': 'rw,seclabel,relatime', 'fstype': 'hugetlbfs'}, '/dev/xvda1': {'mountpoint': '/', 'opts': 'rw,seclabel,relatime,attr2,inode64,noquota', 'fstype': 'xfs'}, 'systemd-1': {'mountpoint': '/proc/sys/fs/binfmt_misc', 'opts': 'rw,relatime,fd=32,pgrp=1,timeout=0,minproto=5,maxproto=5,direct,pipe_ino=13070', 'fstype': 'autofs'}, 'cgroup': {'mountpoint': '/sys/fs/cgroup/memory', 'opts': 'rw,seclabel,nosuid,nodev,noexec,relatime,memory', 'fstype': 'cgroup'}, 'tmpfs': {'mountpoint': '/sys/fs/cgroup', 'opts': 'ro,seclabel,nosuid,nodev,noexec,mode=755', 'fstype': 'tmpfs'}, 'proc': {'mountpoint': '/proc', 'opts': 'rw,nosuid,nodev,noexec,relatime', 'fstype': 'proc'}, 'devtmpfs': {'mountpoint': '/dev', 'opts': 'rw,seclabel,nosuid,size=226316k,nr_inodes=56579,mode=755', 'fstype': 'devtmpfs'}, 'selinuxfs': {'mountpoint': '/sys/fs/selinux', 'opts': 'rw,relatime', 'fstype': 'selinuxfs'}, 'rootfs': {'mountpoint': '/', 'opts': 'rw', 'fstype': 'rootfs'}} mounts from proc
2022-01-18 13:23:00,086 - util.py[DEBUG]: Running command ['mount', '-o', 'ro,sync', '-t', 'iso9660', '/dev/xvda', '/tmp/tmp6yWCbS'] with allowed return codes [0] (shell=False, capture=True)
2022-01-18 13:23:00,114 - util.py[DEBUG]: Failed mount of '/dev/xvda' as 'iso9660': Unexpected error while running command.
Command: ['mount', '-o', 'ro,sync', '-t', 'iso9660', '/dev/xvda', '/tmp/tmp6yWCbS']
Exit code: 32
Reason: -
Stdout: -
Stderr: mount: /dev/xvda is already mounted or /tmp/tmp6yWCbS busy
2022-01-18 13:23:00,114 - util.py[DEBUG]: Recursively deleting /tmp/tmp6yWCbS
2022-01-18 13:23:00,115 - DataSourceOVF.py[DEBUG]: /dev/xvda not mountable as iso9660
2022-01-18 13:23:00,115 - handlers.py[DEBUG]: finish: init-local/search-OVF: SUCCESS: no local data found from DataSourceOVF
2022-01-18 13:23:00,115 - handlers.py[DEBUG]: start: init-local/search-CloudSigma: searching for local data from DataSourceCloudSigma
2022-01-18 13:23:00,115 - __init__.py[DEBUG]: Seeing if we can get any data from <class 'cloudinit.sources.DataSourceCloudSigma.DataSourceCloudSigma'>
2022-01-18 13:23:00,115 - DataSourceCloudSigma.py[DEBUG]: determining hypervisor product name via dmi data
2022-01-18 13:23:00,115 - util.py[DEBUG]: querying dmi data /sys/class/dmi/id/product_name
2022-01-18 13:23:00,115 - util.py[DEBUG]: Reading from /sys/class/dmi/id/product_name (quiet=False)
2022-01-18 13:23:00,116 - util.py[DEBUG]: Read 9 bytes from /sys/class/dmi/id/product_name
2022-01-18 13:23:00,116 - util.py[DEBUG]: dmi data /sys/class/dmi/id/product_name returned HVM domU
2022-01-18 13:23:00,116 - DataSourceCloudSigma.py[DEBUG]: detected hypervisor as HVM domU
2022-01-18 13:23:00,116 - handlers.py[DEBUG]: finish: init-local/search-CloudSigma: SUCCESS: no local data found from DataSourceCloudSigma
2022-01-18 13:23:00,116 - handlers.py[DEBUG]: start: init-local/search-SmartOS: searching for local data from DataSourceSmartOS
2022-01-18 13:23:00,116 - __init__.py[DEBUG]: Seeing if we can get any data from <class 'cloudinit.sources.DataSourceSmartOS.DataSourceSmartOS'>
2022-01-18 13:23:00,116 - util.py[DEBUG]: querying dmi data /sys/class/dmi/id/product_name
2022-01-18 13:23:00,116 - util.py[DEBUG]: Reading from /sys/class/dmi/id/product_name (quiet=False)
2022-01-18 13:23:00,116 - util.py[DEBUG]: Read 9 bytes from /sys/class/dmi/id/product_name
2022-01-18 13:23:00,116 - util.py[DEBUG]: dmi data /sys/class/dmi/id/product_name returned HVM domU
2022-01-18 13:23:00,117 - DataSourceSmartOS.py[DEBUG]: Not running on smartos
2022-01-18 13:23:00,117 - handlers.py[DEBUG]: finish: init-local/search-SmartOS: SUCCESS: no local data found from DataSourceSmartOS
2022-01-18 13:23:00,117 - main.py[DEBUG]: No local datasource found
2022-01-18 13:23:00,117 - util.py[DEBUG]: Reading from /sys/class/net/eth0/carrier (quiet=False)
2022-01-18 13:23:00,117 - util.py[DEBUG]: Reading from /sys/class/net/eth0/dormant (quiet=False)
2022-01-18 13:23:00,118 - util.py[DEBUG]: Reading from /sys/class/net/eth0/operstate (quiet=False)
2022-01-18 13:23:00,118 - util.py[DEBUG]: Read 5 bytes from /sys/class/net/eth0/operstate
2022-01-18 13:23:00,118 - util.py[DEBUG]: Reading from /sys/class/net/eth0/address (quiet=False)
2022-01-18 13:23:00,118 - util.py[DEBUG]: Read 18 bytes from /sys/class/net/eth0/address
2022-01-18 13:23:00,118 - stages.py[DEBUG]: applying net config names for {'version': 1, 'config': [{'subnets': [{'type': 'dhcp'}], 'type': 'physical', 'name': 'eth0', 'mac_address': '0e:ad:97:9c:af:97'}]}
2022-01-18 13:23:00,118 - util.py[DEBUG]: Reading from /sys/class/net/eth0/addr_assign_type (quiet=False)
2022-01-18 13:23:00,118 - util.py[DEBUG]: Read 2 bytes from /sys/class/net/eth0/addr_assign_type
2022-01-18 13:23:00,118 - util.py[DEBUG]: Reading from /sys/class/net/eth0/address (quiet=False)
2022-01-18 13:23:00,118 - util.py[DEBUG]: Read 18 bytes from /sys/class/net/eth0/address
2022-01-18 13:23:00,119 - util.py[DEBUG]: Reading from /sys/class/net/lo/addr_assign_type (quiet=False)
2022-01-18 13:23:00,119 - util.py[DEBUG]: Read 2 bytes from /sys/class/net/lo/addr_assign_type
2022-01-18 13:23:00,119 - util.py[DEBUG]: Reading from /sys/class/net/lo/address (quiet=False)
2022-01-18 13:23:00,119 - util.py[DEBUG]: Read 18 bytes from /sys/class/net/lo/address
2022-01-18 13:23:00,119 - util.py[DEBUG]: Reading from /sys/class/net/eth0/operstate (quiet=False)
2022-01-18 13:23:00,119 - util.py[DEBUG]: Read 5 bytes from /sys/class/net/eth0/operstate
2022-01-18 13:23:00,119 - util.py[DEBUG]: Reading from /sys/class/net/lo/operstate (quiet=False)
2022-01-18 13:23:00,119 - util.py[DEBUG]: Read 8 bytes from /sys/class/net/lo/operstate
2022-01-18 13:23:00,120 - util.py[DEBUG]: Running command ['ip', '-6', 'addr', 'show', 'permanent', 'scope', 'global'] with allowed return codes [0] (shell=False, capture=True)
2022-01-18 13:23:00,129 - util.py[DEBUG]: Running command ['ip', '-4', 'addr', 'show'] with allowed return codes [0] (shell=False, capture=True)
2022-01-18 13:23:00,132 - __init__.py[DEBUG]: no work necessary for renaming of [['0e:ad:97:9c:af:97', 'eth0']]
2022-01-18 13:23:00,132 - stages.py[INFO]: Applying network configuration from fallback bringup=False: {'version': 1, 'config': [{'subnets': [{'type': 'dhcp'}], 'type': 'physical', 'name': 'eth0', 'mac_address': '0e:ad:97:9c:af:97'}]}
2022-01-18 13:23:00,135 - util.py[DEBUG]: Writing to /etc/sysconfig/network-scripts/ifcfg-eth0 - wb: [420] 159 bytes
2022-01-18 13:23:00,136 - util.py[DEBUG]: Restoring selinux mode for /etc/sysconfig/network-scripts/ifcfg-eth0 (recursive=False)
2022-01-18 13:23:00,136 - util.py[DEBUG]: Restoring selinux mode for /etc/sysconfig/network-scripts/ifcfg-eth0 (recursive=False)
2022-01-18 13:23:00,136 - util.py[DEBUG]: Reading from /etc/resolv.conf (quiet=False)
2022-01-18 13:23:00,136 - util.py[DEBUG]: Read 50 bytes from /etc/resolv.conf
2022-01-18 13:23:00,137 - util.py[DEBUG]: Writing to /etc/resolv.conf - wb: [420] 121 bytes
2022-01-18 13:23:00,137 - util.py[DEBUG]: Restoring selinux mode for /etc/resolv.conf (recursive=False)
2022-01-18 13:23:00,137 - util.py[DEBUG]: Restoring selinux mode for /etc/resolv.conf (recursive=False)
2022-01-18 13:23:00,138 - util.py[DEBUG]: Writing to /etc/udev/rules.d/70-persistent-net.rules - wb: [420] 96 bytes
2022-01-18 13:23:00,138 - util.py[DEBUG]: Restoring selinux mode for /etc/udev/rules.d/70-persistent-net.rules (recursive=False)
2022-01-18 13:23:00,138 - util.py[DEBUG]: Restoring selinux mode for /etc/udev/rules.d/70-persistent-net.rules (recursive=False)
2022-01-18 13:23:00,139 - main.py[DEBUG]: [local] Exiting without datasource in local mode
2022-01-18 13:23:00,139 - util.py[DEBUG]: Reading from /proc/uptime (quiet=False)
2022-01-18 13:23:00,139 - util.py[DEBUG]: Read 10 bytes from /proc/uptime
2022-01-18 13:23:00,139 - util.py[DEBUG]: cloud-init mode 'init' took 0.734 seconds (0.74)
2022-01-18 13:23:00,139 - handlers.py[DEBUG]: finish: init-local: SUCCESS: searching for local datasources
2022-01-18 13:23:03,302 - util.py[DEBUG]: Cloud-init v. 0.7.9 running 'init' at Tue, 18 Jan 2022 13:23:03 +0000. Up 11.43 seconds.
2022-01-18 13:23:03,303 - util.py[DEBUG]: Restoring selinux mode for /var/lib/cloud (recursive=False)
2022-01-18 13:23:03,303 - util.py[DEBUG]: Restoring selinux mode for /var/lib/cloud/scripts (recursive=False)
2022-01-18 13:23:03,304 - util.py[DEBUG]: Restoring selinux mode for /var/lib/cloud/scripts/per-instance (recursive=False)
2022-01-18 13:23:03,304 - util.py[DEBUG]: Restoring selinux mode for /var/lib/cloud/scripts/per-once (recursive=False)
2022-01-18 13:23:03,304 - util.py[DEBUG]: Restoring selinux mode for /var/lib/cloud/scripts/per-boot (recursive=False)
2022-01-18 13:23:03,305 - util.py[DEBUG]: Restoring selinux mode for /var/lib/cloud/scripts/vendor (recursive=False)
2022-01-18 13:23:03,305 - util.py[DEBUG]: Restoring selinux mode for /var/lib/cloud/seed (recursive=False)
2022-01-18 13:23:03,306 - util.py[DEBUG]: Restoring selinux mode for /var/lib/cloud/instances (recursive=False)
2022-01-18 13:23:03,306 - util.py[DEBUG]: Restoring selinux mode for /var/lib/cloud/handlers (recursive=False)
2022-01-18 13:23:03,306 - util.py[DEBUG]: Restoring selinux mode for /var/lib/cloud/sem (recursive=False)
2022-01-18 13:23:03,341 - util.py[DEBUG]: Restoring selinux mode for /var/lib/cloud/data (recursive=False)
2022-01-18 13:23:03,342 - util.py[DEBUG]: Writing to /var/log/cloud-init.log - ab: [384] 0 bytes
2022-01-18 13:23:03,342 - util.py[DEBUG]: Restoring selinux mode for /var/log/cloud-init.log (recursive=False)
2022-01-18 13:23:03,343 - util.py[DEBUG]: Restoring selinux mode for /var/log/cloud-init.log (recursive=False)
2022-01-18 13:23:03,343 - util.py[DEBUG]: Running command ['ifconfig', '-a'] with allowed return codes [0] (shell=False, capture=True)
2022-01-18 13:23:03,366 - util.py[DEBUG]: Running command ['netstat', '-rn'] with allowed return codes [0] (shell=False, capture=True)
2022-01-18 13:23:03,386 - util.py[DEBUG]: Running command ['netstat', '-A', 'inet6', '-n'] with allowed return codes [0] (shell=False, capture=True)
2022-01-18 13:23:03,389 - main.py[DEBUG]: Checking to see if files that we need already exist from a previous run that would allow us to stop early.
2022-01-18 13:23:03,389 - main.py[DEBUG]: Execution continuing, no previous run detected that would allow us to stop early.
2022-01-18 13:23:03,390 - handlers.py[DEBUG]: start: init-network/check-cache: attempting to read from cache [trust]
2022-01-18 13:23:03,390 - util.py[DEBUG]: Reading from /var/lib/cloud/instance/obj.pkl (quiet=False)
2022-01-18 13:23:03,390 - stages.py[DEBUG]: no cache found
2022-01-18 13:23:03,390 - handlers.py[DEBUG]: finish: init-network/check-cache: SUCCESS: no cache found
2022-01-18 13:23:03,390 - util.py[DEBUG]: Attempting to remove /var/lib/cloud/instance
2022-01-18 13:23:03,411 - stages.py[DEBUG]: Using distro class <class 'cloudinit.distros.rhel.Distro'>
2022-01-18 13:23:03,411 - __init__.py[DEBUG]: Looking for for data source in: ['NoCloud', 'ConfigDrive', 'OpenNebula', 'DigitalOcean', 'Azure', 'AltCloud', 'OVF', 'MAAS', 'GCE', 'OpenStack', 'AliYun', 'Ec2', 'CloudSigma', 'CloudStack', 'SmartOS', 'Bigstep', 'None'], via packages ['', u'cloudinit.sources'] that matches dependencies ['FILESYSTEM', 'NETWORK']
2022-01-18 13:23:03,497 - __init__.py[DEBUG]: Searching for network data source in: [u'DataSourceNoCloudNet', u'DataSourceAzureNet', u'DataSourceAltCloud', u'DataSourceOVFNet', u'DataSourceMAAS', u'DataSourceGCE', u'DataSourceOpenStack', u'DataSourceAliYun', u'DataSourceEc2', u'DataSourceCloudStack', u'DataSourceBigstep', u'DataSourceNone']
2022-01-18 13:23:03,497 - handlers.py[DEBUG]: start: init-network/search-NoCloudNet: searching for network data from DataSourceNoCloudNet
2022-01-18 13:23:03,498 - __init__.py[DEBUG]: Seeing if we can get any data from <class 'cloudinit.sources.DataSourceNoCloud.DataSourceNoCloudNet'>
2022-01-18 13:23:03,498 - util.py[DEBUG]: Reading from /var/lib/cloud/seed/nocloud/user-data (quiet=False)
2022-01-18 13:23:03,498 - util.py[DEBUG]: Reading from /var/lib/cloud/seed/nocloud/meta-data (quiet=False)
2022-01-18 13:23:03,498 - util.py[DEBUG]: Reading from /var/lib/cloud/seed/nocloud/vendor-data (quiet=False)
2022-01-18 13:23:03,498 - util.py[DEBUG]: Reading from /var/lib/cloud/seed/nocloud/network-config (quiet=False)
2022-01-18 13:23:03,498 - util.py[DEBUG]: Reading from /var/lib/cloud/seed/nocloud-net/user-data (quiet=False)
2022-01-18 13:23:03,498 - util.py[DEBUG]: Reading from /var/lib/cloud/seed/nocloud-net/meta-data (quiet=False)
2022-01-18 13:23:03,498 - util.py[DEBUG]: Reading from /var/lib/cloud/seed/nocloud-net/vendor-data (quiet=False)
2022-01-18 13:23:03,498 - util.py[DEBUG]: Reading from /var/lib/cloud/seed/nocloud-net/network-config (quiet=False)
2022-01-18 13:23:03,498 - util.py[DEBUG]: Running command ['blkid', '-odevice', '/dev/sr0'] with allowed return codes [0, 2] (shell=False, capture=True)
2022-01-18 13:23:03,536 - util.py[DEBUG]: Running command ['blkid', '-odevice', '/dev/sr1'] with allowed return codes [0, 2] (shell=False, capture=True)
2022-01-18 13:23:03,560 - util.py[DEBUG]: Running command ['blkid', '-tTYPE=vfat', '-odevice'] with allowed return codes [0, 2] (shell=False, capture=True)
2022-01-18 13:23:03,585 - util.py[DEBUG]: Running command ['blkid', '-tTYPE=iso9660', '-odevice'] with allowed return codes [0, 2] (shell=False, capture=True)
2022-01-18 13:23:03,599 - util.py[DEBUG]: Running command ['blkid', '-tLABEL=cidata', '-odevice'] with allowed return codes [0, 2] (shell=False, capture=True)
2022-01-18 13:23:03,618 - handlers.py[DEBUG]: finish: init-network/search-NoCloudNet: SUCCESS: no network data found from DataSourceNoCloudNet
2022-01-18 13:23:03,619 - handlers.py[DEBUG]: start: init-network/search-AzureNet: searching for network data from DataSourceAzureNet
2022-01-18 13:23:03,619 - __init__.py[DEBUG]: Seeing if we can get any data from <class 'cloudinit.sources.DataSourceAzure.DataSourceAzureNet'>
2022-01-18 13:23:03,619 - util.py[DEBUG]: Running command ['blkid', '-tTYPE=iso9660', '-odevice'] with allowed return codes [0, 2] (shell=False, capture=True)
2022-01-18 13:23:03,634 - util.py[DEBUG]: Running command ['blkid', '-tTYPE=udf', '-odevice'] with allowed return codes [0, 2] (shell=False, capture=True)
2022-01-18 13:23:03,657 - handlers.py[DEBUG]: finish: init-network/search-AzureNet: SUCCESS: no network data found from DataSourceAzureNet
2022-01-18 13:23:03,657 - handlers.py[DEBUG]: start: init-network/search-AltCloud: searching for network data from DataSourceAltCloud
2022-01-18 13:23:03,657 - __init__.py[DEBUG]: Seeing if we can get any data from <class 'cloudinit.sources.DataSourceAltCloud.DataSourceAltCloud'>
2022-01-18 13:23:03,657 - DataSourceAltCloud.py[DEBUG]: Invoked get_data()
2022-01-18 13:23:03,657 - util.py[DEBUG]: querying dmi data /sys/class/dmi/id/product_name
2022-01-18 13:23:03,658 - util.py[DEBUG]: Reading from /sys/class/dmi/id/product_name (quiet=False)
2022-01-18 13:23:03,658 - util.py[DEBUG]: Read 9 bytes from /sys/class/dmi/id/product_name
2022-01-18 13:23:03,658 - util.py[DEBUG]: dmi data /sys/class/dmi/id/product_name returned HVM domU
2022-01-18 13:23:03,658 - DataSourceAltCloud.py[DEBUG]: cloud_type: UNKNOWN
2022-01-18 13:23:03,658 - handlers.py[DEBUG]: finish: init-network/search-AltCloud: SUCCESS: no network data found from DataSourceAltCloud
2022-01-18 13:23:03,658 - handlers.py[DEBUG]: start: init-network/search-OVFNet: searching for network data from DataSourceOVFNet
2022-01-18 13:23:03,658 - __init__.py[DEBUG]: Seeing if we can get any data from <class 'cloudinit.sources.DataSourceOVF.DataSourceOVFNet'>
2022-01-18 13:23:03,658 - util.py[DEBUG]: querying dmi data /sys/class/dmi/id/product_name
2022-01-18 13:23:03,659 - util.py[DEBUG]: Reading from /sys/class/dmi/id/product_name (quiet=False)
2022-01-18 13:23:03,659 - util.py[DEBUG]: Read 9 bytes from /sys/class/dmi/id/product_name
2022-01-18 13:23:03,659 - util.py[DEBUG]: dmi data /sys/class/dmi/id/product_name returned HVM domU
2022-01-18 13:23:03,659 - util.py[DEBUG]: Reading from /proc/mounts (quiet=False)
2022-01-18 13:23:03,659 - util.py[DEBUG]: Read 2221 bytes from /proc/mounts
2022-01-18 13:23:03,659 - util.py[DEBUG]: Fetched {'configfs': {'mountpoint': '/sys/kernel/config', 'opts': 'rw,relatime', 'fstype': 'configfs'}, 'devpts': {'mountpoint': '/dev/pts', 'opts': 'rw,seclabel,nosuid,noexec,relatime,gid=5,mode=620,ptmxmode=000', 'fstype': 'devpts'}, 'debugfs': {'mountpoint': '/sys/kernel/debug', 'opts': 'rw,relatime', 'fstype': 'debugfs'}, 'securityfs': {'mountpoint': '/sys/kernel/security', 'opts': 'rw,nosuid,nodev,noexec,relatime', 'fstype': 'securityfs'}, 'sysfs': {'mountpoint': '/sys', 'opts': 'rw,seclabel,nosuid,nodev,noexec,relatime', 'fstype': 'sysfs'}, 'mqueue': {'mountpoint': '/dev/mqueue', 'opts': 'rw,seclabel,relatime', 'fstype': 'mqueue'}, 'pstore': {'mountpoint': '/sys/fs/pstore', 'opts': 'rw,nosuid,nodev,noexec,relatime', 'fstype': 'pstore'}, 'rpc_pipefs': {'mountpoint': '/var/lib/nfs/rpc_pipefs', 'opts': 'rw,relatime', 'fstype': 'rpc_pipefs'}, 'hugetlbfs': {'mountpoint': '/dev/hugepages', 'opts': 'rw,seclabel,relatime', 'fstype': 'hugetlbfs'}, '/dev/xvda1': {'mountpoint': '/', 'opts': 'rw,seclabel,relatime,attr2,inode64,noquota', 'fstype': 'xfs'}, 'systemd-1': {'mountpoint': '/proc/sys/fs/binfmt_misc', 'opts': 'rw,relatime,fd=32,pgrp=1,timeout=0,minproto=5,maxproto=5,direct,pipe_ino=13070', 'fstype': 'autofs'}, 'cgroup': {'mountpoint': '/sys/fs/cgroup/memory', 'opts': 'rw,seclabel,nosuid,nodev,noexec,relatime,memory', 'fstype': 'cgroup'}, 'tmpfs': {'mountpoint': '/sys/fs/cgroup', 'opts': 'ro,seclabel,nosuid,nodev,noexec,mode=755', 'fstype': 'tmpfs'}, 'proc': {'mountpoint': '/proc', 'opts': 'rw,nosuid,nodev,noexec,relatime', 'fstype': 'proc'}, 'devtmpfs': {'mountpoint': '/dev', 'opts': 'rw,seclabel,nosuid,size=226316k,nr_inodes=56579,mode=755', 'fstype': 'devtmpfs'}, 'selinuxfs': {'mountpoint': '/sys/fs/selinux', 'opts': 'rw,relatime', 'fstype': 'selinuxfs'}, 'rootfs': {'mountpoint': '/', 'opts': 'rw', 'fstype': 'rootfs'}} mounts from proc
2022-01-18 13:23:03,660 - util.py[DEBUG]: Peeking at /dev/xvda (max_bytes=512)
2022-01-18 13:23:03,660 - util.py[DEBUG]: Reading from /proc/mounts (quiet=False)
2022-01-18 13:23:03,660 - util.py[DEBUG]: Read 2221 bytes from /proc/mounts
2022-01-18 13:23:03,660 - util.py[DEBUG]: Fetched {'configfs': {'mountpoint': '/sys/kernel/config', 'opts': 'rw,relatime', 'fstype': 'configfs'}, 'devpts': {'mountpoint': '/dev/pts', 'opts': 'rw,seclabel,nosuid,noexec,relatime,gid=5,mode=620,ptmxmode=000', 'fstype': 'devpts'}, 'debugfs': {'mountpoint': '/sys/kernel/debug', 'opts': 'rw,relatime', 'fstype': 'debugfs'}, 'securityfs': {'mountpoint': '/sys/kernel/security', 'opts': 'rw,nosuid,nodev,noexec,relatime', 'fstype': 'securityfs'}, 'sysfs': {'mountpoint': '/sys', 'opts': 'rw,seclabel,nosuid,nodev,noexec,relatime', 'fstype': 'sysfs'}, 'mqueue': {'mountpoint': '/dev/mqueue', 'opts': 'rw,seclabel,relatime', 'fstype': 'mqueue'}, 'pstore': {'mountpoint': '/sys/fs/pstore', 'opts': 'rw,nosuid,nodev,noexec,relatime', 'fstype': 'pstore'}, 'rpc_pipefs': {'mountpoint': '/var/lib/nfs/rpc_pipefs', 'opts': 'rw,relatime', 'fstype': 'rpc_pipefs'}, 'hugetlbfs': {'mountpoint': '/dev/hugepages', 'opts': 'rw,seclabel,relatime', 'fstype': 'hugetlbfs'}, '/dev/xvda1': {'mountpoint': '/', 'opts': 'rw,seclabel,relatime,attr2,inode64,noquota', 'fstype': 'xfs'}, 'systemd-1': {'mountpoint': '/proc/sys/fs/binfmt_misc', 'opts': 'rw,relatime,fd=32,pgrp=1,timeout=0,minproto=5,maxproto=5,direct,pipe_ino=13070', 'fstype': 'autofs'}, 'cgroup': {'mountpoint': '/sys/fs/cgroup/memory', 'opts': 'rw,seclabel,nosuid,nodev,noexec,relatime,memory', 'fstype': 'cgroup'}, 'tmpfs': {'mountpoint': '/sys/fs/cgroup', 'opts': 'ro,seclabel,nosuid,nodev,noexec,mode=755', 'fstype': 'tmpfs'}, 'proc': {'mountpoint': '/proc', 'opts': 'rw,nosuid,nodev,noexec,relatime', 'fstype': 'proc'}, 'devtmpfs': {'mountpoint': '/dev', 'opts': 'rw,seclabel,nosuid,size=226316k,nr_inodes=56579,mode=755', 'fstype': 'devtmpfs'}, 'selinuxfs': {'mountpoint': '/sys/fs/selinux', 'opts': 'rw,relatime', 'fstype': 'selinuxfs'}, 'rootfs': {'mountpoint': '/', 'opts': 'rw', 'fstype': 'rootfs'}} mounts from proc
2022-01-18 13:23:03,661 - util.py[DEBUG]: Running command ['mount', '-o', 'ro,sync', '-t', 'iso9660', '/dev/xvda', '/tmp/tmpVjZf87'] with allowed return codes [0] (shell=False, capture=True)
2022-01-18 13:23:03,680 - util.py[DEBUG]: Failed mount of '/dev/xvda' as 'iso9660': Unexpected error while running command.
Command: ['mount', '-o', 'ro,sync', '-t', 'iso9660', '/dev/xvda', '/tmp/tmpVjZf87']
Exit code: 32
Reason: -
Stdout: -
Stderr: mount: /dev/xvda is already mounted or /tmp/tmpVjZf87 busy
2022-01-18 13:23:03,680 - util.py[DEBUG]: Recursively deleting /tmp/tmpVjZf87
2022-01-18 13:23:03,695 - DataSourceOVF.py[DEBUG]: /dev/xvda not mountable as iso9660
2022-01-18 13:23:03,696 - handlers.py[DEBUG]: finish: init-network/search-OVFNet: SUCCESS: no network data found from DataSourceOVFNet
2022-01-18 13:23:03,696 - handlers.py[DEBUG]: start: init-network/search-MAAS: searching for network data from DataSourceMAAS
2022-01-18 13:23:03,696 - __init__.py[DEBUG]: Seeing if we can get any data from <class 'cloudinit.sources.DataSourceMAAS.DataSourceMAAS'>
2022-01-18 13:23:03,696 - handlers.py[DEBUG]: finish: init-network/search-MAAS: SUCCESS: no network data found from DataSourceMAAS
2022-01-18 13:23:03,696 - handlers.py[DEBUG]: start: init-network/search-GCE: searching for network data from DataSourceGCE
2022-01-18 13:23:03,696 - __init__.py[DEBUG]: Seeing if we can get any data from <class 'cloudinit.sources.DataSourceGCE.DataSourceGCE'>
2022-01-18 13:23:03,770 - DataSourceGCE.py[DEBUG]: http://metadata.google.internal/computeMetadata/v1/ is not resolvable
2022-01-18 13:23:03,771 - handlers.py[DEBUG]: finish: init-network/search-GCE: SUCCESS: no network data found from DataSourceGCE
2022-01-18 13:23:03,771 - handlers.py[DEBUG]: start: init-network/search-OpenStack: searching for network data from DataSourceOpenStack
2022-01-18 13:23:03,771 - __init__.py[DEBUG]: Seeing if we can get any data from <class 'cloudinit.sources.DataSourceOpenStack.DataSourceOpenStack'>
2022-01-18 13:23:03,771 - url_helper.py[DEBUG]: [0/1] open 'http://169.254.169.254/openstack' with {'url': 'http://169.254.169.254/openstack', 'headers': {'User-Agent': 'Cloud-Init/0.7.9'}, 'allow_redirects': True, 'method': 'GET', 'timeout': 10.0} configuration
2022-01-18 13:23:03,799 - url_helper.py[DEBUG]: Read from http://169.254.169.254/openstack (404, 337b) after 1 attempts
2022-01-18 13:23:03,800 - url_helper.py[DEBUG]: Calling 'http://169.254.169.254/openstack' failed [0/-1s]: bad status code [404]
2022-01-18 13:23:03,800 - DataSourceOpenStack.py[DEBUG]: Giving up on OpenStack md from ['http://169.254.169.254/openstack'] after 0 seconds
2022-01-18 13:23:03,800 - handlers.py[DEBUG]: finish: init-network/search-OpenStack: SUCCESS: no network data found from DataSourceOpenStack
2022-01-18 13:23:03,800 - handlers.py[DEBUG]: start: init-network/search-AliYun: searching for network data from DataSourceAliYun
2022-01-18 13:23:03,800 - __init__.py[DEBUG]: Seeing if we can get any data from <class 'cloudinit.sources.DataSourceAliYun.DataSourceAliYun'>
2022-01-18 13:23:03,800 - util.py[DEBUG]: Reading from /var/lib/cloud/seed/AliYun/meta-data (quiet=False)
2022-01-18 13:23:03,800 - util.py[DEBUG]: querying dmi data /sys/class/dmi/id/product_name
2022-01-18 13:23:03,801 - util.py[DEBUG]: Reading from /sys/class/dmi/id/product_name (quiet=False)
2022-01-18 13:23:03,801 - util.py[DEBUG]: Read 9 bytes from /sys/class/dmi/id/product_name
2022-01-18 13:23:03,801 - util.py[DEBUG]: dmi data /sys/class/dmi/id/product_name returned HVM domU
2022-01-18 13:23:03,801 - DataSourceEc2.py[DEBUG]: strict_mode: warn, cloud_platform=No-EC2-Metadata
2022-01-18 13:23:03,801 - handlers.py[DEBUG]: finish: init-network/search-AliYun: SUCCESS: no network data found from DataSourceAliYun
2022-01-18 13:23:03,801 - handlers.py[DEBUG]: start: init-network/search-Ec2: searching for network data from DataSourceEc2
2022-01-18 13:23:03,801 - __init__.py[DEBUG]: Seeing if we can get any data from <class 'cloudinit.sources.DataSourceEc2.DataSourceEc2'>
2022-01-18 13:23:03,801 - util.py[DEBUG]: Reading from /var/lib/cloud/seed/ec2/meta-data (quiet=False)
2022-01-18 13:23:03,801 - util.py[DEBUG]: Reading from /sys/hypervisor/uuid (quiet=False)
2022-01-18 13:23:03,801 - util.py[DEBUG]: Read 37 bytes from /sys/hypervisor/uuid
2022-01-18 13:23:03,802 - util.py[DEBUG]: querying dmi data /sys/class/dmi/id/product_serial
2022-01-18 13:23:03,802 - util.py[DEBUG]: Reading from /sys/class/dmi/id/product_serial (quiet=False)
2022-01-18 13:23:03,802 - util.py[DEBUG]: Read 37 bytes from /sys/class/dmi/id/product_serial
2022-01-18 13:23:03,802 - util.py[DEBUG]: dmi data /sys/class/dmi/id/product_serial returned ec2831b1-b021-a54a-be81-f91133a6f003
2022-01-18 13:23:03,802 - DataSourceEc2.py[DEBUG]: strict_mode: warn, cloud_platform=AWS
2022-01-18 13:23:03,804 - DataSourceEc2.py[DEBUG]: Removed the following from metadata urls: ['http://instance-data.:8773']
2022-01-18 13:23:03,804 - url_helper.py[DEBUG]: [0/1] open 'http://169.254.169.254/2009-04-04/meta-data/instance-id' with {'url': 'http://169.254.169.254/2009-04-04/meta-data/instance-id', 'headers': {'User-Agent': 'Cloud-Init/0.7.9'}, 'allow_redirects': True, 'method': 'GET', 'timeout': 50.0} configuration
2022-01-18 13:23:03,807 - url_helper.py[DEBUG]: Read from http://169.254.169.254/2009-04-04/meta-data/instance-id (200, 19b) after 1 attempts
2022-01-18 13:23:03,807 - DataSourceEc2.py[DEBUG]: Using metadata source: 'http://169.254.169.254'
2022-01-18 13:23:03,807 - url_helper.py[DEBUG]: [0/6] open 'http://169.254.169.254/2009-04-04/user-data' with {'url': 'http://169.254.169.254/2009-04-04/user-data', 'headers': {'User-Agent': 'Cloud-Init/0.7.9'}, 'allow_redirects': True, 'method': 'GET', 'timeout': 5.0} configuration
2022-01-18 13:23:03,810 - url_helper.py[DEBUG]: Read from http://169.254.169.254/2009-04-04/user-data (200, 179b) after 1 attempts
2022-01-18 13:23:03,810 - url_helper.py[DEBUG]: [0/6] open 'http://169.254.169.254/2009-04-04/meta-data/' with {'url': 'http://169.254.169.254/2009-04-04/meta-data/', 'headers': {'User-Agent': 'Cloud-Init/0.7.9'}, 'allow_redirects': True, 'method': 'GET', 'timeout': 5.0} configuration
2022-01-18 13:23:03,812 - url_helper.py[DEBUG]: Read from http://169.254.169.254/2009-04-04/meta-data/ (200, 245b) after 1 attempts
2022-01-18 13:23:03,813 - url_helper.py[DEBUG]: [0/6] open 'http://169.254.169.254/2009-04-04/meta-data/block-device-mapping/' with {'url': 'http://169.254.169.254/2009-04-04/meta-data/block-device-mapping/', 'headers': {'User-Agent': 'Cloud-Init/0.7.9'}, 'allow_redirects': True, 'method': 'GET', 'timeout': 5.0} configuration
2022-01-18 13:23:03,815 - url_helper.py[DEBUG]: Read from http://169.254.169.254/2009-04-04/meta-data/block-device-mapping/ (200, 8b) after 1 attempts
2022-01-18 13:23:03,815 - url_helper.py[DEBUG]: [0/6] open 'http://169.254.169.254/2009-04-04/meta-data/block-device-mapping/ami' with {'url': 'http://169.254.169.254/2009-04-04/meta-data/block-device-mapping/ami', 'headers': {'User-Agent': 'Cloud-Init/0.7.9'}, 'allow_redirects': True, 'method': 'GET', 'timeout': 5.0} configuration
2022-01-18 13:23:03,818 - url_helper.py[DEBUG]: Read from http://169.254.169.254/2009-04-04/meta-data/block-device-mapping/ami (200, 9b) after 1 attempts
2022-01-18 13:23:03,818 - url_helper.py[DEBUG]: [0/6] open 'http://169.254.169.254/2009-04-04/meta-data/block-device-mapping/root' with {'url': 'http://169.254.169.254/2009-04-04/meta-data/block-device-mapping/root', 'headers': {'User-Agent': 'Cloud-Init/0.7.9'}, 'allow_redirects': True, 'method': 'GET', 'timeout': 5.0} configuration
2022-01-18 13:23:03,821 - url_helper.py[DEBUG]: Read from http://169.254.169.254/2009-04-04/meta-data/block-device-mapping/root (200, 9b) after 1 attempts
2022-01-18 13:23:03,821 - url_helper.py[DEBUG]: [0/6] open 'http://169.254.169.254/2009-04-04/meta-data/placement/' with {'url': 'http://169.254.169.254/2009-04-04/meta-data/placement/', 'headers': {'User-Agent': 'Cloud-Init/0.7.9'}, 'allow_redirects': True, 'method': 'GET', 'timeout': 5.0} configuration
2022-01-18 13:23:03,823 - url_helper.py[DEBUG]: Read from http://169.254.169.254/2009-04-04/meta-data/placement/ (200, 17b) after 1 attempts
2022-01-18 13:23:03,823 - url_helper.py[DEBUG]: [0/6] open 'http://169.254.169.254/2009-04-04/meta-data/placement/availability-zone' with {'url': 'http://169.254.169.254/2009-04-04/meta-data/placement/availability-zone', 'headers': {'User-Agent': 'Cloud-Init/0.7.9'}, 'allow_redirects': True, 'method': 'GET', 'timeout': 5.0} configuration
2022-01-18 13:23:03,826 - url_helper.py[DEBUG]: Read from http://169.254.169.254/2009-04-04/meta-data/placement/availability-zone (200, 10b) after 1 attempts
2022-01-18 13:23:03,826 - url_helper.py[DEBUG]: [0/6] open 'http://169.254.169.254/2009-04-04/meta-data/public-keys/' with {'url': 'http://169.254.169.254/2009-04-04/meta-data/public-keys/', 'headers': {'User-Agent': 'Cloud-Init/0.7.9'}, 'allow_redirects': True, 'method': 'GET', 'timeout': 5.0} configuration
2022-01-18 13:23:03,828 - url_helper.py[DEBUG]: Read from http://169.254.169.254/2009-04-04/meta-data/public-keys/ (200, 10b) after 1 attempts
2022-01-18 13:23:03,829 - url_helper.py[DEBUG]: [0/6] open 'http://169.254.169.254/2009-04-04/meta-data/public-keys/0/openssh-key' with {'url': 'http://169.254.169.254/2009-04-04/meta-data/public-keys/0/openssh-key', 'headers': {'User-Agent': 'Cloud-Init/0.7.9'}, 'allow_redirects': True, 'method': 'GET', 'timeout': 5.0} configuration
2022-01-18 13:23:03,831 - url_helper.py[DEBUG]: Read from http://169.254.169.254/2009-04-04/meta-data/public-keys/0/openssh-key (200, 390b) after 1 attempts
2022-01-18 13:23:03,831 - url_helper.py[DEBUG]: [0/6] open 'http://169.254.169.254/2009-04-04/meta-data/profile' with {'url': 'http://169.254.169.254/2009-04-04/meta-data/profile', 'headers': {'User-Agent': 'Cloud-Init/0.7.9'}, 'allow_redirects': True, 'method': 'GET', 'timeout': 5.0} configuration
2022-01-18 13:23:03,834 - url_helper.py[DEBUG]: Read from http://169.254.169.254/2009-04-04/meta-data/profile (200, 11b) after 1 attempts
2022-01-18 13:23:03,834 - url_helper.py[DEBUG]: [0/6] open 'http://169.254.169.254/2009-04-04/meta-data/local-ipv4' with {'url': 'http://169.254.169.254/2009-04-04/meta-data/local-ipv4', 'headers': {'User-Agent': 'Cloud-Init/0.7.9'}, 'allow_redirects': True, 'method': 'GET', 'timeout': 5.0} configuration
2022-01-18 13:23:03,836 - url_helper.py[DEBUG]: Read from http://169.254.169.254/2009-04-04/meta-data/local-ipv4 (200, 10b) after 1 attempts
2022-01-18 13:23:03,837 - url_helper.py[DEBUG]: [0/6] open 'http://169.254.169.254/2009-04-04/meta-data/reservation-id' with {'url': 'http://169.254.169.254/2009-04-04/meta-data/reservation-id', 'headers': {'User-Agent': 'Cloud-Init/0.7.9'}, 'allow_redirects': True, 'method': 'GET', 'timeout': 5.0} configuration
2022-01-18 13:23:03,839 - url_helper.py[DEBUG]: Read from http://169.254.169.254/2009-04-04/meta-data/reservation-id (200, 19b) after 1 attempts
2022-01-18 13:23:03,839 - url_helper.py[DEBUG]: [0/6] open 'http://169.254.169.254/2009-04-04/meta-data/local-hostname' with {'url': 'http://169.254.169.254/2009-04-04/meta-data/local-hostname', 'headers': {'User-Agent': 'Cloud-Init/0.7.9'}, 'allow_redirects': True, 'method': 'GET', 'timeout': 5.0} configuration
2022-01-18 13:23:03,842 - url_helper.py[DEBUG]: Read from http://169.254.169.254/2009-04-04/meta-data/local-hostname (200, 26b) after 1 attempts
2022-01-18 13:23:03,842 - url_helper.py[DEBUG]: [0/6] open 'http://169.254.169.254/2009-04-04/meta-data/security-groups' with {'url': 'http://169.254.169.254/2009-04-04/meta-data/security-groups', 'headers': {'User-Agent': 'Cloud-Init/0.7.9'}, 'allow_redirects': True, 'method': 'GET', 'timeout': 5.0} configuration
2022-01-18 13:23:03,844 - url_helper.py[DEBUG]: Read from http://169.254.169.254/2009-04-04/meta-data/security-groups (200, 24b) after 1 attempts
2022-01-18 13:23:03,844 - url_helper.py[DEBUG]: [0/6] open 'http://169.254.169.254/2009-04-04/meta-data/product-codes' with {'url': 'http://169.254.169.254/2009-04-04/meta-data/product-codes', 'headers': {'User-Agent': 'Cloud-Init/0.7.9'}, 'allow_redirects': True, 'method': 'GET', 'timeout': 5.0} configuration
2022-01-18 13:23:03,847 - url_helper.py[DEBUG]: Read from http://169.254.169.254/2009-04-04/meta-data/product-codes (200, 25b) after 1 attempts
2022-01-18 13:23:03,847 - url_helper.py[DEBUG]: [0/6] open 'http://169.254.169.254/2009-04-04/meta-data/ami-launch-index' with {'url': 'http://169.254.169.254/2009-04-04/meta-data/ami-launch-index', 'headers': {'User-Agent': 'Cloud-Init/0.7.9'}, 'allow_redirects': True, 'method': 'GET', 'timeout': 5.0} configuration
2022-01-18 13:23:03,850 - url_helper.py[DEBUG]: Read from http://169.254.169.254/2009-04-04/meta-data/ami-launch-index (200, 1b) after 1 attempts
2022-01-18 13:23:03,850 - url_helper.py[DEBUG]: [0/6] open 'http://169.254.169.254/2009-04-04/meta-data/public-hostname' with {'url': 'http://169.254.169.254/2009-04-04/meta-data/public-hostname', 'headers': {'User-Agent': 'Cloud-Init/0.7.9'}, 'allow_redirects': True, 'method': 'GET', 'timeout': 5.0} configuration
2022-01-18 13:23:03,853 - url_helper.py[DEBUG]: Read from http://169.254.169.254/2009-04-04/meta-data/public-hostname (200, 41b) after 1 attempts
2022-01-18 13:23:03,853 - url_helper.py[DEBUG]: [0/6] open 'http://169.254.169.254/2009-04-04/meta-data/hostname' with {'url': 'http://169.254.169.254/2009-04-04/meta-data/hostname', 'headers': {'User-Agent': 'Cloud-Init/0.7.9'}, 'allow_redirects': True, 'method': 'GET', 'timeout': 5.0} configuration
2022-01-18 13:23:03,855 - url_helper.py[DEBUG]: Read from http://169.254.169.254/2009-04-04/meta-data/hostname (200, 26b) after 1 attempts
2022-01-18 13:23:03,855 - url_helper.py[DEBUG]: [0/6] open 'http://169.254.169.254/2009-04-04/meta-data/ami-id' with {'url': 'http://169.254.169.254/2009-04-04/meta-data/ami-id', 'headers': {'User-Agent': 'Cloud-Init/0.7.9'}, 'allow_redirects': True, 'method': 'GET', 'timeout': 5.0} configuration
2022-01-18 13:23:03,858 - url_helper.py[DEBUG]: Read from http://169.254.169.254/2009-04-04/meta-data/ami-id (200, 12b) after 1 attempts
2022-01-18 13:23:03,858 - url_helper.py[DEBUG]: [0/6] open 'http://169.254.169.254/2009-04-04/meta-data/instance-action' with {'url': 'http://169.254.169.254/2009-04-04/meta-data/instance-action', 'headers': {'User-Agent': 'Cloud-Init/0.7.9'}, 'allow_redirects': True, 'method': 'GET', 'timeout': 5.0} configuration
2022-01-18 13:23:03,861 - url_helper.py[DEBUG]: Read from http://169.254.169.254/2009-04-04/meta-data/instance-action (200, 4b) after 1 attempts
2022-01-18 13:23:03,861 - url_helper.py[DEBUG]: [0/6] open 'http://169.254.169.254/2009-04-04/meta-data/public-ipv4' with {'url': 'http://169.254.169.254/2009-04-04/meta-data/public-ipv4', 'headers': {'User-Agent': 'Cloud-Init/0.7.9'}, 'allow_redirects': True, 'method': 'GET', 'timeout': 5.0} configuration
2022-01-18 13:23:03,864 - url_helper.py[DEBUG]: Read from http://169.254.169.254/2009-04-04/meta-data/public-ipv4 (200, 13b) after 1 attempts
2022-01-18 13:23:03,864 - url_helper.py[DEBUG]: [0/6] open 'http://169.254.169.254/2009-04-04/meta-data/ami-manifest-path' with {'url': 'http://169.254.169.254/2009-04-04/meta-data/ami-manifest-path', 'headers': {'User-Agent': 'Cloud-Init/0.7.9'}, 'allow_redirects': True, 'method': 'GET', 'timeout': 5.0} configuration
2022-01-18 13:23:03,866 - url_helper.py[DEBUG]: Read from http://169.254.169.254/2009-04-04/meta-data/ami-manifest-path (200, 9b) after 1 attempts
2022-01-18 13:23:03,867 - url_helper.py[DEBUG]: [0/6] open 'http://169.254.169.254/2009-04-04/meta-data/instance-type' with {'url': 'http://169.254.169.254/2009-04-04/meta-data/instance-type', 'headers': {'User-Agent': 'Cloud-Init/0.7.9'}, 'allow_redirects': True, 'method': 'GET', 'timeout': 5.0} configuration
2022-01-18 13:23:03,869 - url_helper.py[DEBUG]: Read from http://169.254.169.254/2009-04-04/meta-data/instance-type (200, 7b) after 1 attempts
2022-01-18 13:23:03,869 - url_helper.py[DEBUG]: [0/6] open 'http://169.254.169.254/2009-04-04/meta-data/instance-id' with {'url': 'http://169.254.169.254/2009-04-04/meta-data/instance-id', 'headers': {'User-Agent': 'Cloud-Init/0.7.9'}, 'allow_redirects': True, 'method': 'GET', 'timeout': 5.0} configuration
2022-01-18 13:23:03,872 - url_helper.py[DEBUG]: Read from http://169.254.169.254/2009-04-04/meta-data/instance-id (200, 19b) after 1 attempts
2022-01-18 13:23:03,872 - DataSourceEc2.py[DEBUG]: Crawl of metadata service took 0.065 seconds
2022-01-18 13:23:03,872 - handlers.py[DEBUG]: finish: init-network/search-Ec2: SUCCESS: found network data from DataSourceEc2
2022-01-18 13:23:03,872 - stages.py[INFO]: Loaded datasource DataSourceEc2 - DataSourceEc2
2022-01-18 13:23:03,872 - util.py[DEBUG]: Reading from /etc/cloud/cloud.cfg (quiet=False)
2022-01-18 13:23:03,872 - util.py[DEBUG]: Read 1146 bytes from /etc/cloud/cloud.cfg
2022-01-18 13:23:03,872 - util.py[DEBUG]: Attempting to load yaml from string of length 1146 with allowed root types (<type 'dict'>,)
2022-01-18 13:23:03,881 - util.py[DEBUG]: Reading from /etc/cloud/cloud.cfg.d/05_logging.cfg (quiet=False)
2022-01-18 13:23:03,881 - util.py[DEBUG]: Read 1821 bytes from /etc/cloud/cloud.cfg.d/05_logging.cfg
2022-01-18 13:23:03,881 - util.py[DEBUG]: Attempting to load yaml from string of length 1821 with allowed root types (<type 'dict'>,)
2022-01-18 13:23:03,885 - util.py[DEBUG]: Attempting to load yaml from string of length 0 with allowed root types (<type 'dict'>,)
2022-01-18 13:23:03,885 - util.py[DEBUG]: load_yaml given empty string, returning default
2022-01-18 13:23:03,885 - util.py[DEBUG]: Attempting to remove /var/lib/cloud/instance
2022-01-18 13:23:03,885 - util.py[DEBUG]: Creating symbolic link from '/var/lib/cloud/instance' => '/var/lib/cloud/instances/i-071ba7f9d50245d7d'
2022-01-18 13:23:03,886 - util.py[DEBUG]: Restoring selinux mode for /var/lib/cloud/instances/i-071ba7f9d50245d7d (recursive=True)
2022-01-18 13:23:03,887 - util.py[DEBUG]: Restoring selinux mode for /var/lib/cloud/instances/i-071ba7f9d50245d7d/handlers (recursive=False)
2022-01-18 13:23:03,887 - util.py[DEBUG]: Restoring selinux mode for /var/lib/cloud/instances/i-071ba7f9d50245d7d (recursive=True)
2022-01-18 13:23:03,888 - util.py[DEBUG]: Restoring selinux mode for /var/lib/cloud/instances/i-071ba7f9d50245d7d/scripts (recursive=False)
2022-01-18 13:23:03,888 - util.py[DEBUG]: Restoring selinux mode for /var/lib/cloud/instances/i-071ba7f9d50245d7d (recursive=True)
2022-01-18 13:23:03,889 - util.py[DEBUG]: Restoring selinux mode for /var/lib/cloud/instances/i-071ba7f9d50245d7d/sem (recursive=False)
2022-01-18 13:23:03,890 - util.py[DEBUG]: Reading from /var/lib/cloud/instances/i-071ba7f9d50245d7d/datasource (quiet=False)
2022-01-18 13:23:03,890 - util.py[DEBUG]: Writing to /var/lib/cloud/instances/i-071ba7f9d50245d7d/datasource - wb: [420] 29 bytes
2022-01-18 13:23:03,890 - util.py[DEBUG]: Restoring selinux mode for /var/lib/cloud/instances/i-071ba7f9d50245d7d/datasource (recursive=False)
2022-01-18 13:23:03,891 - util.py[DEBUG]: Restoring selinux mode for /var/lib/cloud/instances/i-071ba7f9d50245d7d/datasource (recursive=False)
2022-01-18 13:23:03,891 - util.py[DEBUG]: Writing to /var/lib/cloud/data/previous-datasource - wb: [420] 29 bytes
2022-01-18 13:23:03,892 - util.py[DEBUG]: Restoring selinux mode for /var/lib/cloud/data/previous-datasource (recursive=False)
2022-01-18 13:23:03,892 - util.py[DEBUG]: Restoring selinux mode for /var/lib/cloud/data/previous-datasource (recursive=False)
2022-01-18 13:23:03,892 - util.py[DEBUG]: Reading from /var/lib/cloud/data/instance-id (quiet=False)
2022-01-18 13:23:03,892 - stages.py[DEBUG]: previous iid found to be NO_PREVIOUS_INSTANCE_ID
2022-01-18 13:23:03,892 - util.py[DEBUG]: Writing to /var/lib/cloud/data/instance-id - wb: [420] 20 bytes
2022-01-18 13:23:03,893 - util.py[DEBUG]: Restoring selinux mode for /var/lib/cloud/data/instance-id (recursive=False)
2022-01-18 13:23:03,893 - util.py[DEBUG]: Restoring selinux mode for /var/lib/cloud/data/instance-id (recursive=False)
2022-01-18 13:23:03,894 - util.py[DEBUG]: Writing to /run/cloud-init/.instance-id - wb: [420] 20 bytes
2022-01-18 13:23:03,894 - util.py[DEBUG]: Restoring selinux mode for /run/cloud-init/.instance-id (recursive=False)
2022-01-18 13:23:03,895 - util.py[DEBUG]: Restoring selinux mode for /run/cloud-init/.instance-id (recursive=False)
2022-01-18 13:23:03,895 - util.py[DEBUG]: Writing to /var/lib/cloud/data/previous-instance-id - wb: [420] 24 bytes
2022-01-18 13:23:03,896 - util.py[DEBUG]: Restoring selinux mode for /var/lib/cloud/data/previous-instance-id (recursive=False)
2022-01-18 13:23:03,896 - util.py[DEBUG]: Restoring selinux mode for /var/lib/cloud/data/previous-instance-id (recursive=False)
2022-01-18 13:23:03,897 - util.py[DEBUG]: Writing to /var/lib/cloud/instance/obj.pkl - wb: [256] 6526 bytes
2022-01-18 13:23:03,897 - util.py[DEBUG]: Restoring selinux mode for /var/lib/cloud/instances/i-071ba7f9d50245d7d/obj.pkl (recursive=False)
2022-01-18 13:23:03,898 - util.py[DEBUG]: Restoring selinux mode for /var/lib/cloud/instances/i-071ba7f9d50245d7d/obj.pkl (recursive=False)
2022-01-18 13:23:03,898 - main.py[DEBUG]: [net] init will now be targeting instance id: i-071ba7f9d50245d7d. new=True
2022-01-18 13:23:03,898 - util.py[DEBUG]: Reading from /etc/cloud/cloud.cfg (quiet=False)
2022-01-18 13:23:03,898 - util.py[DEBUG]: Read 1146 bytes from /etc/cloud/cloud.cfg
2022-01-18 13:23:03,898 - util.py[DEBUG]: Attempting to load yaml from string of length 1146 with allowed root types (<type 'dict'>,)
2022-01-18 13:23:03,907 - util.py[DEBUG]: Reading from /etc/cloud/cloud.cfg.d/05_logging.cfg (quiet=False)
2022-01-18 13:23:03,907 - util.py[DEBUG]: Read 1821 bytes from /etc/cloud/cloud.cfg.d/05_logging.cfg
2022-01-18 13:23:03,907 - util.py[DEBUG]: Attempting to load yaml from string of length 1821 with allowed root types (<type 'dict'>,)
2022-01-18 13:23:03,910 - util.py[DEBUG]: Attempting to load yaml from string of length 0 with allowed root types (<type 'dict'>,)
2022-01-18 13:23:03,911 - util.py[DEBUG]: load_yaml given empty string, returning default
2022-01-18 13:23:03,911 - util.py[DEBUG]: Reading from /sys/class/net/eth0/carrier (quiet=False)
2022-01-18 13:23:03,912 - util.py[DEBUG]: Read 2 bytes from /sys/class/net/eth0/carrier
2022-01-18 13:23:03,912 - util.py[DEBUG]: Reading from /sys/class/net/eth0/address (quiet=False)
2022-01-18 13:23:03,912 - util.py[DEBUG]: Read 18 bytes from /sys/class/net/eth0/address
2022-01-18 13:23:03,912 - stages.py[DEBUG]: applying net config names for {'version': 1, 'config': [{'subnets': [{'type': 'dhcp'}], 'type': 'physical', 'name': 'eth0', 'mac_address': '0e:ad:97:9c:af:97'}]}
2022-01-18 13:23:03,912 - stages.py[DEBUG]: Using distro class <class 'cloudinit.distros.rhel.Distro'>
2022-01-18 13:23:03,912 - util.py[DEBUG]: Reading from /sys/class/net/eth0/addr_assign_type (quiet=False)
2022-01-18 13:23:03,912 - util.py[DEBUG]: Read 2 bytes from /sys/class/net/eth0/addr_assign_type
2022-01-18 13:23:03,913 - util.py[DEBUG]: Reading from /sys/class/net/eth0/address (quiet=False)
2022-01-18 13:23:03,913 - util.py[DEBUG]: Read 18 bytes from /sys/class/net/eth0/address
2022-01-18 13:23:03,913 - util.py[DEBUG]: Reading from /sys/class/net/lo/addr_assign_type (quiet=False)
2022-01-18 13:23:03,913 - util.py[DEBUG]: Read 2 bytes from /sys/class/net/lo/addr_assign_type
2022-01-18 13:23:03,913 - util.py[DEBUG]: Reading from /sys/class/net/lo/address (quiet=False)
2022-01-18 13:23:03,913 - util.py[DEBUG]: Read 18 bytes from /sys/class/net/lo/address
2022-01-18 13:23:03,913 - util.py[DEBUG]: Reading from /sys/class/net/eth0/operstate (quiet=False)
2022-01-18 13:23:03,913 - util.py[DEBUG]: Read 3 bytes from /sys/class/net/eth0/operstate
2022-01-18 13:23:03,913 - util.py[DEBUG]: Reading from /sys/class/net/lo/operstate (quiet=False)
2022-01-18 13:23:03,914 - util.py[DEBUG]: Read 8 bytes from /sys/class/net/lo/operstate
2022-01-18 13:23:03,914 - util.py[DEBUG]: Running command ['ip', '-6', 'addr', 'show', 'permanent', 'scope', 'global'] with allowed return codes [0] (shell=False, capture=True)
2022-01-18 13:23:03,918 - util.py[DEBUG]: Running command ['ip', '-4', 'addr', 'show'] with allowed return codes [0] (shell=False, capture=True)
2022-01-18 13:23:03,920 - __init__.py[DEBUG]: no work necessary for renaming of [['0e:ad:97:9c:af:97', 'eth0']]
2022-01-18 13:23:03,921 - stages.py[INFO]: Applying network configuration from fallback bringup=True: {'version': 1, 'config': [{'subnets': [{'type': 'dhcp'}], 'type': 'physical', 'name': 'eth0', 'mac_address': '0e:ad:97:9c:af:97'}]}
2022-01-18 13:23:03,923 - util.py[DEBUG]: Writing to /etc/sysconfig/network-scripts/ifcfg-eth0 - wb: [420] 159 bytes
2022-01-18 13:23:03,924 - util.py[DEBUG]: Restoring selinux mode for /etc/sysconfig/network-scripts/ifcfg-eth0 (recursive=False)
2022-01-18 13:23:03,924 - util.py[DEBUG]: Restoring selinux mode for /etc/sysconfig/network-scripts/ifcfg-eth0 (recursive=False)
2022-01-18 13:23:03,924 - util.py[DEBUG]: Reading from /etc/resolv.conf (quiet=False)
2022-01-18 13:23:03,924 - util.py[DEBUG]: Read 81 bytes from /etc/resolv.conf
2022-01-18 13:23:03,924 - util.py[DEBUG]: Writing to /etc/resolv.conf - wb: [420] 152 bytes
2022-01-18 13:23:03,925 - util.py[DEBUG]: Restoring selinux mode for /etc/resolv.conf (recursive=False)
2022-01-18 13:23:03,925 - util.py[DEBUG]: Restoring selinux mode for /etc/resolv.conf (recursive=False)
2022-01-18 13:23:03,925 - util.py[DEBUG]: Writing to /etc/udev/rules.d/70-persistent-net.rules - wb: [420] 96 bytes
2022-01-18 13:23:03,926 - util.py[DEBUG]: Restoring selinux mode for /etc/udev/rules.d/70-persistent-net.rules (recursive=False)
2022-01-18 13:23:03,926 - util.py[DEBUG]: Restoring selinux mode for /etc/udev/rules.d/70-persistent-net.rules (recursive=False)
2022-01-18 13:23:03,926 - util.py[DEBUG]: Writing to /var/lib/cloud/instances/i-071ba7f9d50245d7d/user-data.txt - wb: [384] 179 bytes
2022-01-18 13:23:03,927 - util.py[DEBUG]: Restoring selinux mode for /var/lib/cloud/instances/i-071ba7f9d50245d7d/user-data.txt (recursive=False)
2022-01-18 13:23:03,927 - util.py[DEBUG]: Restoring selinux mode for /var/lib/cloud/instances/i-071ba7f9d50245d7d/user-data.txt (recursive=False)
2022-01-18 13:23:03,928 - util.py[DEBUG]: Attempting to load yaml from string of length 179 with allowed root types (<type 'dict'>,)
2022-01-18 13:23:03,934 - util.py[DEBUG]: Writing to /var/lib/cloud/instances/i-071ba7f9d50245d7d/user-data.txt.i - wb: [384] 520 bytes
2022-01-18 13:23:03,934 - util.py[DEBUG]: Restoring selinux mode for /var/lib/cloud/instances/i-071ba7f9d50245d7d/user-data.txt.i (recursive=False)
2022-01-18 13:23:03,935 - util.py[DEBUG]: Restoring selinux mode for /var/lib/cloud/instances/i-071ba7f9d50245d7d/user-data.txt.i (recursive=False)
2022-01-18 13:23:03,935 - util.py[DEBUG]: Writing to /var/lib/cloud/instances/i-071ba7f9d50245d7d/vendor-data.txt - wb: [384] 0 bytes
2022-01-18 13:23:03,936 - util.py[DEBUG]: Restoring selinux mode for /var/lib/cloud/instances/i-071ba7f9d50245d7d/vendor-data.txt (recursive=False)
2022-01-18 13:23:03,936 - util.py[DEBUG]: Restoring selinux mode for /var/lib/cloud/instances/i-071ba7f9d50245d7d/vendor-data.txt (recursive=False)
2022-01-18 13:23:03,937 - util.py[DEBUG]: Writing to /var/lib/cloud/instances/i-071ba7f9d50245d7d/vendor-data.txt.i - wb: [384] 344 bytes
2022-01-18 13:23:03,938 - util.py[DEBUG]: Restoring selinux mode for /var/lib/cloud/instances/i-071ba7f9d50245d7d/vendor-data.txt.i (recursive=False)
2022-01-18 13:23:03,938 - util.py[DEBUG]: Restoring selinux mode for /var/lib/cloud/instances/i-071ba7f9d50245d7d/vendor-data.txt.i (recursive=False)
2022-01-18 13:23:03,939 - util.py[DEBUG]: Writing to /var/lib/cloud/instances/i-071ba7f9d50245d7d/sem/consume_data - wb: [420] 19 bytes
2022-01-18 13:23:03,939 - util.py[DEBUG]: Restoring selinux mode for /var/lib/cloud/instances/i-071ba7f9d50245d7d/sem/consume_data (recursive=False)
2022-01-18 13:23:03,940 - util.py[DEBUG]: Restoring selinux mode for /var/lib/cloud/instances/i-071ba7f9d50245d7d/sem/consume_data (recursive=False)
2022-01-18 13:23:03,940 - helpers.py[DEBUG]: Running consume_data using lock (<FileLock using file '/var/lib/cloud/instances/i-071ba7f9d50245d7d/sem/consume_data'>)
2022-01-18 13:23:03,940 - handlers.py[DEBUG]: start: init-network/consume-user-data: reading and applying user-data
2022-01-18 13:23:03,940 - launch_index.py[DEBUG]: Discarding 0 multipart messages which do not match launch index 0
2022-01-18 13:23:03,941 - stages.py[DEBUG]: Added default handler for set(['text/cloud-config-jsonp', 'text/cloud-config']) from CloudConfigPartHandler: [['text/cloud-config', 'text/cloud-config-jsonp']]
2022-01-18 13:23:03,941 - stages.py[DEBUG]: Added default handler for set(['text/x-shellscript']) from ShellScriptPartHandler: [['text/x-shellscript']]
2022-01-18 13:23:03,941 - stages.py[DEBUG]: Added default handler for set(['text/cloud-boothook']) from BootHookPartHandler: [['text/cloud-boothook']]
2022-01-18 13:23:03,941 - stages.py[DEBUG]: Added default handler for set(['text/upstart-job']) from UpstartJobPartHandler: [['text/upstart-job']]
2022-01-18 13:23:03,942 - __init__.py[DEBUG]: Calling handler BootHookPartHandler: [['text/cloud-boothook']] (__begin__, None, 2) with frequency once-per-instance
2022-01-18 13:23:03,942 - __init__.py[DEBUG]: Calling handler UpstartJobPartHandler: [['text/upstart-job']] (__begin__, None, 2) with frequency once-per-instance
2022-01-18 13:23:03,942 - __init__.py[DEBUG]: Calling handler CloudConfigPartHandler: [['text/cloud-config', 'text/cloud-config-jsonp']] (__begin__, None, 3) with frequency once-per-instance
2022-01-18 13:23:03,942 - __init__.py[DEBUG]: Calling handler ShellScriptPartHandler: [['text/x-shellscript']] (__begin__, None, 2) with frequency once-per-instance
2022-01-18 13:23:03,942 - __init__.py[DEBUG]: {'Content-Type': 'text/cloud-config', 'Content-Disposition': 'attachment; filename="part-001"', 'MIME-Version': '1.0'}
2022-01-18 13:23:03,942 - __init__.py[DEBUG]: Calling handler CloudConfigPartHandler: [['text/cloud-config', 'text/cloud-config-jsonp']] (text/cloud-config, part-001, 3) with frequency once-per-instance
2022-01-18 13:23:03,942 - util.py[DEBUG]: Attempting to load yaml from string of length 179 with allowed root types (<type 'dict'>,)
2022-01-18 13:23:03,943 - cloud_config.py[DEBUG]: Merging by applying [('dict', ['replace']), ('list', []), ('str', [])]
2022-01-18 13:23:03,943 - __init__.py[DEBUG]: Calling handler BootHookPartHandler: [['text/cloud-boothook']] (__end__, None, 2) with frequency once-per-instance
2022-01-18 13:23:03,944 - __init__.py[DEBUG]: Calling handler UpstartJobPartHandler: [['text/upstart-job']] (__end__, None, 2) with frequency once-per-instance
2022-01-18 13:23:03,944 - __init__.py[DEBUG]: Calling handler CloudConfigPartHandler: [['text/cloud-config', 'text/cloud-config-jsonp']] (__end__, None, 3) with frequency once-per-instance
2022-01-18 13:23:03,944 - util.py[DEBUG]: Writing to /var/lib/cloud/instances/i-071ba7f9d50245d7d/cloud-config.txt - wb: [384] 168 bytes
2022-01-18 13:23:03,945 - util.py[DEBUG]: Restoring selinux mode for /var/lib/cloud/instances/i-071ba7f9d50245d7d/cloud-config.txt (recursive=False)
2022-01-18 13:23:03,945 - util.py[DEBUG]: Restoring selinux mode for /var/lib/cloud/instances/i-071ba7f9d50245d7d/cloud-config.txt (recursive=False)
2022-01-18 13:23:03,946 - __init__.py[DEBUG]: Calling handler ShellScriptPartHandler: [['text/x-shellscript']] (__end__, None, 2) with frequency once-per-instance
2022-01-18 13:23:03,946 - handlers.py[DEBUG]: finish: init-network/consume-user-data: SUCCESS: reading and applying user-data
2022-01-18 13:23:03,946 - handlers.py[DEBUG]: start: init-network/consume-vendor-data: reading and applying vendor-data
2022-01-18 13:23:03,946 - stages.py[DEBUG]: no vendordata from datasource
2022-01-18 13:23:03,946 - handlers.py[DEBUG]: finish: init-network/consume-vendor-data: SUCCESS: reading and applying vendor-data
2022-01-18 13:23:03,946 - util.py[DEBUG]: Reading from /etc/cloud/cloud.cfg (quiet=False)
2022-01-18 13:23:03,946 - util.py[DEBUG]: Read 1146 bytes from /etc/cloud/cloud.cfg
2022-01-18 13:23:03,946 - util.py[DEBUG]: Attempting to load yaml from string of length 1146 with allowed root types (<type 'dict'>,)
2022-01-18 13:23:03,955 - util.py[DEBUG]: Reading from /etc/cloud/cloud.cfg.d/05_logging.cfg (quiet=False)
2022-01-18 13:23:03,955 - util.py[DEBUG]: Read 1821 bytes from /etc/cloud/cloud.cfg.d/05_logging.cfg
2022-01-18 13:23:03,955 - util.py[DEBUG]: Attempting to load yaml from string of length 1821 with allowed root types (<type 'dict'>,)
2022-01-18 13:23:03,958 - util.py[DEBUG]: Attempting to load yaml from string of length 0 with allowed root types (<type 'dict'>,)
2022-01-18 13:23:03,959 - util.py[DEBUG]: load_yaml given empty string, returning default
2022-01-18 13:23:03,959 - util.py[DEBUG]: Reading from /var/lib/cloud/instance/cloud-config.txt (quiet=False)
2022-01-18 13:23:03,959 - util.py[DEBUG]: Read 168 bytes from /var/lib/cloud/instance/cloud-config.txt
2022-01-18 13:23:03,959 - util.py[DEBUG]: Attempting to load yaml from string of length 168 with allowed root types (<type 'dict'>,)
2022-01-18 13:23:03,961 - util.py[DEBUG]: Reading from /var/lib/cloud/instance/cloud-config.txt (quiet=False)
2022-01-18 13:23:03,961 - util.py[DEBUG]: Read 168 bytes from /var/lib/cloud/instance/cloud-config.txt
2022-01-18 13:23:03,961 - util.py[DEBUG]: Attempting to load yaml from string of length 168 with allowed root types (<type 'dict'>,)
2022-01-18 13:23:03,965 - util.py[DEBUG]: Writing to /var/lib/cloud/instance/obj.pkl - wb: [256] 5548 bytes
2022-01-18 13:23:03,965 - util.py[DEBUG]: Restoring selinux mode for /var/lib/cloud/instances/i-071ba7f9d50245d7d/obj.pkl (recursive=False)
2022-01-18 13:23:03,966 - util.py[DEBUG]: Restoring selinux mode for /var/lib/cloud/instances/i-071ba7f9d50245d7d/obj.pkl (recursive=False)
2022-01-18 13:23:03,981 - stages.py[DEBUG]: Using distro class <class 'cloudinit.distros.rhel.Distro'>
2022-01-18 13:23:03,981 - stages.py[DEBUG]: Running module migrator (<module 'cloudinit.config.cc_migrator' from '/usr/lib/python2.7/site-packages/cloudinit/config/cc_migrator.pyc'>) with frequency always
2022-01-18 13:23:03,982 - handlers.py[DEBUG]: start: init-network/config-migrator: running config-migrator with frequency always
2022-01-18 13:23:03,982 - helpers.py[DEBUG]: Running config-migrator using lock (<cloudinit.helpers.DummyLock object at 0x7f590969c310>)
2022-01-18 13:23:03,982 - cc_migrator.py[DEBUG]: Migrated 0 semaphore files to there canonicalized names
2022-01-18 13:23:03,982 - handlers.py[DEBUG]: finish: init-network/config-migrator: SUCCESS: config-migrator ran successfully
2022-01-18 13:23:03,982 - stages.py[DEBUG]: Running module bootcmd (<module 'cloudinit.config.cc_bootcmd' from '/usr/lib/python2.7/site-packages/cloudinit/config/cc_bootcmd.pyc'>) with frequency always
2022-01-18 13:23:03,982 - handlers.py[DEBUG]: start: init-network/config-bootcmd: running config-bootcmd with frequency always
2022-01-18 13:23:03,983 - helpers.py[DEBUG]: Running config-bootcmd using lock (<cloudinit.helpers.DummyLock object at 0x7f590969c410>)
2022-01-18 13:23:03,983 - cc_bootcmd.py[DEBUG]: Skipping module named bootcmd, no 'bootcmd' key in configuration
2022-01-18 13:23:03,983 - handlers.py[DEBUG]: finish: init-network/config-bootcmd: SUCCESS: config-bootcmd ran successfully
2022-01-18 13:23:03,983 - stages.py[DEBUG]: Running module write-files (<module 'cloudinit.config.cc_write_files' from '/usr/lib/python2.7/site-packages/cloudinit/config/cc_write_files.pyc'>) with frequency once-per-instance
2022-01-18 13:23:03,983 - handlers.py[DEBUG]: start: init-network/config-write-files: running config-write-files with frequency once-per-instance
2022-01-18 13:23:03,983 - util.py[DEBUG]: Writing to /var/lib/cloud/instances/i-071ba7f9d50245d7d/sem/config_write_files - wb: [420] 19 bytes
2022-01-18 13:23:03,984 - util.py[DEBUG]: Restoring selinux mode for /var/lib/cloud/instances/i-071ba7f9d50245d7d/sem/config_write_files (recursive=False)
2022-01-18 13:23:03,984 - util.py[DEBUG]: Restoring selinux mode for /var/lib/cloud/instances/i-071ba7f9d50245d7d/sem/config_write_files (recursive=False)
2022-01-18 13:23:03,984 - helpers.py[DEBUG]: Running config-write-files using lock (<FileLock using file '/var/lib/cloud/instances/i-071ba7f9d50245d7d/sem/config_write_files'>)
2022-01-18 13:23:03,985 - cc_write_files.py[DEBUG]: Skipping module named write-files, no/empty 'write_files' key in configuration
2022-01-18 13:23:03,985 - handlers.py[DEBUG]: finish: init-network/config-write-files: SUCCESS: config-write-files ran successfully
2022-01-18 13:23:03,985 - stages.py[DEBUG]: Running module growpart (<module 'cloudinit.config.cc_growpart' from '/usr/lib/python2.7/site-packages/cloudinit/config/cc_growpart.pyc'>) with frequency always
2022-01-18 13:23:03,985 - handlers.py[DEBUG]: start: init-network/config-growpart: running config-growpart with frequency always
2022-01-18 13:23:03,985 - helpers.py[DEBUG]: Running config-growpart using lock (<cloudinit.helpers.DummyLock object at 0x7f590969c5d0>)
2022-01-18 13:23:03,985 - cc_growpart.py[DEBUG]: No 'growpart' entry in cfg.  Using default: {'ignore_growroot_disabled': False, 'mode': 'auto', 'devices': ['/']}
2022-01-18 13:23:03,985 - util.py[DEBUG]: Running command ['growpart', '--help'] with allowed return codes [0] (shell=False, capture=True)
2022-01-18 13:23:04,006 - util.py[DEBUG]: Reading from /proc/834/mountinfo (quiet=False)
2022-01-18 13:23:04,007 - util.py[DEBUG]: Read 2858 bytes from /proc/834/mountinfo
2022-01-18 13:23:04,008 - util.py[DEBUG]: Reading from /sys/class/block/xvda1/partition (quiet=False)
2022-01-18 13:23:04,008 - util.py[DEBUG]: Read 2 bytes from /sys/class/block/xvda1/partition
2022-01-18 13:23:04,008 - util.py[DEBUG]: Reading from /sys/devices/vbd-768/block/xvda/dev (quiet=False)
2022-01-18 13:23:04,008 - util.py[DEBUG]: Read 6 bytes from /sys/devices/vbd-768/block/xvda/dev
2022-01-18 13:23:04,009 - util.py[DEBUG]: Running command ['growpart', '--dry-run', '/dev/xvda', '1'] with allowed return codes [0] (shell=False, capture=True)
2022-01-18 13:23:04,064 - util.py[DEBUG]: Running command ['growpart', '/dev/xvda', '1'] with allowed return codes [0] (shell=False, capture=True)
2022-01-18 13:23:04,116 - util.py[DEBUG]: resize_devices took 0.110 seconds
2022-01-18 13:23:04,116 - cc_growpart.py[INFO]: '/' resized: changed (/dev/xvda, 1) from 8588886016 to 10736352768
2022-01-18 13:23:04,116 - handlers.py[DEBUG]: finish: init-network/config-growpart: SUCCESS: config-growpart ran successfully
2022-01-18 13:23:04,117 - stages.py[DEBUG]: Running module resizefs (<module 'cloudinit.config.cc_resizefs' from '/usr/lib/python2.7/site-packages/cloudinit/config/cc_resizefs.pyc'>) with frequency always
2022-01-18 13:23:04,117 - handlers.py[DEBUG]: start: init-network/config-resizefs: running config-resizefs with frequency always
2022-01-18 13:23:04,117 - helpers.py[DEBUG]: Running config-resizefs using lock (<cloudinit.helpers.DummyLock object at 0x7f590969c750>)
2022-01-18 13:23:04,117 - util.py[DEBUG]: Reading from /proc/834/mountinfo (quiet=False)
2022-01-18 13:23:04,117 - util.py[DEBUG]: Read 2858 bytes from /proc/834/mountinfo
2022-01-18 13:23:04,118 - cc_resizefs.py[DEBUG]: resize_info: dev=/dev/xvda1 mnt_point=/ path=/
2022-01-18 13:23:04,118 - util.py[DEBUG]: Running command ['systemd-detect-virt', '--quiet', '--container'] with allowed return codes [0] (shell=False, capture=True)
2022-01-18 13:23:04,120 - util.py[DEBUG]: Running command ['running-in-container'] with allowed return codes [0] (shell=False, capture=True)
2022-01-18 13:23:04,123 - util.py[DEBUG]: Running command ['lxc-is-container'] with allowed return codes [0] (shell=False, capture=True)
2022-01-18 13:23:04,126 - util.py[DEBUG]: Reading from /proc/1/environ (quiet=False)
2022-01-18 13:23:04,126 - util.py[DEBUG]: Read 0 bytes from /proc/1/environ
2022-01-18 13:23:04,126 - util.py[DEBUG]: Reading from /proc/self/status (quiet=False)
2022-01-18 13:23:04,127 - util.py[DEBUG]: Read 1186 bytes from /proc/self/status
2022-01-18 13:23:04,127 - cc_resizefs.py[DEBUG]: Resizing / (xfs) using xfs_growfs /dev/xvda1
2022-01-18 13:23:04,127 - util.py[DEBUG]: Running command ('xfs_growfs', '/dev/xvda1') with allowed return codes [0] (shell=False, capture=True)
2022-01-18 13:23:04,151 - util.py[DEBUG]: Resizing took 0.025 seconds
2022-01-18 13:23:04,152 - cc_resizefs.py[DEBUG]: Resized root filesystem (type=xfs, val=True)
2022-01-18 13:23:04,152 - handlers.py[DEBUG]: finish: init-network/config-resizefs: SUCCESS: config-resizefs ran successfully
2022-01-18 13:23:04,152 - stages.py[DEBUG]: Running module set_hostname (<module 'cloudinit.config.cc_set_hostname' from '/usr/lib/python2.7/site-packages/cloudinit/config/cc_set_hostname.pyc'>) with frequency once-per-instance
2022-01-18 13:23:04,152 - handlers.py[DEBUG]: start: init-network/config-set_hostname: running config-set_hostname with frequency once-per-instance
2022-01-18 13:23:04,153 - util.py[DEBUG]: Writing to /var/lib/cloud/instances/i-071ba7f9d50245d7d/sem/config_set_hostname - wb: [420] 19 bytes
2022-01-18 13:23:04,153 - util.py[DEBUG]: Restoring selinux mode for /var/lib/cloud/instances/i-071ba7f9d50245d7d/sem/config_set_hostname (recursive=False)
2022-01-18 13:23:04,154 - util.py[DEBUG]: Restoring selinux mode for /var/lib/cloud/instances/i-071ba7f9d50245d7d/sem/config_set_hostname (recursive=False)
2022-01-18 13:23:04,154 - helpers.py[DEBUG]: Running config-set_hostname using lock (<FileLock using file '/var/lib/cloud/instances/i-071ba7f9d50245d7d/sem/config_set_hostname'>)
2022-01-18 13:23:04,154 - cc_set_hostname.py[DEBUG]: Setting the hostname to ci3-1569ld597725-uf1.class.splunk.com (ci3-1569ld597725-uf1)
2022-01-18 13:23:04,154 - util.py[DEBUG]: Running command ['hostnamectl', 'set-hostname', 'ci3-1569ld597725-uf1.class.splunk.com'] with allowed return codes [0] (shell=False, capture=True)
2022-01-18 13:23:04,229 - __init__.py[DEBUG]: Non-persistently setting the system hostname to ci3-1569ld597725-uf1.class.splunk.com
2022-01-18 13:23:04,229 - util.py[DEBUG]: Running command ['hostname', 'ci3-1569ld597725-uf1.class.splunk.com'] with allowed return codes [0] (shell=False, capture=True)
2022-01-18 13:23:04,233 - handlers.py[DEBUG]: finish: init-network/config-set_hostname: SUCCESS: config-set_hostname ran successfully
2022-01-18 13:23:04,233 - stages.py[DEBUG]: Running module update_hostname (<module 'cloudinit.config.cc_update_hostname' from '/usr/lib/python2.7/site-packages/cloudinit/config/cc_update_hostname.pyc'>) with frequency always
2022-01-18 13:23:04,233 - handlers.py[DEBUG]: start: init-network/config-update_hostname: running config-update_hostname with frequency always
2022-01-18 13:23:04,233 - helpers.py[DEBUG]: Running config-update_hostname using lock (<cloudinit.helpers.DummyLock object at 0x7f590969ccd0>)
2022-01-18 13:23:04,233 - cc_update_hostname.py[DEBUG]: Updating hostname to ci3-1569ld597725-uf1.class.splunk.com (ci3-1569ld597725-uf1)
2022-01-18 13:23:04,234 - util.py[DEBUG]: Running command ['hostname'] with allowed return codes [0] (shell=False, capture=True)
2022-01-18 13:23:04,236 - __init__.py[DEBUG]: Attempting to update hostname to ci3-1569ld597725-uf1.class.splunk.com in 1 files
2022-01-18 13:23:04,236 - util.py[DEBUG]: Writing to /var/lib/cloud/data/previous-hostname - wb: [420] 37 bytes
2022-01-18 13:23:04,237 - util.py[DEBUG]: Restoring selinux mode for /var/lib/cloud/data/previous-hostname (recursive=False)
2022-01-18 13:23:04,237 - util.py[DEBUG]: Restoring selinux mode for /var/lib/cloud/data/previous-hostname (recursive=False)
2022-01-18 13:23:04,238 - handlers.py[DEBUG]: finish: init-network/config-update_hostname: SUCCESS: config-update_hostname ran successfully
2022-01-18 13:23:04,238 - stages.py[DEBUG]: Running module update_etc_hosts (<module 'cloudinit.config.cc_update_etc_hosts' from '/usr/lib/python2.7/site-packages/cloudinit/config/cc_update_etc_hosts.pyc'>) with frequency always
2022-01-18 13:23:04,238 - handlers.py[DEBUG]: start: init-network/config-update_etc_hosts: running config-update_etc_hosts with frequency always
2022-01-18 13:23:04,238 - helpers.py[DEBUG]: Running config-update_etc_hosts using lock (<cloudinit.helpers.DummyLock object at 0x7f590969cbd0>)
2022-01-18 13:23:04,239 - util.py[DEBUG]: Reading from /etc/cloud/templates/hosts.redhat.tmpl (quiet=False)
2022-01-18 13:23:04,239 - util.py[DEBUG]: Read 912 bytes from /etc/cloud/templates/hosts.redhat.tmpl
2022-01-18 13:23:04,240 - templater.py[DEBUG]: Rendering content of '/etc/cloud/templates/hosts.redhat.tmpl' using renderer jinja
2022-01-18 13:23:04,244 - util.py[DEBUG]: Writing to /etc/hosts - wb: [420] 764 bytes
2022-01-18 13:23:04,244 - util.py[DEBUG]: Restoring selinux mode for /etc/hosts (recursive=False)
2022-01-18 13:23:04,245 - util.py[DEBUG]: Restoring selinux mode for /etc/hosts (recursive=False)
2022-01-18 13:23:04,245 - handlers.py[DEBUG]: finish: init-network/config-update_etc_hosts: SUCCESS: config-update_etc_hosts ran successfully
2022-01-18 13:23:04,245 - stages.py[DEBUG]: Running module rsyslog (<module 'cloudinit.config.cc_rsyslog' from '/usr/lib/python2.7/site-packages/cloudinit/config/cc_rsyslog.pyc'>) with frequency once-per-instance
2022-01-18 13:23:04,245 - handlers.py[DEBUG]: start: init-network/config-rsyslog: running config-rsyslog with frequency once-per-instance
2022-01-18 13:23:04,245 - util.py[DEBUG]: Writing to /var/lib/cloud/instances/i-071ba7f9d50245d7d/sem/config_rsyslog - wb: [420] 19 bytes
2022-01-18 13:23:04,246 - util.py[DEBUG]: Restoring selinux mode for /var/lib/cloud/instances/i-071ba7f9d50245d7d/sem/config_rsyslog (recursive=False)
2022-01-18 13:23:04,246 - util.py[DEBUG]: Restoring selinux mode for /var/lib/cloud/instances/i-071ba7f9d50245d7d/sem/config_rsyslog (recursive=False)
2022-01-18 13:23:04,247 - helpers.py[DEBUG]: Running config-rsyslog using lock (<FileLock using file '/var/lib/cloud/instances/i-071ba7f9d50245d7d/sem/config_rsyslog'>)
2022-01-18 13:23:04,247 - cc_rsyslog.py[DEBUG]: Skipping module named rsyslog, no 'rsyslog' key in configuration
2022-01-18 13:23:04,247 - handlers.py[DEBUG]: finish: init-network/config-rsyslog: SUCCESS: config-rsyslog ran successfully
2022-01-18 13:23:04,247 - stages.py[DEBUG]: Running module users-groups (<module 'cloudinit.config.cc_users_groups' from '/usr/lib/python2.7/site-packages/cloudinit/config/cc_users_groups.pyc'>) with frequency once-per-instance
2022-01-18 13:23:04,247 - handlers.py[DEBUG]: start: init-network/config-users-groups: running config-users-groups with frequency once-per-instance
2022-01-18 13:23:04,247 - util.py[DEBUG]: Writing to /var/lib/cloud/instances/i-071ba7f9d50245d7d/sem/config_users_groups - wb: [420] 19 bytes
2022-01-18 13:23:04,248 - util.py[DEBUG]: Restoring selinux mode for /var/lib/cloud/instances/i-071ba7f9d50245d7d/sem/config_users_groups (recursive=False)
2022-01-18 13:23:04,248 - util.py[DEBUG]: Restoring selinux mode for /var/lib/cloud/instances/i-071ba7f9d50245d7d/sem/config_users_groups (recursive=False)
2022-01-18 13:23:04,248 - helpers.py[DEBUG]: Running config-users-groups using lock (<FileLock using file '/var/lib/cloud/instances/i-071ba7f9d50245d7d/sem/config_users_groups'>)
2022-01-18 13:23:04,249 - util.py[DEBUG]: Reading from /etc/system-image/channel.ini (quiet=True)
2022-01-18 13:23:04,249 - util.py[DEBUG]: Read 0 bytes from /etc/system-image/channel.ini
2022-01-18 13:23:04,249 - __init__.py[DEBUG]: Adding user centos
2022-01-18 13:23:04,249 - util.py[DEBUG]: Running hidden command to protect sensitive input/output logstring: ['useradd', 'centos', '--comment', 'Cloud User', '--groups', 'adm,systemd-journal,wheel', '--shell', '/bin/bash', '-m']
2022-01-18 13:23:04,298 - util.py[DEBUG]: Running command ['passwd', '-l', 'centos'] with allowed return codes [0] (shell=False, capture=True)
2022-01-18 13:23:04,355 - util.py[DEBUG]: Reading from /etc/sudoers (quiet=False)
2022-01-18 13:23:04,356 - util.py[DEBUG]: Read 3938 bytes from /etc/sudoers
2022-01-18 13:23:04,357 - util.py[DEBUG]: Restoring selinux mode for /etc/sudoers.d (recursive=False)
2022-01-18 13:23:04,357 - util.py[DEBUG]: Writing to /etc/sudoers.d/90-cloud-init-users - wb: [288] 123 bytes
2022-01-18 13:23:04,357 - util.py[DEBUG]: Restoring selinux mode for /etc/sudoers.d/90-cloud-init-users (recursive=False)
2022-01-18 13:23:04,358 - util.py[DEBUG]: Restoring selinux mode for /etc/sudoers.d/90-cloud-init-users (recursive=False)
2022-01-18 13:23:04,358 - handlers.py[DEBUG]: finish: init-network/config-users-groups: SUCCESS: config-users-groups ran successfully
2022-01-18 13:23:04,358 - stages.py[DEBUG]: Running module ssh (<module 'cloudinit.config.cc_ssh' from '/usr/lib/python2.7/site-packages/cloudinit/config/cc_ssh.pyc'>) with frequency once-per-instance
2022-01-18 13:23:04,358 - handlers.py[DEBUG]: start: init-network/config-ssh: running config-ssh with frequency once-per-instance
2022-01-18 13:23:04,359 - util.py[DEBUG]: Writing to /var/lib/cloud/instances/i-071ba7f9d50245d7d/sem/config_ssh - wb: [420] 19 bytes
2022-01-18 13:23:04,359 - util.py[DEBUG]: Restoring selinux mode for /var/lib/cloud/instances/i-071ba7f9d50245d7d/sem/config_ssh (recursive=False)
2022-01-18 13:23:04,360 - util.py[DEBUG]: Restoring selinux mode for /var/lib/cloud/instances/i-071ba7f9d50245d7d/sem/config_ssh (recursive=False)
2022-01-18 13:23:04,360 - helpers.py[DEBUG]: Running config-ssh using lock (<FileLock using file '/var/lib/cloud/instances/i-071ba7f9d50245d7d/sem/config_ssh'>)
2022-01-18 13:23:04,361 - util.py[DEBUG]: Restoring selinux mode for /home/centos (recursive=True)
2022-01-18 13:23:04,361 - util.py[DEBUG]: Restoring selinux mode for /home/centos/.ssh (recursive=False)
2022-01-18 13:23:04,362 - util.py[DEBUG]: Changing the ownership of /home/centos/.ssh to 1000:1000
2022-01-18 13:23:04,362 - util.py[DEBUG]: Reading from /etc/ssh/sshd_config (quiet=False)
2022-01-18 13:23:04,363 - util.py[DEBUG]: Read 3907 bytes from /etc/ssh/sshd_config
2022-01-18 13:23:04,363 - util.py[DEBUG]: Restoring selinux mode for /home/centos/.ssh (recursive=True)
2022-01-18 13:23:04,363 - util.py[DEBUG]: Restoring selinux mode for /home/centos/.ssh (recursive=False)
2022-01-18 13:23:04,363 - util.py[DEBUG]: Writing to /home/centos/.ssh/authorized_keys - wb: [384] 390 bytes
2022-01-18 13:23:04,364 - util.py[DEBUG]: Restoring selinux mode for /home/centos/.ssh/authorized_keys (recursive=False)
2022-01-18 13:23:04,364 - util.py[DEBUG]: Restoring selinux mode for /home/centos/.ssh/authorized_keys (recursive=False)
2022-01-18 13:23:04,364 - util.py[DEBUG]: Changing the ownership of /home/centos/.ssh/authorized_keys to 1000:1000
2022-01-18 13:23:04,365 - util.py[DEBUG]: Restoring selinux mode for /home/centos/.ssh (recursive=True)
2022-01-18 13:23:04,365 - util.py[DEBUG]: Restoring selinux mode for /root (recursive=True)
2022-01-18 13:23:04,367 - util.py[DEBUG]: Restoring selinux mode for /root/.ssh (recursive=False)
2022-01-18 13:23:04,367 - util.py[DEBUG]: Changing the ownership of /root/.ssh to 0:0
2022-01-18 13:23:04,367 - util.py[DEBUG]: Reading from /etc/ssh/sshd_config (quiet=False)
2022-01-18 13:23:04,367 - util.py[DEBUG]: Read 3907 bytes from /etc/ssh/sshd_config
2022-01-18 13:23:04,368 - util.py[DEBUG]: Restoring selinux mode for /root/.ssh (recursive=True)
2022-01-18 13:23:04,368 - util.py[DEBUG]: Restoring selinux mode for /root/.ssh (recursive=False)
2022-01-18 13:23:04,368 - util.py[DEBUG]: Writing to /root/.ssh/authorized_keys - wb: [384] 390 bytes
2022-01-18 13:23:04,368 - util.py[DEBUG]: Restoring selinux mode for /root/.ssh/authorized_keys (recursive=False)
2022-01-18 13:23:04,368 - util.py[DEBUG]: Restoring selinux mode for /root/.ssh/authorized_keys (recursive=False)
2022-01-18 13:23:04,369 - util.py[DEBUG]: Changing the ownership of /root/.ssh/authorized_keys to 0:0
2022-01-18 13:23:04,369 - util.py[DEBUG]: Restoring selinux mode for /root/.ssh (recursive=True)
2022-01-18 13:23:04,369 - handlers.py[DEBUG]: finish: init-network/config-ssh: SUCCESS: config-ssh ran successfully
2022-01-18 13:23:04,369 - main.py[DEBUG]: Ran 11 modules with 0 failures
2022-01-18 13:23:04,370 - util.py[DEBUG]: Reading from /proc/uptime (quiet=False)
2022-01-18 13:23:04,370 - util.py[DEBUG]: Read 11 bytes from /proc/uptime
2022-01-18 13:23:04,370 - util.py[DEBUG]: cloud-init mode 'init' took 1.141 seconds (1.14)
2022-01-18 13:23:04,370 - handlers.py[DEBUG]: finish: init-network: SUCCESS: searching for network datasources
2022-01-18 13:23:05,213 - util.py[DEBUG]: Cloud-init v. 0.7.9 running 'modules:config' at Tue, 18 Jan 2022 13:23:05 +0000. Up 13.20 seconds.
2022-01-18 13:23:05,312 - stages.py[DEBUG]: Using distro class <class 'cloudinit.distros.rhel.Distro'>
2022-01-18 13:23:05,313 - stages.py[DEBUG]: Running module mounts (<module 'cloudinit.config.cc_mounts' from '/usr/lib/python2.7/site-packages/cloudinit/config/cc_mounts.pyc'>) with frequency once-per-instance
2022-01-18 13:23:05,313 - handlers.py[DEBUG]: start: modules-config/config-mounts: running config-mounts with frequency once-per-instance
2022-01-18 13:23:05,314 - util.py[DEBUG]: Writing to /var/lib/cloud/instances/i-071ba7f9d50245d7d/sem/config_mounts - wb: [420] 20 bytes
2022-01-18 13:23:05,314 - util.py[DEBUG]: Restoring selinux mode for /var/lib/cloud/instances/i-071ba7f9d50245d7d/sem/config_mounts (recursive=False)
2022-01-18 13:23:05,315 - util.py[DEBUG]: Restoring selinux mode for /var/lib/cloud/instances/i-071ba7f9d50245d7d/sem/config_mounts (recursive=False)
2022-01-18 13:23:05,315 - helpers.py[DEBUG]: Running config-mounts using lock (<FileLock using file '/var/lib/cloud/instances/i-071ba7f9d50245d7d/sem/config_mounts'>)
2022-01-18 13:23:05,316 - cc_mounts.py[DEBUG]: mounts configuration is []
2022-01-18 13:23:05,316 - cc_mounts.py[DEBUG]: Attempting to determine the real name of ephemeral0
2022-01-18 13:23:05,316 - DataSourceEc2.py[DEBUG]: Unable to convert ephemeral0 to a device
2022-01-18 13:23:05,316 - cc_mounts.py[DEBUG]: Ignoring nonexistant default named mount ephemeral0
2022-01-18 13:23:05,316 - cc_mounts.py[DEBUG]: Attempting to determine the real name of swap
2022-01-18 13:23:05,316 - DataSourceEc2.py[DEBUG]: Unable to convert swap to a device
2022-01-18 13:23:05,316 - cc_mounts.py[DEBUG]: Ignoring nonexistant default named mount swap
2022-01-18 13:23:05,316 - cc_mounts.py[DEBUG]: no need to setup swap
2022-01-18 13:23:05,316 - cc_mounts.py[DEBUG]: No modifications to fstab needed.
2022-01-18 13:23:05,316 - handlers.py[DEBUG]: finish: modules-config/config-mounts: SUCCESS: config-mounts ran successfully
2022-01-18 13:23:05,316 - stages.py[DEBUG]: Running module locale (<module 'cloudinit.config.cc_locale' from '/usr/lib/python2.7/site-packages/cloudinit/config/cc_locale.pyc'>) with frequency once-per-instance
2022-01-18 13:23:05,317 - handlers.py[DEBUG]: start: modules-config/config-locale: running config-locale with frequency once-per-instance
2022-01-18 13:23:05,317 - util.py[DEBUG]: Writing to /var/lib/cloud/instances/i-071ba7f9d50245d7d/sem/config_locale - wb: [420] 20 bytes
2022-01-18 13:23:05,317 - util.py[DEBUG]: Restoring selinux mode for /var/lib/cloud/instances/i-071ba7f9d50245d7d/sem/config_locale (recursive=False)
2022-01-18 13:23:05,318 - util.py[DEBUG]: Restoring selinux mode for /var/lib/cloud/instances/i-071ba7f9d50245d7d/sem/config_locale (recursive=False)
2022-01-18 13:23:05,318 - helpers.py[DEBUG]: Running config-locale using lock (<FileLock using file '/var/lib/cloud/instances/i-071ba7f9d50245d7d/sem/config_locale'>)
2022-01-18 13:23:05,318 - cc_locale.py[DEBUG]: Setting locale to en_US.UTF-8
2022-01-18 13:23:05,318 - util.py[DEBUG]: Reading from /etc/locale.conf (quiet=False)
2022-01-18 13:23:05,318 - util.py[DEBUG]: Read 19 bytes from /etc/locale.conf
2022-01-18 13:23:05,319 - util.py[DEBUG]: Writing to /etc/locale.conf - wb: [420] 17 bytes
2022-01-18 13:23:05,319 - util.py[DEBUG]: Restoring selinux mode for /etc/locale.conf (recursive=False)
2022-01-18 13:23:05,319 - util.py[DEBUG]: Restoring selinux mode for /etc/locale.conf (recursive=False)
2022-01-18 13:23:05,320 - handlers.py[DEBUG]: finish: modules-config/config-locale: SUCCESS: config-locale ran successfully
2022-01-18 13:23:05,320 - stages.py[DEBUG]: Running module set-passwords (<module 'cloudinit.config.cc_set_passwords' from '/usr/lib/python2.7/site-packages/cloudinit/config/cc_set_passwords.pyc'>) with frequency once-per-instance
2022-01-18 13:23:05,320 - handlers.py[DEBUG]: start: modules-config/config-set-passwords: running config-set-passwords with frequency once-per-instance
2022-01-18 13:23:05,320 - util.py[DEBUG]: Writing to /var/lib/cloud/instances/i-071ba7f9d50245d7d/sem/config_set_passwords - wb: [420] 20 bytes
2022-01-18 13:23:05,320 - util.py[DEBUG]: Restoring selinux mode for /var/lib/cloud/instances/i-071ba7f9d50245d7d/sem/config_set_passwords (recursive=False)
2022-01-18 13:23:05,321 - util.py[DEBUG]: Restoring selinux mode for /var/lib/cloud/instances/i-071ba7f9d50245d7d/sem/config_set_passwords (recursive=False)
2022-01-18 13:23:05,321 - helpers.py[DEBUG]: Running config-set-passwords using lock (<FileLock using file '/var/lib/cloud/instances/i-071ba7f9d50245d7d/sem/config_set_passwords'>)
2022-01-18 13:23:05,322 - util.py[DEBUG]: Reading from /etc/ssh/sshd_config (quiet=False)
2022-01-18 13:23:05,322 - util.py[DEBUG]: Read 3907 bytes from /etc/ssh/sshd_config
2022-01-18 13:23:05,322 - cc_set_passwords.py[DEBUG]: Replacing auth line 65 with no
2022-01-18 13:23:05,322 - util.py[DEBUG]: Writing to /etc/ssh/sshd_config - wb: [384] 3905 bytes
2022-01-18 13:23:05,323 - util.py[DEBUG]: Restoring selinux mode for /etc/ssh/sshd_config (recursive=False)
2022-01-18 13:23:05,334 - util.py[DEBUG]: Restoring selinux mode for /etc/ssh/sshd_config (recursive=False)
2022-01-18 13:23:05,335 - util.py[DEBUG]: Running command ['service', 'sshd', 'restart'] with allowed return codes [0] (shell=False, capture=True)
2022-01-18 13:23:05,462 - cc_set_passwords.py[DEBUG]: Restarted the ssh daemon
2022-01-18 13:23:05,463 - handlers.py[DEBUG]: finish: modules-config/config-set-passwords: SUCCESS: config-set-passwords ran successfully
2022-01-18 13:23:05,463 - stages.py[DEBUG]: Running module rh_subscription (<module 'cloudinit.config.cc_rh_subscription' from '/usr/lib/python2.7/site-packages/cloudinit/config/cc_rh_subscription.pyc'>) with frequency once-per-instance
2022-01-18 13:23:05,463 - handlers.py[DEBUG]: start: modules-config/config-rh_subscription: running config-rh_subscription with frequency once-per-instance
2022-01-18 13:23:05,464 - util.py[DEBUG]: Writing to /var/lib/cloud/instances/i-071ba7f9d50245d7d/sem/config_rh_subscription - wb: [420] 20 bytes
2022-01-18 13:23:05,465 - util.py[DEBUG]: Restoring selinux mode for /var/lib/cloud/instances/i-071ba7f9d50245d7d/sem/config_rh_subscription (recursive=False)
2022-01-18 13:23:05,465 - util.py[DEBUG]: Restoring selinux mode for /var/lib/cloud/instances/i-071ba7f9d50245d7d/sem/config_rh_subscription (recursive=False)
2022-01-18 13:23:05,466 - helpers.py[DEBUG]: Running config-rh_subscription using lock (<FileLock using file '/var/lib/cloud/instances/i-071ba7f9d50245d7d/sem/config_rh_subscription'>)
2022-01-18 13:23:05,466 - cc_rh_subscription.py[DEBUG]: rh_subscription: module not configured.
2022-01-18 13:23:05,466 - handlers.py[DEBUG]: finish: modules-config/config-rh_subscription: SUCCESS: config-rh_subscription ran successfully
2022-01-18 13:23:05,466 - stages.py[DEBUG]: Running module yum-add-repo (<module 'cloudinit.config.cc_yum_add_repo' from '/usr/lib/python2.7/site-packages/cloudinit/config/cc_yum_add_repo.pyc'>) with frequency once-per-instance
2022-01-18 13:23:05,466 - handlers.py[DEBUG]: start: modules-config/config-yum-add-repo: running config-yum-add-repo with frequency once-per-instance
2022-01-18 13:23:05,466 - util.py[DEBUG]: Writing to /var/lib/cloud/instances/i-071ba7f9d50245d7d/sem/config_yum_add_repo - wb: [420] 20 bytes
2022-01-18 13:23:05,467 - util.py[DEBUG]: Restoring selinux mode for /var/lib/cloud/instances/i-071ba7f9d50245d7d/sem/config_yum_add_repo (recursive=False)
2022-01-18 13:23:05,467 - util.py[DEBUG]: Restoring selinux mode for /var/lib/cloud/instances/i-071ba7f9d50245d7d/sem/config_yum_add_repo (recursive=False)
2022-01-18 13:23:05,468 - helpers.py[DEBUG]: Running config-yum-add-repo using lock (<FileLock using file '/var/lib/cloud/instances/i-071ba7f9d50245d7d/sem/config_yum_add_repo'>)
2022-01-18 13:23:05,468 - cc_yum_add_repo.py[DEBUG]: Skipping module named yum-add-repo, no 'yum_repos' configuration found
2022-01-18 13:23:05,468 - handlers.py[DEBUG]: finish: modules-config/config-yum-add-repo: SUCCESS: config-yum-add-repo ran successfully
2022-01-18 13:23:05,468 - stages.py[DEBUG]: Running module package-update-upgrade-install (<module 'cloudinit.config.cc_package_update_upgrade_install' from '/usr/lib/python2.7/site-packages/cloudinit/config/cc_package_update_upgrade_install.pyc'>) with frequency once-per-instance
2022-01-18 13:23:05,468 - handlers.py[DEBUG]: start: modules-config/config-package-update-upgrade-install: running config-package-update-upgrade-install with frequency once-per-instance
2022-01-18 13:23:05,468 - util.py[DEBUG]: Writing to /var/lib/cloud/instances/i-071ba7f9d50245d7d/sem/config_package_update_upgrade_install - wb: [420] 20 bytes
2022-01-18 13:23:05,469 - util.py[DEBUG]: Restoring selinux mode for /var/lib/cloud/instances/i-071ba7f9d50245d7d/sem/config_package_update_upgrade_install (recursive=False)
2022-01-18 13:23:05,469 - util.py[DEBUG]: Restoring selinux mode for /var/lib/cloud/instances/i-071ba7f9d50245d7d/sem/config_package_update_upgrade_install (recursive=False)
2022-01-18 13:23:05,469 - helpers.py[DEBUG]: Running config-package-update-upgrade-install using lock (<FileLock using file '/var/lib/cloud/instances/i-071ba7f9d50245d7d/sem/config_package_update_upgrade_install'>)
2022-01-18 13:23:05,470 - handlers.py[DEBUG]: finish: modules-config/config-package-update-upgrade-install: SUCCESS: config-package-update-upgrade-install ran successfully
2022-01-18 13:23:05,470 - stages.py[DEBUG]: Running module timezone (<module 'cloudinit.config.cc_timezone' from '/usr/lib/python2.7/site-packages/cloudinit/config/cc_timezone.pyc'>) with frequency once-per-instance
2022-01-18 13:23:05,470 - handlers.py[DEBUG]: start: modules-config/config-timezone: running config-timezone with frequency once-per-instance
2022-01-18 13:23:05,470 - util.py[DEBUG]: Writing to /var/lib/cloud/instances/i-071ba7f9d50245d7d/sem/config_timezone - wb: [420] 20 bytes
2022-01-18 13:23:05,471 - util.py[DEBUG]: Restoring selinux mode for /var/lib/cloud/instances/i-071ba7f9d50245d7d/sem/config_timezone (recursive=False)
2022-01-18 13:23:05,472 - util.py[DEBUG]: Restoring selinux mode for /var/lib/cloud/instances/i-071ba7f9d50245d7d/sem/config_timezone (recursive=False)
2022-01-18 13:23:05,472 - helpers.py[DEBUG]: Running config-timezone using lock (<FileLock using file '/var/lib/cloud/instances/i-071ba7f9d50245d7d/sem/config_timezone'>)
2022-01-18 13:23:05,472 - cc_timezone.py[DEBUG]: Skipping module named timezone, no 'timezone' specified
2022-01-18 13:23:05,472 - handlers.py[DEBUG]: finish: modules-config/config-timezone: SUCCESS: config-timezone ran successfully
2022-01-18 13:23:05,472 - stages.py[DEBUG]: Running module puppet (<module 'cloudinit.config.cc_puppet' from '/usr/lib/python2.7/site-packages/cloudinit/config/cc_puppet.pyc'>) with frequency once-per-instance
2022-01-18 13:23:05,472 - handlers.py[DEBUG]: start: modules-config/config-puppet: running config-puppet with frequency once-per-instance
2022-01-18 13:23:05,473 - util.py[DEBUG]: Writing to /var/lib/cloud/instances/i-071ba7f9d50245d7d/sem/config_puppet - wb: [420] 20 bytes
2022-01-18 13:23:05,473 - util.py[DEBUG]: Restoring selinux mode for /var/lib/cloud/instances/i-071ba7f9d50245d7d/sem/config_puppet (recursive=False)
2022-01-18 13:23:05,474 - util.py[DEBUG]: Restoring selinux mode for /var/lib/cloud/instances/i-071ba7f9d50245d7d/sem/config_puppet (recursive=False)
2022-01-18 13:23:05,474 - helpers.py[DEBUG]: Running config-puppet using lock (<FileLock using file '/var/lib/cloud/instances/i-071ba7f9d50245d7d/sem/config_puppet'>)
2022-01-18 13:23:05,474 - cc_puppet.py[DEBUG]: Skipping module named puppet, no 'puppet' configuration found
2022-01-18 13:23:05,474 - handlers.py[DEBUG]: finish: modules-config/config-puppet: SUCCESS: config-puppet ran successfully
2022-01-18 13:23:05,474 - stages.py[DEBUG]: Running module chef (<module 'cloudinit.config.cc_chef' from '/usr/lib/python2.7/site-packages/cloudinit/config/cc_chef.pyc'>) with frequency once-per-instance
2022-01-18 13:23:05,474 - handlers.py[DEBUG]: start: modules-config/config-chef: running config-chef with frequency once-per-instance
2022-01-18 13:23:05,475 - util.py[DEBUG]: Writing to /var/lib/cloud/instances/i-071ba7f9d50245d7d/sem/config_chef - wb: [420] 20 bytes
2022-01-18 13:23:05,475 - util.py[DEBUG]: Restoring selinux mode for /var/lib/cloud/instances/i-071ba7f9d50245d7d/sem/config_chef (recursive=False)
2022-01-18 13:23:05,475 - util.py[DEBUG]: Restoring selinux mode for /var/lib/cloud/instances/i-071ba7f9d50245d7d/sem/config_chef (recursive=False)
2022-01-18 13:23:05,476 - helpers.py[DEBUG]: Running config-chef using lock (<FileLock using file '/var/lib/cloud/instances/i-071ba7f9d50245d7d/sem/config_chef'>)
2022-01-18 13:23:05,476 - cc_chef.py[DEBUG]: Skipping module named chef, no 'chef' key in configuration
2022-01-18 13:23:05,476 - handlers.py[DEBUG]: finish: modules-config/config-chef: SUCCESS: config-chef ran successfully
2022-01-18 13:23:05,476 - stages.py[DEBUG]: Running module salt-minion (<module 'cloudinit.config.cc_salt_minion' from '/usr/lib/python2.7/site-packages/cloudinit/config/cc_salt_minion.pyc'>) with frequency once-per-instance
2022-01-18 13:23:05,476 - handlers.py[DEBUG]: start: modules-config/config-salt-minion: running config-salt-minion with frequency once-per-instance
2022-01-18 13:23:05,476 - util.py[DEBUG]: Writing to /var/lib/cloud/instances/i-071ba7f9d50245d7d/sem/config_salt_minion - wb: [420] 20 bytes
2022-01-18 13:23:05,477 - util.py[DEBUG]: Restoring selinux mode for /var/lib/cloud/instances/i-071ba7f9d50245d7d/sem/config_salt_minion (recursive=False)
2022-01-18 13:23:05,477 - util.py[DEBUG]: Restoring selinux mode for /var/lib/cloud/instances/i-071ba7f9d50245d7d/sem/config_salt_minion (recursive=False)
2022-01-18 13:23:05,478 - helpers.py[DEBUG]: Running config-salt-minion using lock (<FileLock using file '/var/lib/cloud/instances/i-071ba7f9d50245d7d/sem/config_salt_minion'>)
2022-01-18 13:23:05,478 - cc_salt_minion.py[DEBUG]: Skipping module named salt-minion, no 'salt_minion' key in configuration
2022-01-18 13:23:05,478 - handlers.py[DEBUG]: finish: modules-config/config-salt-minion: SUCCESS: config-salt-minion ran successfully
2022-01-18 13:23:05,478 - stages.py[DEBUG]: Running module mcollective (<module 'cloudinit.config.cc_mcollective' from '/usr/lib/python2.7/site-packages/cloudinit/config/cc_mcollective.pyc'>) with frequency once-per-instance
2022-01-18 13:23:05,478 - handlers.py[DEBUG]: start: modules-config/config-mcollective: running config-mcollective with frequency once-per-instance
2022-01-18 13:23:05,478 - util.py[DEBUG]: Writing to /var/lib/cloud/instances/i-071ba7f9d50245d7d/sem/config_mcollective - wb: [420] 20 bytes
2022-01-18 13:23:05,479 - util.py[DEBUG]: Restoring selinux mode for /var/lib/cloud/instances/i-071ba7f9d50245d7d/sem/config_mcollective (recursive=False)
2022-01-18 13:23:05,479 - util.py[DEBUG]: Restoring selinux mode for /var/lib/cloud/instances/i-071ba7f9d50245d7d/sem/config_mcollective (recursive=False)
2022-01-18 13:23:05,480 - helpers.py[DEBUG]: Running config-mcollective using lock (<FileLock using file '/var/lib/cloud/instances/i-071ba7f9d50245d7d/sem/config_mcollective'>)
2022-01-18 13:23:05,480 - cc_mcollective.py[DEBUG]: Skipping module named mcollective, no 'mcollective' key in configuration
2022-01-18 13:23:05,480 - handlers.py[DEBUG]: finish: modules-config/config-mcollective: SUCCESS: config-mcollective ran successfully
2022-01-18 13:23:05,480 - stages.py[DEBUG]: Running module disable-ec2-metadata (<module 'cloudinit.config.cc_disable_ec2_metadata' from '/usr/lib/python2.7/site-packages/cloudinit/config/cc_disable_ec2_metadata.pyc'>) with frequency always
2022-01-18 13:23:05,480 - handlers.py[DEBUG]: start: modules-config/config-disable-ec2-metadata: running config-disable-ec2-metadata with frequency always
2022-01-18 13:23:05,480 - helpers.py[DEBUG]: Running config-disable-ec2-metadata using lock (<cloudinit.helpers.DummyLock object at 0x7f6296805550>)
2022-01-18 13:23:05,480 - cc_disable_ec2_metadata.py[DEBUG]: Skipping module named disable-ec2-metadata, disabling the ec2 route not enabled
2022-01-18 13:23:05,480 - handlers.py[DEBUG]: finish: modules-config/config-disable-ec2-metadata: SUCCESS: config-disable-ec2-metadata ran successfully
2022-01-18 13:23:05,480 - stages.py[DEBUG]: Running module runcmd (<module 'cloudinit.config.cc_runcmd' from '/usr/lib/python2.7/site-packages/cloudinit/config/cc_runcmd.pyc'>) with frequency once-per-instance
2022-01-18 13:23:05,481 - handlers.py[DEBUG]: start: modules-config/config-runcmd: running config-runcmd with frequency once-per-instance
2022-01-18 13:23:05,481 - util.py[DEBUG]: Writing to /var/lib/cloud/instances/i-071ba7f9d50245d7d/sem/config_runcmd - wb: [420] 20 bytes
2022-01-18 13:23:05,481 - util.py[DEBUG]: Restoring selinux mode for /var/lib/cloud/instances/i-071ba7f9d50245d7d/sem/config_runcmd (recursive=False)
2022-01-18 13:23:05,482 - util.py[DEBUG]: Restoring selinux mode for /var/lib/cloud/instances/i-071ba7f9d50245d7d/sem/config_runcmd (recursive=False)
2022-01-18 13:23:05,482 - helpers.py[DEBUG]: Running config-runcmd using lock (<FileLock using file '/var/lib/cloud/instances/i-071ba7f9d50245d7d/sem/config_runcmd'>)
2022-01-18 13:23:05,482 - cc_runcmd.py[DEBUG]: Skipping module named runcmd, no 'runcmd' key in configuration
2022-01-18 13:23:05,483 - handlers.py[DEBUG]: finish: modules-config/config-runcmd: SUCCESS: config-runcmd ran successfully
2022-01-18 13:23:05,483 - main.py[DEBUG]: Ran 13 modules with 0 failures
2022-01-18 13:23:05,483 - util.py[DEBUG]: Reading from /proc/uptime (quiet=False)
2022-01-18 13:23:05,483 - util.py[DEBUG]: Read 11 bytes from /proc/uptime
2022-01-18 13:23:05,483 - util.py[DEBUG]: cloud-init mode 'modules' took 0.455 seconds (0.45)
2022-01-18 13:23:05,484 - handlers.py[DEBUG]: finish: modules-config: SUCCESS: running modules for config
2022-01-18 13:23:05,746 - util.py[DEBUG]: Cloud-init v. 0.7.9 running 'modules:final' at Tue, 18 Jan 2022 13:23:05 +0000. Up 13.84 seconds.
2022-01-18 13:23:05,769 - stages.py[DEBUG]: Using distro class <class 'cloudinit.distros.rhel.Distro'>
2022-01-18 13:23:05,769 - stages.py[DEBUG]: Running module rightscale_userdata (<module 'cloudinit.config.cc_rightscale_userdata' from '/usr/lib/python2.7/site-packages/cloudinit/config/cc_rightscale_userdata.pyc'>) with frequency once-per-instance
2022-01-18 13:23:05,769 - handlers.py[DEBUG]: start: modules-final/config-rightscale_userdata: running config-rightscale_userdata with frequency once-per-instance
2022-01-18 13:23:05,770 - util.py[DEBUG]: Writing to /var/lib/cloud/instances/i-071ba7f9d50245d7d/sem/config_rightscale_userdata - wb: [420] 20 bytes
2022-01-18 13:23:05,770 - util.py[DEBUG]: Restoring selinux mode for /var/lib/cloud/instances/i-071ba7f9d50245d7d/sem/config_rightscale_userdata (recursive=False)
2022-01-18 13:23:05,771 - util.py[DEBUG]: Restoring selinux mode for /var/lib/cloud/instances/i-071ba7f9d50245d7d/sem/config_rightscale_userdata (recursive=False)
2022-01-18 13:23:05,771 - helpers.py[DEBUG]: Running config-rightscale_userdata using lock (<FileLock using file '/var/lib/cloud/instances/i-071ba7f9d50245d7d/sem/config_rightscale_userdata'>)
2022-01-18 13:23:05,771 - cc_rightscale_userdata.py[DEBUG]: Failed to get raw userdata in module rightscale_userdata
2022-01-18 13:23:05,771 - handlers.py[DEBUG]: finish: modules-final/config-rightscale_userdata: SUCCESS: config-rightscale_userdata ran successfully
2022-01-18 13:23:05,771 - stages.py[DEBUG]: Running module scripts-per-once (<module 'cloudinit.config.cc_scripts_per_once' from '/usr/lib/python2.7/site-packages/cloudinit/config/cc_scripts_per_once.pyc'>) with frequency once
2022-01-18 13:23:05,772 - handlers.py[DEBUG]: start: modules-final/config-scripts-per-once: running config-scripts-per-once with frequency once
2022-01-18 13:23:05,772 - util.py[DEBUG]: Writing to /var/lib/cloud/sem/config_scripts_per_once.once - wb: [420] 20 bytes
2022-01-18 13:23:05,772 - util.py[DEBUG]: Restoring selinux mode for /var/lib/cloud/sem/config_scripts_per_once.once (recursive=False)
2022-01-18 13:23:05,773 - util.py[DEBUG]: Restoring selinux mode for /var/lib/cloud/sem/config_scripts_per_once.once (recursive=False)
2022-01-18 13:23:05,773 - helpers.py[DEBUG]: Running config-scripts-per-once using lock (<FileLock using file '/var/lib/cloud/sem/config_scripts_per_once.once'>)
2022-01-18 13:23:05,773 - handlers.py[DEBUG]: finish: modules-final/config-scripts-per-once: SUCCESS: config-scripts-per-once ran successfully
2022-01-18 13:23:05,773 - stages.py[DEBUG]: Running module scripts-per-boot (<module 'cloudinit.config.cc_scripts_per_boot' from '/usr/lib/python2.7/site-packages/cloudinit/config/cc_scripts_per_boot.pyc'>) with frequency always
2022-01-18 13:23:05,773 - handlers.py[DEBUG]: start: modules-final/config-scripts-per-boot: running config-scripts-per-boot with frequency always
2022-01-18 13:23:05,774 - helpers.py[DEBUG]: Running config-scripts-per-boot using lock (<cloudinit.helpers.DummyLock object at 0x7f22e21ec5d0>)
2022-01-18 13:23:05,774 - handlers.py[DEBUG]: finish: modules-final/config-scripts-per-boot: SUCCESS: config-scripts-per-boot ran successfully
2022-01-18 13:23:05,774 - stages.py[DEBUG]: Running module scripts-per-instance (<module 'cloudinit.config.cc_scripts_per_instance' from '/usr/lib/python2.7/site-packages/cloudinit/config/cc_scripts_per_instance.pyc'>) with frequency once-per-instance
2022-01-18 13:23:05,774 - handlers.py[DEBUG]: start: modules-final/config-scripts-per-instance: running config-scripts-per-instance with frequency once-per-instance
2022-01-18 13:23:05,774 - util.py[DEBUG]: Writing to /var/lib/cloud/instances/i-071ba7f9d50245d7d/sem/config_scripts_per_instance - wb: [420] 20 bytes
2022-01-18 13:23:05,775 - util.py[DEBUG]: Restoring selinux mode for /var/lib/cloud/instances/i-071ba7f9d50245d7d/sem/config_scripts_per_instance (recursive=False)
2022-01-18 13:23:05,775 - util.py[DEBUG]: Restoring selinux mode for /var/lib/cloud/instances/i-071ba7f9d50245d7d/sem/config_scripts_per_instance (recursive=False)
2022-01-18 13:23:05,775 - helpers.py[DEBUG]: Running config-scripts-per-instance using lock (<FileLock using file '/var/lib/cloud/instances/i-071ba7f9d50245d7d/sem/config_scripts_per_instance'>)
2022-01-18 13:23:05,776 - handlers.py[DEBUG]: finish: modules-final/config-scripts-per-instance: SUCCESS: config-scripts-per-instance ran successfully
2022-01-18 13:23:05,776 - stages.py[DEBUG]: Running module scripts-user (<module 'cloudinit.config.cc_scripts_user' from '/usr/lib/python2.7/site-packages/cloudinit/config/cc_scripts_user.pyc'>) with frequency once-per-instance
2022-01-18 13:23:05,776 - handlers.py[DEBUG]: start: modules-final/config-scripts-user: running config-scripts-user with frequency once-per-instance
2022-01-18 13:23:05,776 - util.py[DEBUG]: Writing to /var/lib/cloud/instances/i-071ba7f9d50245d7d/sem/config_scripts_user - wb: [420] 20 bytes
2022-01-18 13:23:05,776 - util.py[DEBUG]: Restoring selinux mode for /var/lib/cloud/instances/i-071ba7f9d50245d7d/sem/config_scripts_user (recursive=False)
2022-01-18 13:23:05,777 - util.py[DEBUG]: Restoring selinux mode for /var/lib/cloud/instances/i-071ba7f9d50245d7d/sem/config_scripts_user (recursive=False)
2022-01-18 13:23:05,777 - helpers.py[DEBUG]: Running config-scripts-user using lock (<FileLock using file '/var/lib/cloud/instances/i-071ba7f9d50245d7d/sem/config_scripts_user'>)
2022-01-18 13:23:05,777 - handlers.py[DEBUG]: finish: modules-final/config-scripts-user: SUCCESS: config-scripts-user ran successfully
2022-01-18 13:23:05,777 - stages.py[DEBUG]: Running module ssh-authkey-fingerprints (<module 'cloudinit.config.cc_ssh_authkey_fingerprints' from '/usr/lib/python2.7/site-packages/cloudinit/config/cc_ssh_authkey_fingerprints.pyc'>) with frequency once-per-instance
2022-01-18 13:23:05,778 - handlers.py[DEBUG]: start: modules-final/config-ssh-authkey-fingerprints: running config-ssh-authkey-fingerprints with frequency once-per-instance
2022-01-18 13:23:05,778 - util.py[DEBUG]: Writing to /var/lib/cloud/instances/i-071ba7f9d50245d7d/sem/config_ssh_authkey_fingerprints - wb: [420] 20 bytes
2022-01-18 13:23:05,778 - util.py[DEBUG]: Restoring selinux mode for /var/lib/cloud/instances/i-071ba7f9d50245d7d/sem/config_ssh_authkey_fingerprints (recursive=False)
2022-01-18 13:23:05,779 - util.py[DEBUG]: Restoring selinux mode for /var/lib/cloud/instances/i-071ba7f9d50245d7d/sem/config_ssh_authkey_fingerprints (recursive=False)
2022-01-18 13:23:05,779 - helpers.py[DEBUG]: Running config-ssh-authkey-fingerprints using lock (<FileLock using file '/var/lib/cloud/instances/i-071ba7f9d50245d7d/sem/config_ssh_authkey_fingerprints'>)
2022-01-18 13:23:05,780 - util.py[DEBUG]: Reading from /etc/ssh/sshd_config (quiet=False)
2022-01-18 13:23:05,780 - util.py[DEBUG]: Read 3905 bytes from /etc/ssh/sshd_config
2022-01-18 13:23:05,781 - util.py[DEBUG]: Restoring selinux mode for /home/centos/.ssh (recursive=True)
2022-01-18 13:23:05,781 - util.py[DEBUG]: Reading from /home/centos/.ssh/authorized_keys (quiet=False)
2022-01-18 13:23:05,781 - util.py[DEBUG]: Read 390 bytes from /home/centos/.ssh/authorized_keys
2022-01-18 13:23:05,812 - handlers.py[DEBUG]: finish: modules-final/config-ssh-authkey-fingerprints: SUCCESS: config-ssh-authkey-fingerprints ran successfully
2022-01-18 13:23:05,812 - stages.py[DEBUG]: Running module keys-to-console (<module 'cloudinit.config.cc_keys_to_console' from '/usr/lib/python2.7/site-packages/cloudinit/config/cc_keys_to_console.pyc'>) with frequency once-per-instance
2022-01-18 13:23:05,812 - handlers.py[DEBUG]: start: modules-final/config-keys-to-console: running config-keys-to-console with frequency once-per-instance
2022-01-18 13:23:05,813 - util.py[DEBUG]: Writing to /var/lib/cloud/instances/i-071ba7f9d50245d7d/sem/config_keys_to_console - wb: [420] 20 bytes
2022-01-18 13:23:05,813 - util.py[DEBUG]: Restoring selinux mode for /var/lib/cloud/instances/i-071ba7f9d50245d7d/sem/config_keys_to_console (recursive=False)
2022-01-18 13:23:05,814 - util.py[DEBUG]: Restoring selinux mode for /var/lib/cloud/instances/i-071ba7f9d50245d7d/sem/config_keys_to_console (recursive=False)
2022-01-18 13:23:05,814 - helpers.py[DEBUG]: Running config-keys-to-console using lock (<FileLock using file '/var/lib/cloud/instances/i-071ba7f9d50245d7d/sem/config_keys_to_console'>)
2022-01-18 13:23:05,814 - util.py[DEBUG]: Running command ['/usr/libexec/cloud-init/write-ssh-key-fingerprints', '', 'ssh-dss'] with allowed return codes [0] (shell=False, capture=True)
2022-01-18 13:23:05,883 - handlers.py[DEBUG]: finish: modules-final/config-keys-to-console: SUCCESS: config-keys-to-console ran successfully
2022-01-18 13:23:05,883 - stages.py[DEBUG]: Running module phone-home (<module 'cloudinit.config.cc_phone_home' from '/usr/lib/python2.7/site-packages/cloudinit/config/cc_phone_home.pyc'>) with frequency once-per-instance
2022-01-18 13:23:05,883 - handlers.py[DEBUG]: start: modules-final/config-phone-home: running config-phone-home with frequency once-per-instance
2022-01-18 13:23:05,883 - util.py[DEBUG]: Writing to /var/lib/cloud/instances/i-071ba7f9d50245d7d/sem/config_phone_home - wb: [420] 20 bytes
2022-01-18 13:23:05,884 - util.py[DEBUG]: Restoring selinux mode for /var/lib/cloud/instances/i-071ba7f9d50245d7d/sem/config_phone_home (recursive=False)
2022-01-18 13:23:05,885 - util.py[DEBUG]: Restoring selinux mode for /var/lib/cloud/instances/i-071ba7f9d50245d7d/sem/config_phone_home (recursive=False)
2022-01-18 13:23:05,885 - helpers.py[DEBUG]: Running config-phone-home using lock (<FileLock using file '/var/lib/cloud/instances/i-071ba7f9d50245d7d/sem/config_phone_home'>)
2022-01-18 13:23:05,885 - cc_phone_home.py[DEBUG]: Skipping module named phone-home, no 'phone_home' configuration found
2022-01-18 13:23:05,885 - handlers.py[DEBUG]: finish: modules-final/config-phone-home: SUCCESS: config-phone-home ran successfully
2022-01-18 13:23:05,885 - stages.py[DEBUG]: Running module final-message (<module 'cloudinit.config.cc_final_message' from '/usr/lib/python2.7/site-packages/cloudinit/config/cc_final_message.pyc'>) with frequency always
2022-01-18 13:23:05,886 - handlers.py[DEBUG]: start: modules-final/config-final-message: running config-final-message with frequency always
2022-01-18 13:23:05,886 - helpers.py[DEBUG]: Running config-final-message using lock (<cloudinit.helpers.DummyLock object at 0x7f22e21f3390>)
2022-01-18 13:23:05,886 - util.py[DEBUG]: Reading from /proc/uptime (quiet=False)
2022-01-18 13:23:05,886 - util.py[DEBUG]: Read 11 bytes from /proc/uptime
2022-01-18 13:23:05,889 - util.py[DEBUG]: Cloud-init v. 0.7.9 finished at Tue, 18 Jan 2022 13:23:05 +0000. Datasource DataSourceEc2.  Up 14.03 seconds
2022-01-18 13:23:05,890 - util.py[DEBUG]: Writing to /var/lib/cloud/instance/boot-finished - wb: [420] 51 bytes
2022-01-18 13:23:05,890 - util.py[DEBUG]: Restoring selinux mode for /var/lib/cloud/instances/i-071ba7f9d50245d7d/boot-finished (recursive=False)
2022-01-18 13:23:05,891 - util.py[DEBUG]: Restoring selinux mode for /var/lib/cloud/instances/i-071ba7f9d50245d7d/boot-finished (recursive=False)
2022-01-18 13:23:05,898 - handlers.py[DEBUG]: finish: modules-final/config-final-message: SUCCESS: config-final-message ran successfully
2022-01-18 13:23:05,898 - stages.py[DEBUG]: Running module power-state-change (<module 'cloudinit.config.cc_power_state_change' from '/usr/lib/python2.7/site-packages/cloudinit/config/cc_power_state_change.pyc'>) with frequency once-per-instance
2022-01-18 13:23:05,898 - handlers.py[DEBUG]: start: modules-final/config-power-state-change: running config-power-state-change with frequency once-per-instance
2022-01-18 13:23:05,898 - util.py[DEBUG]: Writing to /var/lib/cloud/instances/i-071ba7f9d50245d7d/sem/config_power_state_change - wb: [420] 19 bytes
2022-01-18 13:23:05,899 - util.py[DEBUG]: Restoring selinux mode for /var/lib/cloud/instances/i-071ba7f9d50245d7d/sem/config_power_state_change (recursive=False)
2022-01-18 13:23:05,899 - util.py[DEBUG]: Restoring selinux mode for /var/lib/cloud/instances/i-071ba7f9d50245d7d/sem/config_power_state_change (recursive=False)
2022-01-18 13:23:05,900 - helpers.py[DEBUG]: Running config-power-state-change using lock (<FileLock using file '/var/lib/cloud/instances/i-071ba7f9d50245d7d/sem/config_power_state_change'>)
2022-01-18 13:23:05,900 - cc_power_state_change.py[DEBUG]: no power_state provided. doing nothing
2022-01-18 13:23:05,900 - handlers.py[DEBUG]: finish: modules-final/config-power-state-change: SUCCESS: config-power-state-change ran successfully
2022-01-18 13:23:05,900 - main.py[DEBUG]: Ran 10 modules with 0 failures
2022-01-18 13:23:05,901 - util.py[DEBUG]: Creating symbolic link from '/run/cloud-init/result.json' => '../../var/lib/cloud/data/result.json'
2022-01-18 13:23:05,901 - util.py[DEBUG]: Reading from /proc/uptime (quiet=False)
2022-01-18 13:23:05,901 - util.py[DEBUG]: Read 11 bytes from /proc/uptime
2022-01-18 13:23:05,901 - util.py[DEBUG]: cloud-init mode 'modules' took 0.214 seconds (0.22)
2022-01-18 13:23:05,901 - handlers.py[DEBUG]: finish: modules-final: SUCCESS: running modules for final
