2022-01-18 13:22:44,780 - util.py[DEBUG]: Cloud-init v. 0.7.9 running 'init-local' at Tue, 18 Jan 2022 13:22:44 +0000. Up 7.02 seconds.
2022-01-18 13:22:44,785 - util.py[DEBUG]: Restoring selinux mode for /var/lib/cloud (recursive=False)
2022-01-18 13:22:44,786 - util.py[DEBUG]: Restoring selinux mode for /var/lib/cloud (recursive=True)
2022-01-18 13:22:44,787 - util.py[DEBUG]: Restoring selinux mode for /var/lib/cloud/scripts (recursive=False)
2022-01-18 13:22:44,788 - util.py[DEBUG]: Restoring selinux mode for /var/lib/cloud/scripts (recursive=True)
2022-01-18 13:22:44,788 - util.py[DEBUG]: Restoring selinux mode for /var/lib/cloud/scripts/per-instance (recursive=False)
2022-01-18 13:22:44,789 - util.py[DEBUG]: Restoring selinux mode for /var/lib/cloud/scripts (recursive=True)
2022-01-18 13:22:44,790 - util.py[DEBUG]: Restoring selinux mode for /var/lib/cloud/scripts/per-once (recursive=False)
2022-01-18 13:22:44,790 - util.py[DEBUG]: Restoring selinux mode for /var/lib/cloud/scripts (recursive=True)
2022-01-18 13:22:44,791 - util.py[DEBUG]: Restoring selinux mode for /var/lib/cloud/scripts/per-boot (recursive=False)
2022-01-18 13:22:44,792 - util.py[DEBUG]: Restoring selinux mode for /var/lib/cloud/scripts (recursive=True)
2022-01-18 13:22:44,793 - util.py[DEBUG]: Restoring selinux mode for /var/lib/cloud/scripts/vendor (recursive=False)
2022-01-18 13:22:44,793 - util.py[DEBUG]: Restoring selinux mode for /var/lib/cloud (recursive=True)
2022-01-18 13:22:44,795 - util.py[DEBUG]: Restoring selinux mode for /var/lib/cloud/seed (recursive=False)
2022-01-18 13:22:44,796 - util.py[DEBUG]: Restoring selinux mode for /var/lib/cloud (recursive=True)
2022-01-18 13:22:44,798 - util.py[DEBUG]: Restoring selinux mode for /var/lib/cloud/instances (recursive=False)
2022-01-18 13:22:44,798 - util.py[DEBUG]: Restoring selinux mode for /var/lib/cloud (recursive=True)
2022-01-18 13:22:44,801 - util.py[DEBUG]: Restoring selinux mode for /var/lib/cloud/handlers (recursive=False)
2022-01-18 13:22:44,801 - util.py[DEBUG]: Restoring selinux mode for /var/lib/cloud (recursive=True)
2022-01-18 13:22:44,803 - util.py[DEBUG]: Restoring selinux mode for /var/lib/cloud/sem (recursive=False)
2022-01-18 13:22:44,804 - util.py[DEBUG]: Restoring selinux mode for /var/lib/cloud/data (recursive=False)
2022-01-18 13:22:44,805 - util.py[DEBUG]: Writing to /var/log/cloud-init.log - ab: [384] 0 bytes
2022-01-18 13:22:44,805 - util.py[DEBUG]: Restoring selinux mode for /var/log/cloud-init.log (recursive=False)
2022-01-18 13:22:44,805 - util.py[DEBUG]: Restoring selinux mode for /var/log/cloud-init.log (recursive=False)
2022-01-18 13:22:44,806 - util.py[DEBUG]: Attempting to remove /var/lib/cloud/instance/boot-finished
2022-01-18 13:22:44,806 - util.py[DEBUG]: Attempting to remove /var/lib/cloud/data/no-net
2022-01-18 13:22:44,806 - handlers.py[DEBUG]: start: init-local/check-cache: attempting to read from cache [check]
2022-01-18 13:22:44,806 - util.py[DEBUG]: Reading from /var/lib/cloud/instance/obj.pkl (quiet=False)
2022-01-18 13:22:44,806 - stages.py[DEBUG]: no cache found
2022-01-18 13:22:44,806 - handlers.py[DEBUG]: finish: init-local/check-cache: SUCCESS: no cache found
2022-01-18 13:22:44,806 - util.py[DEBUG]: Attempting to remove /var/lib/cloud/instance
2022-01-18 13:22:44,824 - stages.py[DEBUG]: Using distro class <class 'cloudinit.distros.rhel.Distro'>
2022-01-18 13:22:44,824 - __init__.py[DEBUG]: Looking for for data source in: ['NoCloud', 'ConfigDrive', 'OpenNebula', 'DigitalOcean', 'Azure', 'AltCloud', 'OVF', 'MAAS', 'GCE', 'OpenStack', 'AliYun', 'Ec2', 'CloudSigma', 'CloudStack', 'SmartOS', 'Bigstep', 'None'], via packages ['', u'cloudinit.sources'] that matches dependencies ['FILESYSTEM']
2022-01-18 13:22:44,896 - __init__.py[DEBUG]: Searching for local data source in: [u'DataSourceNoCloud', u'DataSourceConfigDrive', u'DataSourceOpenNebula', u'DataSourceDigitalOcean', u'DataSourceOVF', u'DataSourceCloudSigma', u'DataSourceSmartOS']
2022-01-18 13:22:44,897 - handlers.py[DEBUG]: start: init-local/search-NoCloud: searching for local data from DataSourceNoCloud
2022-01-18 13:22:44,897 - __init__.py[DEBUG]: Seeing if we can get any data from <class 'cloudinit.sources.DataSourceNoCloud.DataSourceNoCloud'>
2022-01-18 13:22:44,897 - util.py[DEBUG]: Reading from /var/lib/cloud/seed/nocloud/user-data (quiet=False)
2022-01-18 13:22:44,897 - util.py[DEBUG]: Reading from /var/lib/cloud/seed/nocloud/meta-data (quiet=False)
2022-01-18 13:22:44,897 - util.py[DEBUG]: Reading from /var/lib/cloud/seed/nocloud/vendor-data (quiet=False)
2022-01-18 13:22:44,897 - util.py[DEBUG]: Reading from /var/lib/cloud/seed/nocloud/network-config (quiet=False)
2022-01-18 13:22:44,897 - util.py[DEBUG]: Reading from /var/lib/cloud/seed/nocloud-net/user-data (quiet=False)
2022-01-18 13:22:44,897 - util.py[DEBUG]: Reading from /var/lib/cloud/seed/nocloud-net/meta-data (quiet=False)
2022-01-18 13:22:44,897 - util.py[DEBUG]: Reading from /var/lib/cloud/seed/nocloud-net/vendor-data (quiet=False)
2022-01-18 13:22:44,897 - util.py[DEBUG]: Reading from /var/lib/cloud/seed/nocloud-net/network-config (quiet=False)
2022-01-18 13:22:44,897 - util.py[DEBUG]: Running command ['blkid', '-odevice', '/dev/sr0'] with allowed return codes [0, 2] (shell=False, capture=True)
2022-01-18 13:22:44,904 - util.py[DEBUG]: Running command ['blkid', '-odevice', '/dev/sr1'] with allowed return codes [0, 2] (shell=False, capture=True)
2022-01-18 13:22:44,906 - util.py[DEBUG]: Running command ['blkid', '-tTYPE=vfat', '-odevice'] with allowed return codes [0, 2] (shell=False, capture=True)
2022-01-18 13:22:44,911 - util.py[DEBUG]: Running command ['blkid', '-tTYPE=iso9660', '-odevice'] with allowed return codes [0, 2] (shell=False, capture=True)
2022-01-18 13:22:44,914 - util.py[DEBUG]: Running command ['blkid', '-tLABEL=cidata', '-odevice'] with allowed return codes [0, 2] (shell=False, capture=True)
2022-01-18 13:22:44,917 - handlers.py[DEBUG]: finish: init-local/search-NoCloud: SUCCESS: no local data found from DataSourceNoCloud
2022-01-18 13:22:44,917 - handlers.py[DEBUG]: start: init-local/search-ConfigDrive: searching for local data from DataSourceConfigDrive
2022-01-18 13:22:44,917 - __init__.py[DEBUG]: Seeing if we can get any data from <class 'cloudinit.sources.DataSourceConfigDrive.DataSourceConfigDrive'>
2022-01-18 13:22:44,918 - util.py[DEBUG]: Running command ['blkid', '-odevice', '/dev/sr0'] with allowed return codes [0, 2] (shell=False, capture=True)
2022-01-18 13:22:44,920 - util.py[DEBUG]: Running command ['blkid', '-odevice', '/dev/sr1'] with allowed return codes [0, 2] (shell=False, capture=True)
2022-01-18 13:22:44,922 - util.py[DEBUG]: Running command ['blkid', '-odevice', '/dev/cd0'] with allowed return codes [0, 2] (shell=False, capture=True)
2022-01-18 13:22:44,924 - util.py[DEBUG]: Running command ['blkid', '-odevice', '/dev/cd1'] with allowed return codes [0, 2] (shell=False, capture=True)
2022-01-18 13:22:44,926 - util.py[DEBUG]: Running command ['blkid', '-tTYPE=vfat', '-odevice'] with allowed return codes [0, 2] (shell=False, capture=True)
2022-01-18 13:22:44,929 - util.py[DEBUG]: Running command ['blkid', '-tTYPE=iso9660', '-odevice'] with allowed return codes [0, 2] (shell=False, capture=True)
2022-01-18 13:22:44,932 - util.py[DEBUG]: Running command ['blkid', '-tLABEL=config-2', '-odevice'] with allowed return codes [0, 2] (shell=False, capture=True)
2022-01-18 13:22:44,935 - handlers.py[DEBUG]: finish: init-local/search-ConfigDrive: SUCCESS: no local data found from DataSourceConfigDrive
2022-01-18 13:22:44,936 - handlers.py[DEBUG]: start: init-local/search-OpenNebula: searching for local data from DataSourceOpenNebula
2022-01-18 13:22:44,936 - __init__.py[DEBUG]: Seeing if we can get any data from <class 'cloudinit.sources.DataSourceOpenNebula.DataSourceOpenNebula'>
2022-01-18 13:22:44,936 - util.py[DEBUG]: Running command ['blkid', '-tLABEL=CONTEXT', '-odevice'] with allowed return codes [0, 2] (shell=False, capture=True)
2022-01-18 13:22:44,939 - util.py[DEBUG]: Running command ['blkid', '-tLABEL=CDROM', '-odevice'] with allowed return codes [0, 2] (shell=False, capture=True)
2022-01-18 13:22:44,942 - util.py[DEBUG]: Running command ['blkid', '-tTYPE=iso9660', '-odevice'] with allowed return codes [0, 2] (shell=False, capture=True)
2022-01-18 13:22:44,945 - handlers.py[DEBUG]: finish: init-local/search-OpenNebula: SUCCESS: no local data found from DataSourceOpenNebula
2022-01-18 13:22:44,945 - handlers.py[DEBUG]: start: init-local/search-DigitalOcean: searching for local data from DataSourceDigitalOcean
2022-01-18 13:22:44,945 - __init__.py[DEBUG]: Seeing if we can get any data from <class 'cloudinit.sources.DataSourceDigitalOcean.DataSourceDigitalOcean'>
2022-01-18 13:22:44,945 - util.py[DEBUG]: querying dmi data /sys/class/dmi/id/sys_vendor
2022-01-18 13:22:44,946 - util.py[DEBUG]: Reading from /sys/class/dmi/id/sys_vendor (quiet=False)
2022-01-18 13:22:44,946 - util.py[DEBUG]: Read 11 bytes from /sys/class/dmi/id/sys_vendor
2022-01-18 13:22:44,946 - util.py[DEBUG]: dmi data /sys/class/dmi/id/sys_vendor returned Amazon EC2
2022-01-18 13:22:44,946 - handlers.py[DEBUG]: finish: init-local/search-DigitalOcean: SUCCESS: no local data found from DataSourceDigitalOcean
2022-01-18 13:22:44,946 - handlers.py[DEBUG]: start: init-local/search-OVF: searching for local data from DataSourceOVF
2022-01-18 13:22:44,946 - __init__.py[DEBUG]: Seeing if we can get any data from <class 'cloudinit.sources.DataSourceOVF.DataSourceOVF'>
2022-01-18 13:22:44,946 - util.py[DEBUG]: querying dmi data /sys/class/dmi/id/product_name
2022-01-18 13:22:44,946 - util.py[DEBUG]: Reading from /sys/class/dmi/id/product_name (quiet=False)
2022-01-18 13:22:44,947 - util.py[DEBUG]: Read 9 bytes from /sys/class/dmi/id/product_name
2022-01-18 13:22:44,947 - util.py[DEBUG]: dmi data /sys/class/dmi/id/product_name returned t3.small
2022-01-18 13:22:44,947 - util.py[DEBUG]: Reading from /proc/mounts (quiet=False)
2022-01-18 13:22:44,947 - util.py[DEBUG]: Read 2226 bytes from /proc/mounts
2022-01-18 13:22:44,948 - util.py[DEBUG]: Fetched {'configfs': {'mountpoint': '/sys/kernel/config', 'opts': 'rw,relatime', 'fstype': 'configfs'}, 'devpts': {'mountpoint': '/dev/pts', 'opts': 'rw,seclabel,nosuid,noexec,relatime,gid=5,mode=620,ptmxmode=000', 'fstype': 'devpts'}, 'debugfs': {'mountpoint': '/sys/kernel/debug', 'opts': 'rw,relatime', 'fstype': 'debugfs'}, 'securityfs': {'mountpoint': '/sys/kernel/security', 'opts': 'rw,nosuid,nodev,noexec,relatime', 'fstype': 'securityfs'}, 'sysfs': {'mountpoint': '/sys', 'opts': 'rw,seclabel,nosuid,nodev,noexec,relatime', 'fstype': 'sysfs'}, 'mqueue': {'mountpoint': '/dev/mqueue', 'opts': 'rw,seclabel,relatime', 'fstype': 'mqueue'}, 'pstore': {'mountpoint': '/sys/fs/pstore', 'opts': 'rw,nosuid,nodev,noexec,relatime', 'fstype': 'pstore'}, '/dev/nvme0n1p1': {'mountpoint': '/', 'opts': 'rw,seclabel,relatime,attr2,inode64,noquota', 'fstype': 'xfs'}, 'hugetlbfs': {'mountpoint': '/dev/hugepages', 'opts': 'rw,seclabel,relatime', 'fstype': 'hugetlbfs'}, 'rpc_pipefs': {'mountpoint': '/var/lib/nfs/rpc_pipefs', 'opts': 'rw,relatime', 'fstype': 'rpc_pipefs'}, 'systemd-1': {'mountpoint': '/proc/sys/fs/binfmt_misc', 'opts': 'rw,relatime,fd=21,pgrp=1,timeout=0,minproto=5,maxproto=5,direct,pipe_ino=10720', 'fstype': 'autofs'}, 'cgroup': {'mountpoint': '/sys/fs/cgroup/pids', 'opts': 'rw,seclabel,nosuid,nodev,noexec,relatime,pids', 'fstype': 'cgroup'}, 'tmpfs': {'mountpoint': '/sys/fs/cgroup', 'opts': 'ro,seclabel,nosuid,nodev,noexec,mode=755', 'fstype': 'tmpfs'}, 'proc': {'mountpoint': '/proc', 'opts': 'rw,nosuid,nodev,noexec,relatime', 'fstype': 'proc'}, 'devtmpfs': {'mountpoint': '/dev', 'opts': 'rw,seclabel,nosuid,size=899284k,nr_inodes=224821,mode=755', 'fstype': 'devtmpfs'}, 'selinuxfs': {'mountpoint': '/sys/fs/selinux', 'opts': 'rw,relatime', 'fstype': 'selinuxfs'}, 'rootfs': {'mountpoint': '/', 'opts': 'rw', 'fstype': 'rootfs'}} mounts from proc
2022-01-18 13:22:44,948 - handlers.py[DEBUG]: finish: init-local/search-OVF: SUCCESS: no local data found from DataSourceOVF
2022-01-18 13:22:44,948 - handlers.py[DEBUG]: start: init-local/search-CloudSigma: searching for local data from DataSourceCloudSigma
2022-01-18 13:22:44,948 - __init__.py[DEBUG]: Seeing if we can get any data from <class 'cloudinit.sources.DataSourceCloudSigma.DataSourceCloudSigma'>
2022-01-18 13:22:44,948 - DataSourceCloudSigma.py[DEBUG]: determining hypervisor product name via dmi data
2022-01-18 13:22:44,948 - util.py[DEBUG]: querying dmi data /sys/class/dmi/id/product_name
2022-01-18 13:22:44,948 - util.py[DEBUG]: Reading from /sys/class/dmi/id/product_name (quiet=False)
2022-01-18 13:22:44,948 - util.py[DEBUG]: Read 9 bytes from /sys/class/dmi/id/product_name
2022-01-18 13:22:44,948 - util.py[DEBUG]: dmi data /sys/class/dmi/id/product_name returned t3.small
2022-01-18 13:22:44,948 - DataSourceCloudSigma.py[DEBUG]: detected hypervisor as t3.small
2022-01-18 13:22:44,949 - handlers.py[DEBUG]: finish: init-local/search-CloudSigma: SUCCESS: no local data found from DataSourceCloudSigma
2022-01-18 13:22:44,949 - handlers.py[DEBUG]: start: init-local/search-SmartOS: searching for local data from DataSourceSmartOS
2022-01-18 13:22:44,949 - __init__.py[DEBUG]: Seeing if we can get any data from <class 'cloudinit.sources.DataSourceSmartOS.DataSourceSmartOS'>
2022-01-18 13:22:44,949 - util.py[DEBUG]: querying dmi data /sys/class/dmi/id/product_name
2022-01-18 13:22:44,949 - util.py[DEBUG]: Reading from /sys/class/dmi/id/product_name (quiet=False)
2022-01-18 13:22:44,949 - util.py[DEBUG]: Read 9 bytes from /sys/class/dmi/id/product_name
2022-01-18 13:22:44,949 - util.py[DEBUG]: dmi data /sys/class/dmi/id/product_name returned t3.small
2022-01-18 13:22:44,949 - DataSourceSmartOS.py[DEBUG]: Not running on smartos
2022-01-18 13:22:44,949 - handlers.py[DEBUG]: finish: init-local/search-SmartOS: SUCCESS: no local data found from DataSourceSmartOS
2022-01-18 13:22:44,949 - main.py[DEBUG]: No local datasource found
2022-01-18 13:22:44,950 - util.py[DEBUG]: Reading from /sys/class/net/ens5/carrier (quiet=False)
2022-01-18 13:22:44,950 - util.py[DEBUG]: Reading from /sys/class/net/ens5/dormant (quiet=False)
2022-01-18 13:22:44,950 - util.py[DEBUG]: Reading from /sys/class/net/ens5/operstate (quiet=False)
2022-01-18 13:22:44,950 - util.py[DEBUG]: Read 5 bytes from /sys/class/net/ens5/operstate
2022-01-18 13:22:44,950 - util.py[DEBUG]: Reading from /sys/class/net/ens5/address (quiet=False)
2022-01-18 13:22:44,950 - util.py[DEBUG]: Read 18 bytes from /sys/class/net/ens5/address
2022-01-18 13:22:44,950 - stages.py[DEBUG]: applying net config names for {'version': 1, 'config': [{'subnets': [{'type': 'dhcp'}], 'type': 'physical', 'name': 'ens5', 'mac_address': '0e:6b:d4:80:93:6f'}]}
2022-01-18 13:22:44,950 - util.py[DEBUG]: Reading from /sys/class/net/ens5/addr_assign_type (quiet=False)
2022-01-18 13:22:44,950 - util.py[DEBUG]: Read 2 bytes from /sys/class/net/ens5/addr_assign_type
2022-01-18 13:22:44,950 - util.py[DEBUG]: Reading from /sys/class/net/ens5/address (quiet=False)
2022-01-18 13:22:44,950 - util.py[DEBUG]: Read 18 bytes from /sys/class/net/ens5/address
2022-01-18 13:22:44,950 - util.py[DEBUG]: Reading from /sys/class/net/lo/addr_assign_type (quiet=False)
2022-01-18 13:22:44,951 - util.py[DEBUG]: Read 2 bytes from /sys/class/net/lo/addr_assign_type
2022-01-18 13:22:44,951 - util.py[DEBUG]: Reading from /sys/class/net/lo/address (quiet=False)
2022-01-18 13:22:44,951 - util.py[DEBUG]: Read 18 bytes from /sys/class/net/lo/address
2022-01-18 13:22:44,951 - util.py[DEBUG]: Reading from /sys/class/net/lo/operstate (quiet=False)
2022-01-18 13:22:44,951 - util.py[DEBUG]: Read 8 bytes from /sys/class/net/lo/operstate
2022-01-18 13:22:44,951 - util.py[DEBUG]: Reading from /sys/class/net/ens5/operstate (quiet=False)
2022-01-18 13:22:44,951 - util.py[DEBUG]: Read 5 bytes from /sys/class/net/ens5/operstate
2022-01-18 13:22:44,951 - util.py[DEBUG]: Running command ['ip', '-6', 'addr', 'show', 'permanent', 'scope', 'global'] with allowed return codes [0] (shell=False, capture=True)
2022-01-18 13:22:44,958 - util.py[DEBUG]: Running command ['ip', '-4', 'addr', 'show'] with allowed return codes [0] (shell=False, capture=True)
2022-01-18 13:22:44,961 - __init__.py[DEBUG]: no work necessary for renaming of [['0e:6b:d4:80:93:6f', 'ens5']]
2022-01-18 13:22:44,962 - stages.py[INFO]: Applying network configuration from fallback bringup=False: {'version': 1, 'config': [{'subnets': [{'type': 'dhcp'}], 'type': 'physical', 'name': 'ens5', 'mac_address': '0e:6b:d4:80:93:6f'}]}
2022-01-18 13:22:44,964 - util.py[DEBUG]: Writing to /etc/sysconfig/network-scripts/ifcfg-ens5 - wb: [420] 159 bytes
2022-01-18 13:22:44,965 - util.py[DEBUG]: Restoring selinux mode for /etc/sysconfig/network-scripts/ifcfg-ens5 (recursive=False)
2022-01-18 13:22:44,965 - util.py[DEBUG]: Restoring selinux mode for /etc/sysconfig/network-scripts/ifcfg-ens5 (recursive=False)
2022-01-18 13:22:44,965 - util.py[DEBUG]: Reading from /etc/resolv.conf (quiet=False)
2022-01-18 13:22:44,965 - util.py[DEBUG]: Read 50 bytes from /etc/resolv.conf
2022-01-18 13:22:44,965 - util.py[DEBUG]: Writing to /etc/resolv.conf - wb: [420] 121 bytes
2022-01-18 13:22:44,966 - util.py[DEBUG]: Restoring selinux mode for /etc/resolv.conf (recursive=False)
2022-01-18 13:22:44,966 - util.py[DEBUG]: Restoring selinux mode for /etc/resolv.conf (recursive=False)
2022-01-18 13:22:44,966 - util.py[DEBUG]: Writing to /etc/udev/rules.d/70-persistent-net.rules - wb: [420] 96 bytes
2022-01-18 13:22:44,967 - util.py[DEBUG]: Restoring selinux mode for /etc/udev/rules.d/70-persistent-net.rules (recursive=False)
2022-01-18 13:22:44,967 - util.py[DEBUG]: Restoring selinux mode for /etc/udev/rules.d/70-persistent-net.rules (recursive=False)
2022-01-18 13:22:44,967 - main.py[DEBUG]: [local] Exiting without datasource in local mode
2022-01-18 13:22:44,968 - util.py[DEBUG]: Reading from /proc/uptime (quiet=False)
2022-01-18 13:22:44,968 - util.py[DEBUG]: Read 10 bytes from /proc/uptime
2022-01-18 13:22:44,968 - util.py[DEBUG]: cloud-init mode 'init' took 0.241 seconds (0.24)
2022-01-18 13:22:44,968 - handlers.py[DEBUG]: finish: init-local: SUCCESS: searching for local datasources
2022-01-18 13:22:48,300 - util.py[DEBUG]: Cloud-init v. 0.7.9 running 'init' at Tue, 18 Jan 2022 13:22:48 +0000. Up 10.56 seconds.
2022-01-18 13:22:48,301 - util.py[DEBUG]: Restoring selinux mode for /var/lib/cloud (recursive=False)
2022-01-18 13:22:48,303 - util.py[DEBUG]: Restoring selinux mode for /var/lib/cloud/scripts (recursive=False)
2022-01-18 13:22:48,313 - util.py[DEBUG]: Restoring selinux mode for /var/lib/cloud/scripts/per-instance (recursive=False)
2022-01-18 13:22:48,314 - util.py[DEBUG]: Restoring selinux mode for /var/lib/cloud/scripts/per-once (recursive=False)
2022-01-18 13:22:48,315 - util.py[DEBUG]: Restoring selinux mode for /var/lib/cloud/scripts/per-boot (recursive=False)
2022-01-18 13:22:48,315 - util.py[DEBUG]: Restoring selinux mode for /var/lib/cloud/scripts/vendor (recursive=False)
2022-01-18 13:22:48,316 - util.py[DEBUG]: Restoring selinux mode for /var/lib/cloud/seed (recursive=False)
2022-01-18 13:22:48,316 - util.py[DEBUG]: Restoring selinux mode for /var/lib/cloud/instances (recursive=False)
2022-01-18 13:22:48,317 - util.py[DEBUG]: Restoring selinux mode for /var/lib/cloud/handlers (recursive=False)
2022-01-18 13:22:48,317 - util.py[DEBUG]: Restoring selinux mode for /var/lib/cloud/sem (recursive=False)
2022-01-18 13:22:48,318 - util.py[DEBUG]: Restoring selinux mode for /var/lib/cloud/data (recursive=False)
2022-01-18 13:22:48,319 - util.py[DEBUG]: Writing to /var/log/cloud-init.log - ab: [384] 0 bytes
2022-01-18 13:22:48,319 - util.py[DEBUG]: Restoring selinux mode for /var/log/cloud-init.log (recursive=False)
2022-01-18 13:22:48,320 - util.py[DEBUG]: Restoring selinux mode for /var/log/cloud-init.log (recursive=False)
2022-01-18 13:22:48,321 - util.py[DEBUG]: Running command ['ifconfig', '-a'] with allowed return codes [0] (shell=False, capture=True)
2022-01-18 13:22:48,332 - util.py[DEBUG]: Running command ['netstat', '-rn'] with allowed return codes [0] (shell=False, capture=True)
2022-01-18 13:22:48,339 - util.py[DEBUG]: Running command ['netstat', '-A', 'inet6', '-n'] with allowed return codes [0] (shell=False, capture=True)
2022-01-18 13:22:48,346 - main.py[DEBUG]: Checking to see if files that we need already exist from a previous run that would allow us to stop early.
2022-01-18 13:22:48,347 - main.py[DEBUG]: Execution continuing, no previous run detected that would allow us to stop early.
2022-01-18 13:22:48,352 - handlers.py[DEBUG]: start: init-network/check-cache: attempting to read from cache [trust]
2022-01-18 13:22:48,352 - util.py[DEBUG]: Reading from /var/lib/cloud/instance/obj.pkl (quiet=False)
2022-01-18 13:22:48,352 - stages.py[DEBUG]: no cache found
2022-01-18 13:22:48,352 - handlers.py[DEBUG]: finish: init-network/check-cache: SUCCESS: no cache found
2022-01-18 13:22:48,357 - util.py[DEBUG]: Attempting to remove /var/lib/cloud/instance
2022-01-18 13:22:48,401 - stages.py[DEBUG]: Using distro class <class 'cloudinit.distros.rhel.Distro'>
2022-01-18 13:22:48,402 - __init__.py[DEBUG]: Looking for for data source in: ['NoCloud', 'ConfigDrive', 'OpenNebula', 'DigitalOcean', 'Azure', 'AltCloud', 'OVF', 'MAAS', 'GCE', 'OpenStack', 'AliYun', 'Ec2', 'CloudSigma', 'CloudStack', 'SmartOS', 'Bigstep', 'None'], via packages ['', u'cloudinit.sources'] that matches dependencies ['FILESYSTEM', 'NETWORK']
2022-01-18 13:22:48,454 - __init__.py[DEBUG]: Searching for network data source in: [u'DataSourceNoCloudNet', u'DataSourceAzureNet', u'DataSourceAltCloud', u'DataSourceOVFNet', u'DataSourceMAAS', u'DataSourceGCE', u'DataSourceOpenStack', u'DataSourceAliYun', u'DataSourceEc2', u'DataSourceCloudStack', u'DataSourceBigstep', u'DataSourceNone']
2022-01-18 13:22:48,455 - handlers.py[DEBUG]: start: init-network/search-NoCloudNet: searching for network data from DataSourceNoCloudNet
2022-01-18 13:22:48,455 - __init__.py[DEBUG]: Seeing if we can get any data from <class 'cloudinit.sources.DataSourceNoCloud.DataSourceNoCloudNet'>
2022-01-18 13:22:48,455 - util.py[DEBUG]: Reading from /var/lib/cloud/seed/nocloud/user-data (quiet=False)
2022-01-18 13:22:48,455 - util.py[DEBUG]: Reading from /var/lib/cloud/seed/nocloud/meta-data (quiet=False)
2022-01-18 13:22:48,455 - util.py[DEBUG]: Reading from /var/lib/cloud/seed/nocloud/vendor-data (quiet=False)
2022-01-18 13:22:48,455 - util.py[DEBUG]: Reading from /var/lib/cloud/seed/nocloud/network-config (quiet=False)
2022-01-18 13:22:48,455 - util.py[DEBUG]: Reading from /var/lib/cloud/seed/nocloud-net/user-data (quiet=False)
2022-01-18 13:22:48,456 - util.py[DEBUG]: Reading from /var/lib/cloud/seed/nocloud-net/meta-data (quiet=False)
2022-01-18 13:22:48,456 - util.py[DEBUG]: Reading from /var/lib/cloud/seed/nocloud-net/vendor-data (quiet=False)
2022-01-18 13:22:48,456 - util.py[DEBUG]: Reading from /var/lib/cloud/seed/nocloud-net/network-config (quiet=False)
2022-01-18 13:22:48,456 - util.py[DEBUG]: Running command ['blkid', '-odevice', '/dev/sr0'] with allowed return codes [0, 2] (shell=False, capture=True)
2022-01-18 13:22:48,466 - util.py[DEBUG]: Running command ['blkid', '-odevice', '/dev/sr1'] with allowed return codes [0, 2] (shell=False, capture=True)
2022-01-18 13:22:48,474 - util.py[DEBUG]: Running command ['blkid', '-tTYPE=vfat', '-odevice'] with allowed return codes [0, 2] (shell=False, capture=True)
2022-01-18 13:22:48,480 - util.py[DEBUG]: Running command ['blkid', '-tTYPE=iso9660', '-odevice'] with allowed return codes [0, 2] (shell=False, capture=True)
2022-01-18 13:22:48,485 - util.py[DEBUG]: Running command ['blkid', '-tLABEL=cidata', '-odevice'] with allowed return codes [0, 2] (shell=False, capture=True)
2022-01-18 13:22:48,489 - handlers.py[DEBUG]: finish: init-network/search-NoCloudNet: SUCCESS: no network data found from DataSourceNoCloudNet
2022-01-18 13:22:48,489 - handlers.py[DEBUG]: start: init-network/search-AzureNet: searching for network data from DataSourceAzureNet
2022-01-18 13:22:48,490 - __init__.py[DEBUG]: Seeing if we can get any data from <class 'cloudinit.sources.DataSourceAzure.DataSourceAzureNet'>
2022-01-18 13:22:48,490 - util.py[DEBUG]: Running command ['blkid', '-tTYPE=iso9660', '-odevice'] with allowed return codes [0, 2] (shell=False, capture=True)
2022-01-18 13:22:48,494 - util.py[DEBUG]: Running command ['blkid', '-tTYPE=udf', '-odevice'] with allowed return codes [0, 2] (shell=False, capture=True)
2022-01-18 13:22:48,499 - handlers.py[DEBUG]: finish: init-network/search-AzureNet: SUCCESS: no network data found from DataSourceAzureNet
2022-01-18 13:22:48,499 - handlers.py[DEBUG]: start: init-network/search-AltCloud: searching for network data from DataSourceAltCloud
2022-01-18 13:22:48,499 - __init__.py[DEBUG]: Seeing if we can get any data from <class 'cloudinit.sources.DataSourceAltCloud.DataSourceAltCloud'>
2022-01-18 13:22:48,500 - DataSourceAltCloud.py[DEBUG]: Invoked get_data()
2022-01-18 13:22:48,500 - util.py[DEBUG]: querying dmi data /sys/class/dmi/id/product_name
2022-01-18 13:22:48,500 - util.py[DEBUG]: Reading from /sys/class/dmi/id/product_name (quiet=False)
2022-01-18 13:22:48,500 - util.py[DEBUG]: Read 9 bytes from /sys/class/dmi/id/product_name
2022-01-18 13:22:48,500 - util.py[DEBUG]: dmi data /sys/class/dmi/id/product_name returned t3.small
2022-01-18 13:22:48,500 - DataSourceAltCloud.py[DEBUG]: cloud_type: UNKNOWN
2022-01-18 13:22:48,501 - handlers.py[DEBUG]: finish: init-network/search-AltCloud: SUCCESS: no network data found from DataSourceAltCloud
2022-01-18 13:22:48,501 - handlers.py[DEBUG]: start: init-network/search-OVFNet: searching for network data from DataSourceOVFNet
2022-01-18 13:22:48,501 - __init__.py[DEBUG]: Seeing if we can get any data from <class 'cloudinit.sources.DataSourceOVF.DataSourceOVFNet'>
2022-01-18 13:22:48,501 - util.py[DEBUG]: querying dmi data /sys/class/dmi/id/product_name
2022-01-18 13:22:48,501 - util.py[DEBUG]: Reading from /sys/class/dmi/id/product_name (quiet=False)
2022-01-18 13:22:48,501 - util.py[DEBUG]: Read 9 bytes from /sys/class/dmi/id/product_name
2022-01-18 13:22:48,501 - util.py[DEBUG]: dmi data /sys/class/dmi/id/product_name returned t3.small
2022-01-18 13:22:48,502 - util.py[DEBUG]: Reading from /proc/mounts (quiet=False)
2022-01-18 13:22:48,502 - util.py[DEBUG]: Read 2226 bytes from /proc/mounts
2022-01-18 13:22:48,502 - util.py[DEBUG]: Fetched {'configfs': {'mountpoint': '/sys/kernel/config', 'opts': 'rw,relatime', 'fstype': 'configfs'}, 'devpts': {'mountpoint': '/dev/pts', 'opts': 'rw,seclabel,nosuid,noexec,relatime,gid=5,mode=620,ptmxmode=000', 'fstype': 'devpts'}, 'debugfs': {'mountpoint': '/sys/kernel/debug', 'opts': 'rw,relatime', 'fstype': 'debugfs'}, 'securityfs': {'mountpoint': '/sys/kernel/security', 'opts': 'rw,nosuid,nodev,noexec,relatime', 'fstype': 'securityfs'}, 'sysfs': {'mountpoint': '/sys', 'opts': 'rw,seclabel,nosuid,nodev,noexec,relatime', 'fstype': 'sysfs'}, 'mqueue': {'mountpoint': '/dev/mqueue', 'opts': 'rw,seclabel,relatime', 'fstype': 'mqueue'}, 'pstore': {'mountpoint': '/sys/fs/pstore', 'opts': 'rw,nosuid,nodev,noexec,relatime', 'fstype': 'pstore'}, '/dev/nvme0n1p1': {'mountpoint': '/', 'opts': 'rw,seclabel,relatime,attr2,inode64,noquota', 'fstype': 'xfs'}, 'hugetlbfs': {'mountpoint': '/dev/hugepages', 'opts': 'rw,seclabel,relatime', 'fstype': 'hugetlbfs'}, 'rpc_pipefs': {'mountpoint': '/var/lib/nfs/rpc_pipefs', 'opts': 'rw,relatime', 'fstype': 'rpc_pipefs'}, 'systemd-1': {'mountpoint': '/proc/sys/fs/binfmt_misc', 'opts': 'rw,relatime,fd=21,pgrp=1,timeout=0,minproto=5,maxproto=5,direct,pipe_ino=10720', 'fstype': 'autofs'}, 'cgroup': {'mountpoint': '/sys/fs/cgroup/pids', 'opts': 'rw,seclabel,nosuid,nodev,noexec,relatime,pids', 'fstype': 'cgroup'}, 'tmpfs': {'mountpoint': '/sys/fs/cgroup', 'opts': 'ro,seclabel,nosuid,nodev,noexec,mode=755', 'fstype': 'tmpfs'}, 'proc': {'mountpoint': '/proc', 'opts': 'rw,nosuid,nodev,noexec,relatime', 'fstype': 'proc'}, 'devtmpfs': {'mountpoint': '/dev', 'opts': 'rw,seclabel,nosuid,size=899284k,nr_inodes=224821,mode=755', 'fstype': 'devtmpfs'}, 'selinuxfs': {'mountpoint': '/sys/fs/selinux', 'opts': 'rw,relatime', 'fstype': 'selinuxfs'}, 'rootfs': {'mountpoint': '/', 'opts': 'rw', 'fstype': 'rootfs'}} mounts from proc
2022-01-18 13:22:48,503 - handlers.py[DEBUG]: finish: init-network/search-OVFNet: SUCCESS: no network data found from DataSourceOVFNet
2022-01-18 13:22:48,503 - handlers.py[DEBUG]: start: init-network/search-MAAS: searching for network data from DataSourceMAAS
2022-01-18 13:22:48,503 - __init__.py[DEBUG]: Seeing if we can get any data from <class 'cloudinit.sources.DataSourceMAAS.DataSourceMAAS'>
2022-01-18 13:22:48,503 - handlers.py[DEBUG]: finish: init-network/search-MAAS: SUCCESS: no network data found from DataSourceMAAS
2022-01-18 13:22:48,503 - handlers.py[DEBUG]: start: init-network/search-GCE: searching for network data from DataSourceGCE
2022-01-18 13:22:48,504 - __init__.py[DEBUG]: Seeing if we can get any data from <class 'cloudinit.sources.DataSourceGCE.DataSourceGCE'>
2022-01-18 13:22:48,546 - DataSourceGCE.py[DEBUG]: http://metadata.google.internal/computeMetadata/v1/ is not resolvable
2022-01-18 13:22:48,546 - handlers.py[DEBUG]: finish: init-network/search-GCE: SUCCESS: no network data found from DataSourceGCE
2022-01-18 13:22:48,546 - handlers.py[DEBUG]: start: init-network/search-OpenStack: searching for network data from DataSourceOpenStack
2022-01-18 13:22:48,546 - __init__.py[DEBUG]: Seeing if we can get any data from <class 'cloudinit.sources.DataSourceOpenStack.DataSourceOpenStack'>
2022-01-18 13:22:48,547 - url_helper.py[DEBUG]: [0/1] open 'http://169.254.169.254/openstack' with {'url': 'http://169.254.169.254/openstack', 'headers': {'User-Agent': 'Cloud-Init/0.7.9'}, 'allow_redirects': True, 'method': 'GET', 'timeout': 10.0} configuration
2022-01-18 13:22:48,561 - url_helper.py[DEBUG]: Read from http://169.254.169.254/openstack (404, 339b) after 1 attempts
2022-01-18 13:22:48,561 - url_helper.py[DEBUG]: Calling 'http://169.254.169.254/openstack' failed [0/-1s]: bad status code [404]
2022-01-18 13:22:48,561 - DataSourceOpenStack.py[DEBUG]: Giving up on OpenStack md from ['http://169.254.169.254/openstack'] after 0 seconds
2022-01-18 13:22:48,561 - handlers.py[DEBUG]: finish: init-network/search-OpenStack: SUCCESS: no network data found from DataSourceOpenStack
2022-01-18 13:22:48,561 - handlers.py[DEBUG]: start: init-network/search-AliYun: searching for network data from DataSourceAliYun
2022-01-18 13:22:48,562 - __init__.py[DEBUG]: Seeing if we can get any data from <class 'cloudinit.sources.DataSourceAliYun.DataSourceAliYun'>
2022-01-18 13:22:48,562 - util.py[DEBUG]: Reading from /var/lib/cloud/seed/AliYun/meta-data (quiet=False)
2022-01-18 13:22:48,562 - util.py[DEBUG]: querying dmi data /sys/class/dmi/id/product_name
2022-01-18 13:22:48,562 - util.py[DEBUG]: Reading from /sys/class/dmi/id/product_name (quiet=False)
2022-01-18 13:22:48,562 - util.py[DEBUG]: Read 9 bytes from /sys/class/dmi/id/product_name
2022-01-18 13:22:48,562 - util.py[DEBUG]: dmi data /sys/class/dmi/id/product_name returned t3.small
2022-01-18 13:22:48,562 - DataSourceEc2.py[DEBUG]: strict_mode: warn, cloud_platform=No-EC2-Metadata
2022-01-18 13:22:48,562 - handlers.py[DEBUG]: finish: init-network/search-AliYun: SUCCESS: no network data found from DataSourceAliYun
2022-01-18 13:22:48,562 - handlers.py[DEBUG]: start: init-network/search-Ec2: searching for network data from DataSourceEc2
2022-01-18 13:22:48,563 - __init__.py[DEBUG]: Seeing if we can get any data from <class 'cloudinit.sources.DataSourceEc2.DataSourceEc2'>
2022-01-18 13:22:48,563 - util.py[DEBUG]: Reading from /var/lib/cloud/seed/ec2/meta-data (quiet=False)
2022-01-18 13:22:48,563 - util.py[DEBUG]: Reading from /sys/hypervisor/uuid (quiet=False)
2022-01-18 13:22:48,563 - util.py[DEBUG]: querying dmi data /sys/class/dmi/id/product_uuid
2022-01-18 13:22:48,563 - util.py[DEBUG]: Reading from /sys/class/dmi/id/product_uuid (quiet=False)
2022-01-18 13:22:48,563 - util.py[DEBUG]: Read 37 bytes from /sys/class/dmi/id/product_uuid
2022-01-18 13:22:48,563 - util.py[DEBUG]: dmi data /sys/class/dmi/id/product_uuid returned EC2EBD70-5C30-97CF-F2DB-CCEDC1E73777
2022-01-18 13:22:48,563 - util.py[DEBUG]: querying dmi data /sys/class/dmi/id/product_serial
2022-01-18 13:22:48,563 - util.py[DEBUG]: Reading from /sys/class/dmi/id/product_serial (quiet=False)
2022-01-18 13:22:48,563 - util.py[DEBUG]: Read 37 bytes from /sys/class/dmi/id/product_serial
2022-01-18 13:22:48,563 - util.py[DEBUG]: dmi data /sys/class/dmi/id/product_serial returned ec2ebd70-5c30-97cf-f2db-ccedc1e73777
2022-01-18 13:22:48,564 - DataSourceEc2.py[DEBUG]: strict_mode: warn, cloud_platform=AWS
2022-01-18 13:22:48,566 - DataSourceEc2.py[DEBUG]: Removed the following from metadata urls: ['http://instance-data.:8773']
2022-01-18 13:22:48,566 - url_helper.py[DEBUG]: [0/1] open 'http://169.254.169.254/2009-04-04/meta-data/instance-id' with {'url': 'http://169.254.169.254/2009-04-04/meta-data/instance-id', 'headers': {'User-Agent': 'Cloud-Init/0.7.9'}, 'allow_redirects': True, 'method': 'GET', 'timeout': 50.0} configuration
2022-01-18 13:22:48,568 - url_helper.py[DEBUG]: Read from http://169.254.169.254/2009-04-04/meta-data/instance-id (200, 19b) after 1 attempts
2022-01-18 13:22:48,568 - DataSourceEc2.py[DEBUG]: Using metadata source: 'http://169.254.169.254'
2022-01-18 13:22:48,568 - url_helper.py[DEBUG]: [0/6] open 'http://169.254.169.254/2009-04-04/user-data' with {'url': 'http://169.254.169.254/2009-04-04/user-data', 'headers': {'User-Agent': 'Cloud-Init/0.7.9'}, 'allow_redirects': True, 'method': 'GET', 'timeout': 5.0} configuration
2022-01-18 13:22:48,571 - url_helper.py[DEBUG]: Read from http://169.254.169.254/2009-04-04/user-data (200, 179b) after 1 attempts
2022-01-18 13:22:48,571 - url_helper.py[DEBUG]: [0/6] open 'http://169.254.169.254/2009-04-04/meta-data/' with {'url': 'http://169.254.169.254/2009-04-04/meta-data/', 'headers': {'User-Agent': 'Cloud-Init/0.7.9'}, 'allow_redirects': True, 'method': 'GET', 'timeout': 5.0} configuration
2022-01-18 13:22:48,573 - url_helper.py[DEBUG]: Read from http://169.254.169.254/2009-04-04/meta-data/ (200, 245b) after 1 attempts
2022-01-18 13:22:48,573 - url_helper.py[DEBUG]: [0/6] open 'http://169.254.169.254/2009-04-04/meta-data/block-device-mapping/' with {'url': 'http://169.254.169.254/2009-04-04/meta-data/block-device-mapping/', 'headers': {'User-Agent': 'Cloud-Init/0.7.9'}, 'allow_redirects': True, 'method': 'GET', 'timeout': 5.0} configuration
2022-01-18 13:22:48,575 - url_helper.py[DEBUG]: Read from http://169.254.169.254/2009-04-04/meta-data/block-device-mapping/ (200, 8b) after 1 attempts
2022-01-18 13:22:48,575 - url_helper.py[DEBUG]: [0/6] open 'http://169.254.169.254/2009-04-04/meta-data/block-device-mapping/ami' with {'url': 'http://169.254.169.254/2009-04-04/meta-data/block-device-mapping/ami', 'headers': {'User-Agent': 'Cloud-Init/0.7.9'}, 'allow_redirects': True, 'method': 'GET', 'timeout': 5.0} configuration
2022-01-18 13:22:48,578 - url_helper.py[DEBUG]: Read from http://169.254.169.254/2009-04-04/meta-data/block-device-mapping/ami (200, 4b) after 1 attempts
2022-01-18 13:22:48,578 - url_helper.py[DEBUG]: [0/6] open 'http://169.254.169.254/2009-04-04/meta-data/block-device-mapping/root' with {'url': 'http://169.254.169.254/2009-04-04/meta-data/block-device-mapping/root', 'headers': {'User-Agent': 'Cloud-Init/0.7.9'}, 'allow_redirects': True, 'method': 'GET', 'timeout': 5.0} configuration
2022-01-18 13:22:48,580 - url_helper.py[DEBUG]: Read from http://169.254.169.254/2009-04-04/meta-data/block-device-mapping/root (200, 9b) after 1 attempts
2022-01-18 13:22:48,580 - url_helper.py[DEBUG]: [0/6] open 'http://169.254.169.254/2009-04-04/meta-data/placement/' with {'url': 'http://169.254.169.254/2009-04-04/meta-data/placement/', 'headers': {'User-Agent': 'Cloud-Init/0.7.9'}, 'allow_redirects': True, 'method': 'GET', 'timeout': 5.0} configuration
2022-01-18 13:22:48,582 - url_helper.py[DEBUG]: Read from http://169.254.169.254/2009-04-04/meta-data/placement/ (200, 17b) after 1 attempts
2022-01-18 13:22:48,582 - url_helper.py[DEBUG]: [0/6] open 'http://169.254.169.254/2009-04-04/meta-data/placement/availability-zone' with {'url': 'http://169.254.169.254/2009-04-04/meta-data/placement/availability-zone', 'headers': {'User-Agent': 'Cloud-Init/0.7.9'}, 'allow_redirects': True, 'method': 'GET', 'timeout': 5.0} configuration
2022-01-18 13:22:48,584 - url_helper.py[DEBUG]: Read from http://169.254.169.254/2009-04-04/meta-data/placement/availability-zone (200, 10b) after 1 attempts
2022-01-18 13:22:48,584 - url_helper.py[DEBUG]: [0/6] open 'http://169.254.169.254/2009-04-04/meta-data/public-keys/' with {'url': 'http://169.254.169.254/2009-04-04/meta-data/public-keys/', 'headers': {'User-Agent': 'Cloud-Init/0.7.9'}, 'allow_redirects': True, 'method': 'GET', 'timeout': 5.0} configuration
2022-01-18 13:22:48,587 - url_helper.py[DEBUG]: Read from http://169.254.169.254/2009-04-04/meta-data/public-keys/ (200, 10b) after 1 attempts
2022-01-18 13:22:48,587 - url_helper.py[DEBUG]: [0/6] open 'http://169.254.169.254/2009-04-04/meta-data/public-keys/0/openssh-key' with {'url': 'http://169.254.169.254/2009-04-04/meta-data/public-keys/0/openssh-key', 'headers': {'User-Agent': 'Cloud-Init/0.7.9'}, 'allow_redirects': True, 'method': 'GET', 'timeout': 5.0} configuration
2022-01-18 13:22:48,589 - url_helper.py[DEBUG]: Read from http://169.254.169.254/2009-04-04/meta-data/public-keys/0/openssh-key (200, 390b) after 1 attempts
2022-01-18 13:22:48,589 - url_helper.py[DEBUG]: [0/6] open 'http://169.254.169.254/2009-04-04/meta-data/profile' with {'url': 'http://169.254.169.254/2009-04-04/meta-data/profile', 'headers': {'User-Agent': 'Cloud-Init/0.7.9'}, 'allow_redirects': True, 'method': 'GET', 'timeout': 5.0} configuration
2022-01-18 13:22:48,591 - url_helper.py[DEBUG]: Read from http://169.254.169.254/2009-04-04/meta-data/profile (200, 11b) after 1 attempts
2022-01-18 13:22:48,591 - url_helper.py[DEBUG]: [0/6] open 'http://169.254.169.254/2009-04-04/meta-data/local-ipv4' with {'url': 'http://169.254.169.254/2009-04-04/meta-data/local-ipv4', 'headers': {'User-Agent': 'Cloud-Init/0.7.9'}, 'allow_redirects': True, 'method': 'GET', 'timeout': 5.0} configuration
2022-01-18 13:22:48,593 - url_helper.py[DEBUG]: Read from http://169.254.169.254/2009-04-04/meta-data/local-ipv4 (200, 10b) after 1 attempts
2022-01-18 13:22:48,593 - url_helper.py[DEBUG]: [0/6] open 'http://169.254.169.254/2009-04-04/meta-data/reservation-id' with {'url': 'http://169.254.169.254/2009-04-04/meta-data/reservation-id', 'headers': {'User-Agent': 'Cloud-Init/0.7.9'}, 'allow_redirects': True, 'method': 'GET', 'timeout': 5.0} configuration
2022-01-18 13:22:48,596 - url_helper.py[DEBUG]: Read from http://169.254.169.254/2009-04-04/meta-data/reservation-id (200, 19b) after 1 attempts
2022-01-18 13:22:48,596 - url_helper.py[DEBUG]: [0/6] open 'http://169.254.169.254/2009-04-04/meta-data/local-hostname' with {'url': 'http://169.254.169.254/2009-04-04/meta-data/local-hostname', 'headers': {'User-Agent': 'Cloud-Init/0.7.9'}, 'allow_redirects': True, 'method': 'GET', 'timeout': 5.0} configuration
2022-01-18 13:22:48,598 - url_helper.py[DEBUG]: Read from http://169.254.169.254/2009-04-04/meta-data/local-hostname (200, 26b) after 1 attempts
2022-01-18 13:22:48,598 - url_helper.py[DEBUG]: [0/6] open 'http://169.254.169.254/2009-04-04/meta-data/security-groups' with {'url': 'http://169.254.169.254/2009-04-04/meta-data/security-groups', 'headers': {'User-Agent': 'Cloud-Init/0.7.9'}, 'allow_redirects': True, 'method': 'GET', 'timeout': 5.0} configuration
2022-01-18 13:22:48,600 - url_helper.py[DEBUG]: Read from http://169.254.169.254/2009-04-04/meta-data/security-groups (200, 24b) after 1 attempts
2022-01-18 13:22:48,600 - url_helper.py[DEBUG]: [0/6] open 'http://169.254.169.254/2009-04-04/meta-data/product-codes' with {'url': 'http://169.254.169.254/2009-04-04/meta-data/product-codes', 'headers': {'User-Agent': 'Cloud-Init/0.7.9'}, 'allow_redirects': True, 'method': 'GET', 'timeout': 5.0} configuration
2022-01-18 13:22:48,602 - url_helper.py[DEBUG]: Read from http://169.254.169.254/2009-04-04/meta-data/product-codes (200, 25b) after 1 attempts
2022-01-18 13:22:48,602 - url_helper.py[DEBUG]: [0/6] open 'http://169.254.169.254/2009-04-04/meta-data/ami-launch-index' with {'url': 'http://169.254.169.254/2009-04-04/meta-data/ami-launch-index', 'headers': {'User-Agent': 'Cloud-Init/0.7.9'}, 'allow_redirects': True, 'method': 'GET', 'timeout': 5.0} configuration
2022-01-18 13:22:48,604 - url_helper.py[DEBUG]: Read from http://169.254.169.254/2009-04-04/meta-data/ami-launch-index (200, 1b) after 1 attempts
2022-01-18 13:22:48,604 - url_helper.py[DEBUG]: [0/6] open 'http://169.254.169.254/2009-04-04/meta-data/public-hostname' with {'url': 'http://169.254.169.254/2009-04-04/meta-data/public-hostname', 'headers': {'User-Agent': 'Cloud-Init/0.7.9'}, 'allow_redirects': True, 'method': 'GET', 'timeout': 5.0} configuration
2022-01-18 13:22:48,606 - url_helper.py[DEBUG]: Read from http://169.254.169.254/2009-04-04/meta-data/public-hostname (200, 42b) after 1 attempts
2022-01-18 13:22:48,607 - url_helper.py[DEBUG]: [0/6] open 'http://169.254.169.254/2009-04-04/meta-data/hostname' with {'url': 'http://169.254.169.254/2009-04-04/meta-data/hostname', 'headers': {'User-Agent': 'Cloud-Init/0.7.9'}, 'allow_redirects': True, 'method': 'GET', 'timeout': 5.0} configuration
2022-01-18 13:22:48,609 - url_helper.py[DEBUG]: Read from http://169.254.169.254/2009-04-04/meta-data/hostname (200, 26b) after 1 attempts
2022-01-18 13:22:48,609 - url_helper.py[DEBUG]: [0/6] open 'http://169.254.169.254/2009-04-04/meta-data/ami-id' with {'url': 'http://169.254.169.254/2009-04-04/meta-data/ami-id', 'headers': {'User-Agent': 'Cloud-Init/0.7.9'}, 'allow_redirects': True, 'method': 'GET', 'timeout': 5.0} configuration
2022-01-18 13:22:48,611 - url_helper.py[DEBUG]: Read from http://169.254.169.254/2009-04-04/meta-data/ami-id (200, 12b) after 1 attempts
2022-01-18 13:22:48,611 - url_helper.py[DEBUG]: [0/6] open 'http://169.254.169.254/2009-04-04/meta-data/instance-action' with {'url': 'http://169.254.169.254/2009-04-04/meta-data/instance-action', 'headers': {'User-Agent': 'Cloud-Init/0.7.9'}, 'allow_redirects': True, 'method': 'GET', 'timeout': 5.0} configuration
2022-01-18 13:22:48,613 - url_helper.py[DEBUG]: Read from http://169.254.169.254/2009-04-04/meta-data/instance-action (200, 4b) after 1 attempts
2022-01-18 13:22:48,614 - url_helper.py[DEBUG]: [0/6] open 'http://169.254.169.254/2009-04-04/meta-data/public-ipv4' with {'url': 'http://169.254.169.254/2009-04-04/meta-data/public-ipv4', 'headers': {'User-Agent': 'Cloud-Init/0.7.9'}, 'allow_redirects': True, 'method': 'GET', 'timeout': 5.0} configuration
2022-01-18 13:22:48,616 - url_helper.py[DEBUG]: Read from http://169.254.169.254/2009-04-04/meta-data/public-ipv4 (200, 14b) after 1 attempts
2022-01-18 13:22:48,616 - url_helper.py[DEBUG]: [0/6] open 'http://169.254.169.254/2009-04-04/meta-data/ami-manifest-path' with {'url': 'http://169.254.169.254/2009-04-04/meta-data/ami-manifest-path', 'headers': {'User-Agent': 'Cloud-Init/0.7.9'}, 'allow_redirects': True, 'method': 'GET', 'timeout': 5.0} configuration
2022-01-18 13:22:48,618 - url_helper.py[DEBUG]: Read from http://169.254.169.254/2009-04-04/meta-data/ami-manifest-path (200, 9b) after 1 attempts
2022-01-18 13:22:48,618 - url_helper.py[DEBUG]: [0/6] open 'http://169.254.169.254/2009-04-04/meta-data/instance-type' with {'url': 'http://169.254.169.254/2009-04-04/meta-data/instance-type', 'headers': {'User-Agent': 'Cloud-Init/0.7.9'}, 'allow_redirects': True, 'method': 'GET', 'timeout': 5.0} configuration
2022-01-18 13:22:48,620 - url_helper.py[DEBUG]: Read from http://169.254.169.254/2009-04-04/meta-data/instance-type (200, 8b) after 1 attempts
2022-01-18 13:22:48,620 - url_helper.py[DEBUG]: [0/6] open 'http://169.254.169.254/2009-04-04/meta-data/instance-id' with {'url': 'http://169.254.169.254/2009-04-04/meta-data/instance-id', 'headers': {'User-Agent': 'Cloud-Init/0.7.9'}, 'allow_redirects': True, 'method': 'GET', 'timeout': 5.0} configuration
2022-01-18 13:22:48,622 - url_helper.py[DEBUG]: Read from http://169.254.169.254/2009-04-04/meta-data/instance-id (200, 19b) after 1 attempts
2022-01-18 13:22:48,622 - DataSourceEc2.py[DEBUG]: Crawl of metadata service took 0.054 seconds
2022-01-18 13:22:48,623 - handlers.py[DEBUG]: finish: init-network/search-Ec2: SUCCESS: found network data from DataSourceEc2
2022-01-18 13:22:48,623 - stages.py[INFO]: Loaded datasource DataSourceEc2 - DataSourceEc2
2022-01-18 13:22:48,623 - util.py[DEBUG]: Reading from /etc/cloud/cloud.cfg (quiet=False)
2022-01-18 13:22:48,623 - util.py[DEBUG]: Read 1146 bytes from /etc/cloud/cloud.cfg
2022-01-18 13:22:48,623 - util.py[DEBUG]: Attempting to load yaml from string of length 1146 with allowed root types (<type 'dict'>,)
2022-01-18 13:22:48,634 - util.py[DEBUG]: Reading from /etc/cloud/cloud.cfg.d/05_logging.cfg (quiet=False)
2022-01-18 13:22:48,635 - util.py[DEBUG]: Read 1821 bytes from /etc/cloud/cloud.cfg.d/05_logging.cfg
2022-01-18 13:22:48,635 - util.py[DEBUG]: Attempting to load yaml from string of length 1821 with allowed root types (<type 'dict'>,)
2022-01-18 13:22:48,640 - util.py[DEBUG]: Attempting to load yaml from string of length 0 with allowed root types (<type 'dict'>,)
2022-01-18 13:22:48,640 - util.py[DEBUG]: load_yaml given empty string, returning default
2022-01-18 13:22:48,640 - util.py[DEBUG]: Attempting to remove /var/lib/cloud/instance
2022-01-18 13:22:48,641 - util.py[DEBUG]: Creating symbolic link from '/var/lib/cloud/instance' => '/var/lib/cloud/instances/i-0c0853353402e1d0e'
2022-01-18 13:22:48,642 - util.py[DEBUG]: Restoring selinux mode for /var/lib/cloud/instances/i-0c0853353402e1d0e (recursive=True)
2022-01-18 13:22:48,643 - util.py[DEBUG]: Restoring selinux mode for /var/lib/cloud/instances/i-0c0853353402e1d0e/handlers (recursive=False)
2022-01-18 13:22:48,643 - util.py[DEBUG]: Restoring selinux mode for /var/lib/cloud/instances/i-0c0853353402e1d0e (recursive=True)
2022-01-18 13:22:48,644 - util.py[DEBUG]: Restoring selinux mode for /var/lib/cloud/instances/i-0c0853353402e1d0e/scripts (recursive=False)
2022-01-18 13:22:48,645 - util.py[DEBUG]: Restoring selinux mode for /var/lib/cloud/instances/i-0c0853353402e1d0e (recursive=True)
2022-01-18 13:22:48,646 - util.py[DEBUG]: Restoring selinux mode for /var/lib/cloud/instances/i-0c0853353402e1d0e/sem (recursive=False)
2022-01-18 13:22:48,647 - util.py[DEBUG]: Reading from /var/lib/cloud/instances/i-0c0853353402e1d0e/datasource (quiet=False)
2022-01-18 13:22:48,647 - util.py[DEBUG]: Writing to /var/lib/cloud/instances/i-0c0853353402e1d0e/datasource - wb: [420] 29 bytes
2022-01-18 13:22:48,647 - util.py[DEBUG]: Restoring selinux mode for /var/lib/cloud/instances/i-0c0853353402e1d0e/datasource (recursive=False)
2022-01-18 13:22:48,648 - util.py[DEBUG]: Restoring selinux mode for /var/lib/cloud/instances/i-0c0853353402e1d0e/datasource (recursive=False)
2022-01-18 13:22:48,648 - util.py[DEBUG]: Writing to /var/lib/cloud/data/previous-datasource - wb: [420] 29 bytes
2022-01-18 13:22:48,649 - util.py[DEBUG]: Restoring selinux mode for /var/lib/cloud/data/previous-datasource (recursive=False)
2022-01-18 13:22:48,650 - util.py[DEBUG]: Restoring selinux mode for /var/lib/cloud/data/previous-datasource (recursive=False)
2022-01-18 13:22:48,650 - util.py[DEBUG]: Reading from /var/lib/cloud/data/instance-id (quiet=False)
2022-01-18 13:22:48,650 - stages.py[DEBUG]: previous iid found to be NO_PREVIOUS_INSTANCE_ID
2022-01-18 13:22:48,650 - util.py[DEBUG]: Writing to /var/lib/cloud/data/instance-id - wb: [420] 20 bytes
2022-01-18 13:22:48,651 - util.py[DEBUG]: Restoring selinux mode for /var/lib/cloud/data/instance-id (recursive=False)
2022-01-18 13:22:48,651 - util.py[DEBUG]: Restoring selinux mode for /var/lib/cloud/data/instance-id (recursive=False)
2022-01-18 13:22:48,652 - util.py[DEBUG]: Writing to /run/cloud-init/.instance-id - wb: [420] 20 bytes
2022-01-18 13:22:48,653 - util.py[DEBUG]: Restoring selinux mode for /run/cloud-init/.instance-id (recursive=False)
2022-01-18 13:22:48,653 - util.py[DEBUG]: Restoring selinux mode for /run/cloud-init/.instance-id (recursive=False)
2022-01-18 13:22:48,654 - util.py[DEBUG]: Writing to /var/lib/cloud/data/previous-instance-id - wb: [420] 24 bytes
2022-01-18 13:22:48,654 - util.py[DEBUG]: Restoring selinux mode for /var/lib/cloud/data/previous-instance-id (recursive=False)
2022-01-18 13:22:48,655 - util.py[DEBUG]: Restoring selinux mode for /var/lib/cloud/data/previous-instance-id (recursive=False)
2022-01-18 13:22:48,656 - util.py[DEBUG]: Writing to /var/lib/cloud/instance/obj.pkl - wb: [256] 6524 bytes
2022-01-18 13:22:48,657 - util.py[DEBUG]: Restoring selinux mode for /var/lib/cloud/instances/i-0c0853353402e1d0e/obj.pkl (recursive=False)
2022-01-18 13:22:48,657 - util.py[DEBUG]: Restoring selinux mode for /var/lib/cloud/instances/i-0c0853353402e1d0e/obj.pkl (recursive=False)
2022-01-18 13:22:48,658 - main.py[DEBUG]: [net] init will now be targeting instance id: i-0c0853353402e1d0e. new=True
2022-01-18 13:22:48,658 - util.py[DEBUG]: Reading from /etc/cloud/cloud.cfg (quiet=False)
2022-01-18 13:22:48,658 - util.py[DEBUG]: Read 1146 bytes from /etc/cloud/cloud.cfg
2022-01-18 13:22:48,658 - util.py[DEBUG]: Attempting to load yaml from string of length 1146 with allowed root types (<type 'dict'>,)
2022-01-18 13:22:48,670 - util.py[DEBUG]: Reading from /etc/cloud/cloud.cfg.d/05_logging.cfg (quiet=False)
2022-01-18 13:22:48,670 - util.py[DEBUG]: Read 1821 bytes from /etc/cloud/cloud.cfg.d/05_logging.cfg
2022-01-18 13:22:48,670 - util.py[DEBUG]: Attempting to load yaml from string of length 1821 with allowed root types (<type 'dict'>,)
2022-01-18 13:22:48,675 - util.py[DEBUG]: Attempting to load yaml from string of length 0 with allowed root types (<type 'dict'>,)
2022-01-18 13:22:48,676 - util.py[DEBUG]: load_yaml given empty string, returning default
2022-01-18 13:22:48,677 - util.py[DEBUG]: Reading from /sys/class/net/ens5/carrier (quiet=False)
2022-01-18 13:22:48,677 - util.py[DEBUG]: Read 2 bytes from /sys/class/net/ens5/carrier
2022-01-18 13:22:48,677 - util.py[DEBUG]: Reading from /sys/class/net/ens5/address (quiet=False)
2022-01-18 13:22:48,677 - util.py[DEBUG]: Read 18 bytes from /sys/class/net/ens5/address
2022-01-18 13:22:48,677 - stages.py[DEBUG]: applying net config names for {'version': 1, 'config': [{'subnets': [{'type': 'dhcp'}], 'type': 'physical', 'name': 'ens5', 'mac_address': '0e:6b:d4:80:93:6f'}]}
2022-01-18 13:22:48,678 - stages.py[DEBUG]: Using distro class <class 'cloudinit.distros.rhel.Distro'>
2022-01-18 13:22:48,678 - util.py[DEBUG]: Reading from /sys/class/net/ens5/addr_assign_type (quiet=False)
2022-01-18 13:22:48,678 - util.py[DEBUG]: Read 2 bytes from /sys/class/net/ens5/addr_assign_type
2022-01-18 13:22:48,678 - util.py[DEBUG]: Reading from /sys/class/net/ens5/address (quiet=False)
2022-01-18 13:22:48,678 - util.py[DEBUG]: Read 18 bytes from /sys/class/net/ens5/address
2022-01-18 13:22:48,678 - util.py[DEBUG]: Reading from /sys/class/net/lo/addr_assign_type (quiet=False)
2022-01-18 13:22:48,678 - util.py[DEBUG]: Read 2 bytes from /sys/class/net/lo/addr_assign_type
2022-01-18 13:22:48,679 - util.py[DEBUG]: Reading from /sys/class/net/lo/address (quiet=False)
2022-01-18 13:22:48,679 - util.py[DEBUG]: Read 18 bytes from /sys/class/net/lo/address
2022-01-18 13:22:48,679 - util.py[DEBUG]: Reading from /sys/class/net/lo/operstate (quiet=False)
2022-01-18 13:22:48,679 - util.py[DEBUG]: Read 8 bytes from /sys/class/net/lo/operstate
2022-01-18 13:22:48,679 - util.py[DEBUG]: Reading from /sys/class/net/ens5/operstate (quiet=False)
2022-01-18 13:22:48,679 - util.py[DEBUG]: Read 3 bytes from /sys/class/net/ens5/operstate
2022-01-18 13:22:48,679 - util.py[DEBUG]: Running command ['ip', '-6', 'addr', 'show', 'permanent', 'scope', 'global'] with allowed return codes [0] (shell=False, capture=True)
2022-01-18 13:22:48,684 - util.py[DEBUG]: Running command ['ip', '-4', 'addr', 'show'] with allowed return codes [0] (shell=False, capture=True)
2022-01-18 13:22:48,690 - __init__.py[DEBUG]: no work necessary for renaming of [['0e:6b:d4:80:93:6f', 'ens5']]
2022-01-18 13:22:48,690 - stages.py[INFO]: Applying network configuration from fallback bringup=True: {'version': 1, 'config': [{'subnets': [{'type': 'dhcp'}], 'type': 'physical', 'name': 'ens5', 'mac_address': '0e:6b:d4:80:93:6f'}]}
2022-01-18 13:22:48,694 - util.py[DEBUG]: Writing to /etc/sysconfig/network-scripts/ifcfg-ens5 - wb: [420] 159 bytes
2022-01-18 13:22:48,694 - util.py[DEBUG]: Restoring selinux mode for /etc/sysconfig/network-scripts/ifcfg-ens5 (recursive=False)
2022-01-18 13:22:48,695 - util.py[DEBUG]: Restoring selinux mode for /etc/sysconfig/network-scripts/ifcfg-ens5 (recursive=False)
2022-01-18 13:22:48,695 - util.py[DEBUG]: Reading from /etc/resolv.conf (quiet=False)
2022-01-18 13:22:48,695 - util.py[DEBUG]: Read 81 bytes from /etc/resolv.conf
2022-01-18 13:22:48,695 - util.py[DEBUG]: Writing to /etc/resolv.conf - wb: [420] 152 bytes
2022-01-18 13:22:48,695 - util.py[DEBUG]: Restoring selinux mode for /etc/resolv.conf (recursive=False)
2022-01-18 13:22:48,696 - util.py[DEBUG]: Restoring selinux mode for /etc/resolv.conf (recursive=False)
2022-01-18 13:22:48,696 - util.py[DEBUG]: Writing to /etc/udev/rules.d/70-persistent-net.rules - wb: [420] 96 bytes
2022-01-18 13:22:48,697 - util.py[DEBUG]: Restoring selinux mode for /etc/udev/rules.d/70-persistent-net.rules (recursive=False)
2022-01-18 13:22:48,697 - util.py[DEBUG]: Restoring selinux mode for /etc/udev/rules.d/70-persistent-net.rules (recursive=False)
2022-01-18 13:22:48,698 - util.py[DEBUG]: Writing to /var/lib/cloud/instances/i-0c0853353402e1d0e/user-data.txt - wb: [384] 179 bytes
2022-01-18 13:22:48,698 - util.py[DEBUG]: Restoring selinux mode for /var/lib/cloud/instances/i-0c0853353402e1d0e/user-data.txt (recursive=False)
2022-01-18 13:22:48,699 - util.py[DEBUG]: Restoring selinux mode for /var/lib/cloud/instances/i-0c0853353402e1d0e/user-data.txt (recursive=False)
2022-01-18 13:22:48,700 - util.py[DEBUG]: Attempting to load yaml from string of length 179 with allowed root types (<type 'dict'>,)
2022-01-18 13:22:48,715 - util.py[DEBUG]: Writing to /var/lib/cloud/instances/i-0c0853353402e1d0e/user-data.txt.i - wb: [384] 520 bytes
2022-01-18 13:22:48,715 - util.py[DEBUG]: Restoring selinux mode for /var/lib/cloud/instances/i-0c0853353402e1d0e/user-data.txt.i (recursive=False)
2022-01-18 13:22:48,716 - util.py[DEBUG]: Restoring selinux mode for /var/lib/cloud/instances/i-0c0853353402e1d0e/user-data.txt.i (recursive=False)
2022-01-18 13:22:48,717 - util.py[DEBUG]: Writing to /var/lib/cloud/instances/i-0c0853353402e1d0e/vendor-data.txt - wb: [384] 0 bytes
2022-01-18 13:22:48,717 - util.py[DEBUG]: Restoring selinux mode for /var/lib/cloud/instances/i-0c0853353402e1d0e/vendor-data.txt (recursive=False)
2022-01-18 13:22:48,718 - util.py[DEBUG]: Restoring selinux mode for /var/lib/cloud/instances/i-0c0853353402e1d0e/vendor-data.txt (recursive=False)
2022-01-18 13:22:48,719 - util.py[DEBUG]: Writing to /var/lib/cloud/instances/i-0c0853353402e1d0e/vendor-data.txt.i - wb: [384] 344 bytes
2022-01-18 13:22:48,719 - util.py[DEBUG]: Restoring selinux mode for /var/lib/cloud/instances/i-0c0853353402e1d0e/vendor-data.txt.i (recursive=False)
2022-01-18 13:22:48,720 - util.py[DEBUG]: Restoring selinux mode for /var/lib/cloud/instances/i-0c0853353402e1d0e/vendor-data.txt.i (recursive=False)
2022-01-18 13:22:48,721 - util.py[DEBUG]: Writing to /var/lib/cloud/instances/i-0c0853353402e1d0e/sem/consume_data - wb: [420] 19 bytes
2022-01-18 13:22:48,721 - util.py[DEBUG]: Restoring selinux mode for /var/lib/cloud/instances/i-0c0853353402e1d0e/sem/consume_data (recursive=False)
2022-01-18 13:22:48,722 - util.py[DEBUG]: Restoring selinux mode for /var/lib/cloud/instances/i-0c0853353402e1d0e/sem/consume_data (recursive=False)
2022-01-18 13:22:48,722 - helpers.py[DEBUG]: Running consume_data using lock (<FileLock using file '/var/lib/cloud/instances/i-0c0853353402e1d0e/sem/consume_data'>)
2022-01-18 13:22:48,722 - handlers.py[DEBUG]: start: init-network/consume-user-data: reading and applying user-data
2022-01-18 13:22:48,722 - launch_index.py[DEBUG]: Discarding 0 multipart messages which do not match launch index 0
2022-01-18 13:22:48,723 - stages.py[DEBUG]: Added default handler for set(['text/cloud-config-jsonp', 'text/cloud-config']) from CloudConfigPartHandler: [['text/cloud-config', 'text/cloud-config-jsonp']]
2022-01-18 13:22:48,723 - stages.py[DEBUG]: Added default handler for set(['text/x-shellscript']) from ShellScriptPartHandler: [['text/x-shellscript']]
2022-01-18 13:22:48,723 - stages.py[DEBUG]: Added default handler for set(['text/cloud-boothook']) from BootHookPartHandler: [['text/cloud-boothook']]
2022-01-18 13:22:48,723 - stages.py[DEBUG]: Added default handler for set(['text/upstart-job']) from UpstartJobPartHandler: [['text/upstart-job']]
2022-01-18 13:22:48,723 - __init__.py[DEBUG]: Calling handler BootHookPartHandler: [['text/cloud-boothook']] (__begin__, None, 2) with frequency once-per-instance
2022-01-18 13:22:48,723 - __init__.py[DEBUG]: Calling handler UpstartJobPartHandler: [['text/upstart-job']] (__begin__, None, 2) with frequency once-per-instance
2022-01-18 13:22:48,723 - __init__.py[DEBUG]: Calling handler CloudConfigPartHandler: [['text/cloud-config', 'text/cloud-config-jsonp']] (__begin__, None, 3) with frequency once-per-instance
2022-01-18 13:22:48,723 - __init__.py[DEBUG]: Calling handler ShellScriptPartHandler: [['text/x-shellscript']] (__begin__, None, 2) with frequency once-per-instance
2022-01-18 13:22:48,724 - __init__.py[DEBUG]: {'Content-Type': 'text/cloud-config', 'Content-Disposition': 'attachment; filename="part-001"', 'MIME-Version': '1.0'}
2022-01-18 13:22:48,724 - __init__.py[DEBUG]: Calling handler CloudConfigPartHandler: [['text/cloud-config', 'text/cloud-config-jsonp']] (text/cloud-config, part-001, 3) with frequency once-per-instance
2022-01-18 13:22:48,724 - util.py[DEBUG]: Attempting to load yaml from string of length 179 with allowed root types (<type 'dict'>,)
2022-01-18 13:22:48,725 - cloud_config.py[DEBUG]: Merging by applying [('dict', ['replace']), ('list', []), ('str', [])]
2022-01-18 13:22:48,725 - __init__.py[DEBUG]: Calling handler BootHookPartHandler: [['text/cloud-boothook']] (__end__, None, 2) with frequency once-per-instance
2022-01-18 13:22:48,725 - __init__.py[DEBUG]: Calling handler UpstartJobPartHandler: [['text/upstart-job']] (__end__, None, 2) with frequency once-per-instance
2022-01-18 13:22:48,725 - __init__.py[DEBUG]: Calling handler CloudConfigPartHandler: [['text/cloud-config', 'text/cloud-config-jsonp']] (__end__, None, 3) with frequency once-per-instance
2022-01-18 13:22:48,726 - util.py[DEBUG]: Writing to /var/lib/cloud/instances/i-0c0853353402e1d0e/cloud-config.txt - wb: [384] 168 bytes
2022-01-18 13:22:48,726 - util.py[DEBUG]: Restoring selinux mode for /var/lib/cloud/instances/i-0c0853353402e1d0e/cloud-config.txt (recursive=False)
2022-01-18 13:22:48,727 - util.py[DEBUG]: Restoring selinux mode for /var/lib/cloud/instances/i-0c0853353402e1d0e/cloud-config.txt (recursive=False)
2022-01-18 13:22:48,727 - __init__.py[DEBUG]: Calling handler ShellScriptPartHandler: [['text/x-shellscript']] (__end__, None, 2) with frequency once-per-instance
2022-01-18 13:22:48,727 - handlers.py[DEBUG]: finish: init-network/consume-user-data: SUCCESS: reading and applying user-data
2022-01-18 13:22:48,728 - handlers.py[DEBUG]: start: init-network/consume-vendor-data: reading and applying vendor-data
2022-01-18 13:22:48,728 - stages.py[DEBUG]: no vendordata from datasource
2022-01-18 13:22:48,728 - handlers.py[DEBUG]: finish: init-network/consume-vendor-data: SUCCESS: reading and applying vendor-data
2022-01-18 13:22:48,728 - util.py[DEBUG]: Reading from /etc/cloud/cloud.cfg (quiet=False)
2022-01-18 13:22:48,728 - util.py[DEBUG]: Read 1146 bytes from /etc/cloud/cloud.cfg
2022-01-18 13:22:48,728 - util.py[DEBUG]: Attempting to load yaml from string of length 1146 with allowed root types (<type 'dict'>,)
2022-01-18 13:22:48,736 - util.py[DEBUG]: Reading from /etc/cloud/cloud.cfg.d/05_logging.cfg (quiet=False)
2022-01-18 13:22:48,736 - util.py[DEBUG]: Read 1821 bytes from /etc/cloud/cloud.cfg.d/05_logging.cfg
2022-01-18 13:22:48,736 - util.py[DEBUG]: Attempting to load yaml from string of length 1821 with allowed root types (<type 'dict'>,)
2022-01-18 13:22:48,741 - util.py[DEBUG]: Attempting to load yaml from string of length 0 with allowed root types (<type 'dict'>,)
2022-01-18 13:22:48,741 - util.py[DEBUG]: load_yaml given empty string, returning default
2022-01-18 13:22:48,741 - util.py[DEBUG]: Reading from /var/lib/cloud/instance/cloud-config.txt (quiet=False)
2022-01-18 13:22:48,741 - util.py[DEBUG]: Read 168 bytes from /var/lib/cloud/instance/cloud-config.txt
2022-01-18 13:22:48,741 - util.py[DEBUG]: Attempting to load yaml from string of length 168 with allowed root types (<type 'dict'>,)
2022-01-18 13:22:48,743 - util.py[DEBUG]: Reading from /var/lib/cloud/instance/cloud-config.txt (quiet=False)
2022-01-18 13:22:48,743 - util.py[DEBUG]: Read 168 bytes from /var/lib/cloud/instance/cloud-config.txt
2022-01-18 13:22:48,743 - util.py[DEBUG]: Attempting to load yaml from string of length 168 with allowed root types (<type 'dict'>,)
2022-01-18 13:22:48,747 - util.py[DEBUG]: Writing to /var/lib/cloud/instance/obj.pkl - wb: [256] 5546 bytes
2022-01-18 13:22:48,747 - util.py[DEBUG]: Restoring selinux mode for /var/lib/cloud/instances/i-0c0853353402e1d0e/obj.pkl (recursive=False)
2022-01-18 13:22:48,748 - util.py[DEBUG]: Restoring selinux mode for /var/lib/cloud/instances/i-0c0853353402e1d0e/obj.pkl (recursive=False)
2022-01-18 13:22:48,757 - stages.py[DEBUG]: Using distro class <class 'cloudinit.distros.rhel.Distro'>
2022-01-18 13:22:48,757 - stages.py[DEBUG]: Running module migrator (<module 'cloudinit.config.cc_migrator' from '/usr/lib/python2.7/site-packages/cloudinit/config/cc_migrator.pyc'>) with frequency always
2022-01-18 13:22:48,758 - handlers.py[DEBUG]: start: init-network/config-migrator: running config-migrator with frequency always
2022-01-18 13:22:48,758 - helpers.py[DEBUG]: Running config-migrator using lock (<cloudinit.helpers.DummyLock object at 0x7f4b46e4a310>)
2022-01-18 13:22:48,758 - cc_migrator.py[DEBUG]: Migrated 0 semaphore files to there canonicalized names
2022-01-18 13:22:48,758 - handlers.py[DEBUG]: finish: init-network/config-migrator: SUCCESS: config-migrator ran successfully
2022-01-18 13:22:48,758 - stages.py[DEBUG]: Running module bootcmd (<module 'cloudinit.config.cc_bootcmd' from '/usr/lib/python2.7/site-packages/cloudinit/config/cc_bootcmd.pyc'>) with frequency always
2022-01-18 13:22:48,758 - handlers.py[DEBUG]: start: init-network/config-bootcmd: running config-bootcmd with frequency always
2022-01-18 13:22:48,758 - helpers.py[DEBUG]: Running config-bootcmd using lock (<cloudinit.helpers.DummyLock object at 0x7f4b46e4a410>)
2022-01-18 13:22:48,758 - cc_bootcmd.py[DEBUG]: Skipping module named bootcmd, no 'bootcmd' key in configuration
2022-01-18 13:22:48,758 - handlers.py[DEBUG]: finish: init-network/config-bootcmd: SUCCESS: config-bootcmd ran successfully
2022-01-18 13:22:48,758 - stages.py[DEBUG]: Running module write-files (<module 'cloudinit.config.cc_write_files' from '/usr/lib/python2.7/site-packages/cloudinit/config/cc_write_files.pyc'>) with frequency once-per-instance
2022-01-18 13:22:48,759 - handlers.py[DEBUG]: start: init-network/config-write-files: running config-write-files with frequency once-per-instance
2022-01-18 13:22:48,759 - util.py[DEBUG]: Writing to /var/lib/cloud/instances/i-0c0853353402e1d0e/sem/config_write_files - wb: [420] 19 bytes
2022-01-18 13:22:48,759 - util.py[DEBUG]: Restoring selinux mode for /var/lib/cloud/instances/i-0c0853353402e1d0e/sem/config_write_files (recursive=False)
2022-01-18 13:22:48,760 - util.py[DEBUG]: Restoring selinux mode for /var/lib/cloud/instances/i-0c0853353402e1d0e/sem/config_write_files (recursive=False)
2022-01-18 13:22:48,760 - helpers.py[DEBUG]: Running config-write-files using lock (<FileLock using file '/var/lib/cloud/instances/i-0c0853353402e1d0e/sem/config_write_files'>)
2022-01-18 13:22:48,760 - cc_write_files.py[DEBUG]: Skipping module named write-files, no/empty 'write_files' key in configuration
2022-01-18 13:22:48,760 - handlers.py[DEBUG]: finish: init-network/config-write-files: SUCCESS: config-write-files ran successfully
2022-01-18 13:22:48,760 - stages.py[DEBUG]: Running module growpart (<module 'cloudinit.config.cc_growpart' from '/usr/lib/python2.7/site-packages/cloudinit/config/cc_growpart.pyc'>) with frequency always
2022-01-18 13:22:48,761 - handlers.py[DEBUG]: start: init-network/config-growpart: running config-growpart with frequency always
2022-01-18 13:22:48,761 - helpers.py[DEBUG]: Running config-growpart using lock (<cloudinit.helpers.DummyLock object at 0x7f4b46e4a5d0>)
2022-01-18 13:22:48,761 - cc_growpart.py[DEBUG]: No 'growpart' entry in cfg.  Using default: {'ignore_growroot_disabled': False, 'mode': 'auto', 'devices': ['/']}
2022-01-18 13:22:48,761 - util.py[DEBUG]: Running command ['growpart', '--help'] with allowed return codes [0] (shell=False, capture=True)
2022-01-18 13:22:48,770 - util.py[DEBUG]: Reading from /proc/860/mountinfo (quiet=False)
2022-01-18 13:22:48,770 - util.py[DEBUG]: Read 2863 bytes from /proc/860/mountinfo
2022-01-18 13:22:48,771 - util.py[DEBUG]: Reading from /sys/class/block/nvme0n1p1/partition (quiet=False)
2022-01-18 13:22:48,771 - util.py[DEBUG]: Read 2 bytes from /sys/class/block/nvme0n1p1/partition
2022-01-18 13:22:48,771 - util.py[DEBUG]: Reading from /sys/devices/pci0000:00/0000:00:04.0/nvme/nvme0/nvme0n1/dev (quiet=False)
2022-01-18 13:22:48,772 - util.py[DEBUG]: Read 6 bytes from /sys/devices/pci0000:00/0000:00:04.0/nvme/nvme0/nvme0n1/dev
2022-01-18 13:22:48,772 - util.py[DEBUG]: Running command ['growpart', '--dry-run', '/dev/nvme0n1', '1'] with allowed return codes [0] (shell=False, capture=True)
2022-01-18 13:22:48,808 - util.py[DEBUG]: Running command ['growpart', '/dev/nvme0n1', '1'] with allowed return codes [0] (shell=False, capture=True)
2022-01-18 13:22:48,849 - util.py[DEBUG]: resize_devices took 0.079 seconds
2022-01-18 13:22:48,850 - cc_growpart.py[INFO]: '/' resized: changed (/dev/nvme0n1, 1) from 8588886016 to 21473771008
2022-01-18 13:22:48,850 - handlers.py[DEBUG]: finish: init-network/config-growpart: SUCCESS: config-growpart ran successfully
2022-01-18 13:22:48,850 - stages.py[DEBUG]: Running module resizefs (<module 'cloudinit.config.cc_resizefs' from '/usr/lib/python2.7/site-packages/cloudinit/config/cc_resizefs.pyc'>) with frequency always
2022-01-18 13:22:48,851 - handlers.py[DEBUG]: start: init-network/config-resizefs: running config-resizefs with frequency always
2022-01-18 13:22:48,851 - helpers.py[DEBUG]: Running config-resizefs using lock (<cloudinit.helpers.DummyLock object at 0x7f4b46e4a690>)
2022-01-18 13:22:48,851 - util.py[DEBUG]: Reading from /proc/860/mountinfo (quiet=False)
2022-01-18 13:22:48,852 - util.py[DEBUG]: Read 2863 bytes from /proc/860/mountinfo
2022-01-18 13:22:48,852 - cc_resizefs.py[DEBUG]: resize_info: dev=/dev/nvme0n1p1 mnt_point=/ path=/
2022-01-18 13:22:48,852 - util.py[DEBUG]: Running command ['systemd-detect-virt', '--quiet', '--container'] with allowed return codes [0] (shell=False, capture=True)
2022-01-18 13:22:48,856 - util.py[DEBUG]: Running command ['running-in-container'] with allowed return codes [0] (shell=False, capture=True)
2022-01-18 13:22:48,860 - util.py[DEBUG]: Running command ['lxc-is-container'] with allowed return codes [0] (shell=False, capture=True)
2022-01-18 13:22:48,863 - util.py[DEBUG]: Reading from /proc/1/environ (quiet=False)
2022-01-18 13:22:48,863 - util.py[DEBUG]: Read 0 bytes from /proc/1/environ
2022-01-18 13:22:48,863 - util.py[DEBUG]: Reading from /proc/self/status (quiet=False)
2022-01-18 13:22:48,863 - util.py[DEBUG]: Read 1182 bytes from /proc/self/status
2022-01-18 13:22:48,863 - cc_resizefs.py[DEBUG]: Resizing / (xfs) using xfs_growfs /dev/nvme0n1p1
2022-01-18 13:22:48,863 - util.py[DEBUG]: Running command ('xfs_growfs', '/dev/nvme0n1p1') with allowed return codes [0] (shell=False, capture=True)
2022-01-18 13:22:48,907 - util.py[DEBUG]: Resizing took 0.043 seconds
2022-01-18 13:22:48,907 - cc_resizefs.py[DEBUG]: Resized root filesystem (type=xfs, val=True)
2022-01-18 13:22:48,907 - handlers.py[DEBUG]: finish: init-network/config-resizefs: SUCCESS: config-resizefs ran successfully
2022-01-18 13:22:48,907 - stages.py[DEBUG]: Running module set_hostname (<module 'cloudinit.config.cc_set_hostname' from '/usr/lib/python2.7/site-packages/cloudinit/config/cc_set_hostname.pyc'>) with frequency once-per-instance
2022-01-18 13:22:48,908 - handlers.py[DEBUG]: start: init-network/config-set_hostname: running config-set_hostname with frequency once-per-instance
2022-01-18 13:22:48,908 - util.py[DEBUG]: Writing to /var/lib/cloud/instances/i-0c0853353402e1d0e/sem/config_set_hostname - wb: [420] 19 bytes
2022-01-18 13:22:48,908 - util.py[DEBUG]: Restoring selinux mode for /var/lib/cloud/instances/i-0c0853353402e1d0e/sem/config_set_hostname (recursive=False)
2022-01-18 13:22:48,909 - util.py[DEBUG]: Restoring selinux mode for /var/lib/cloud/instances/i-0c0853353402e1d0e/sem/config_set_hostname (recursive=False)
2022-01-18 13:22:48,910 - helpers.py[DEBUG]: Running config-set_hostname using lock (<FileLock using file '/var/lib/cloud/instances/i-0c0853353402e1d0e/sem/config_set_hostname'>)
2022-01-18 13:22:48,910 - cc_set_hostname.py[DEBUG]: Setting the hostname to ci3-1569ld597725-hf1.class.splunk.com (ci3-1569ld597725-hf1)
2022-01-18 13:22:48,910 - util.py[DEBUG]: Running command ['hostnamectl', 'set-hostname', 'ci3-1569ld597725-hf1.class.splunk.com'] with allowed return codes [0] (shell=False, capture=True)
2022-01-18 13:22:48,956 - __init__.py[DEBUG]: Non-persistently setting the system hostname to ci3-1569ld597725-hf1.class.splunk.com
2022-01-18 13:22:48,956 - util.py[DEBUG]: Running command ['hostname', 'ci3-1569ld597725-hf1.class.splunk.com'] with allowed return codes [0] (shell=False, capture=True)
2022-01-18 13:22:48,960 - handlers.py[DEBUG]: finish: init-network/config-set_hostname: SUCCESS: config-set_hostname ran successfully
2022-01-18 13:22:48,960 - stages.py[DEBUG]: Running module update_hostname (<module 'cloudinit.config.cc_update_hostname' from '/usr/lib/python2.7/site-packages/cloudinit/config/cc_update_hostname.pyc'>) with frequency always
2022-01-18 13:22:48,960 - handlers.py[DEBUG]: start: init-network/config-update_hostname: running config-update_hostname with frequency always
2022-01-18 13:22:48,960 - helpers.py[DEBUG]: Running config-update_hostname using lock (<cloudinit.helpers.DummyLock object at 0x7f4b46e4acd0>)
2022-01-18 13:22:48,960 - cc_update_hostname.py[DEBUG]: Updating hostname to ci3-1569ld597725-hf1.class.splunk.com (ci3-1569ld597725-hf1)
2022-01-18 13:22:48,960 - util.py[DEBUG]: Running command ['hostname'] with allowed return codes [0] (shell=False, capture=True)
2022-01-18 13:22:48,963 - __init__.py[DEBUG]: Attempting to update hostname to ci3-1569ld597725-hf1.class.splunk.com in 1 files
2022-01-18 13:22:48,963 - util.py[DEBUG]: Writing to /var/lib/cloud/data/previous-hostname - wb: [420] 37 bytes
2022-01-18 13:22:48,964 - util.py[DEBUG]: Restoring selinux mode for /var/lib/cloud/data/previous-hostname (recursive=False)
2022-01-18 13:22:48,964 - util.py[DEBUG]: Restoring selinux mode for /var/lib/cloud/data/previous-hostname (recursive=False)
2022-01-18 13:22:48,965 - handlers.py[DEBUG]: finish: init-network/config-update_hostname: SUCCESS: config-update_hostname ran successfully
2022-01-18 13:22:48,965 - stages.py[DEBUG]: Running module update_etc_hosts (<module 'cloudinit.config.cc_update_etc_hosts' from '/usr/lib/python2.7/site-packages/cloudinit/config/cc_update_etc_hosts.pyc'>) with frequency always
2022-01-18 13:22:48,965 - handlers.py[DEBUG]: start: init-network/config-update_etc_hosts: running config-update_etc_hosts with frequency always
2022-01-18 13:22:48,965 - helpers.py[DEBUG]: Running config-update_etc_hosts using lock (<cloudinit.helpers.DummyLock object at 0x7f4b46e4abd0>)
2022-01-18 13:22:48,966 - util.py[DEBUG]: Reading from /etc/cloud/templates/hosts.redhat.tmpl (quiet=False)
2022-01-18 13:22:48,966 - util.py[DEBUG]: Read 912 bytes from /etc/cloud/templates/hosts.redhat.tmpl
2022-01-18 13:22:48,966 - templater.py[DEBUG]: Rendering content of '/etc/cloud/templates/hosts.redhat.tmpl' using renderer jinja
2022-01-18 13:22:48,970 - util.py[DEBUG]: Writing to /etc/hosts - wb: [420] 764 bytes
2022-01-18 13:22:48,971 - util.py[DEBUG]: Restoring selinux mode for /etc/hosts (recursive=False)
2022-01-18 13:22:48,971 - util.py[DEBUG]: Restoring selinux mode for /etc/hosts (recursive=False)
2022-01-18 13:22:48,971 - handlers.py[DEBUG]: finish: init-network/config-update_etc_hosts: SUCCESS: config-update_etc_hosts ran successfully
2022-01-18 13:22:48,971 - stages.py[DEBUG]: Running module rsyslog (<module 'cloudinit.config.cc_rsyslog' from '/usr/lib/python2.7/site-packages/cloudinit/config/cc_rsyslog.pyc'>) with frequency once-per-instance
2022-01-18 13:22:48,972 - handlers.py[DEBUG]: start: init-network/config-rsyslog: running config-rsyslog with frequency once-per-instance
2022-01-18 13:22:48,972 - util.py[DEBUG]: Writing to /var/lib/cloud/instances/i-0c0853353402e1d0e/sem/config_rsyslog - wb: [420] 19 bytes
2022-01-18 13:22:48,972 - util.py[DEBUG]: Restoring selinux mode for /var/lib/cloud/instances/i-0c0853353402e1d0e/sem/config_rsyslog (recursive=False)
2022-01-18 13:22:48,973 - util.py[DEBUG]: Restoring selinux mode for /var/lib/cloud/instances/i-0c0853353402e1d0e/sem/config_rsyslog (recursive=False)
2022-01-18 13:22:48,973 - helpers.py[DEBUG]: Running config-rsyslog using lock (<FileLock using file '/var/lib/cloud/instances/i-0c0853353402e1d0e/sem/config_rsyslog'>)
2022-01-18 13:22:48,973 - cc_rsyslog.py[DEBUG]: Skipping module named rsyslog, no 'rsyslog' key in configuration
2022-01-18 13:22:48,974 - handlers.py[DEBUG]: finish: init-network/config-rsyslog: SUCCESS: config-rsyslog ran successfully
2022-01-18 13:22:48,974 - stages.py[DEBUG]: Running module users-groups (<module 'cloudinit.config.cc_users_groups' from '/usr/lib/python2.7/site-packages/cloudinit/config/cc_users_groups.pyc'>) with frequency once-per-instance
2022-01-18 13:22:48,974 - handlers.py[DEBUG]: start: init-network/config-users-groups: running config-users-groups with frequency once-per-instance
2022-01-18 13:22:48,974 - util.py[DEBUG]: Writing to /var/lib/cloud/instances/i-0c0853353402e1d0e/sem/config_users_groups - wb: [420] 19 bytes
2022-01-18 13:22:48,975 - util.py[DEBUG]: Restoring selinux mode for /var/lib/cloud/instances/i-0c0853353402e1d0e/sem/config_users_groups (recursive=False)
2022-01-18 13:22:48,975 - util.py[DEBUG]: Restoring selinux mode for /var/lib/cloud/instances/i-0c0853353402e1d0e/sem/config_users_groups (recursive=False)
2022-01-18 13:22:48,976 - helpers.py[DEBUG]: Running config-users-groups using lock (<FileLock using file '/var/lib/cloud/instances/i-0c0853353402e1d0e/sem/config_users_groups'>)
2022-01-18 13:22:48,976 - util.py[DEBUG]: Reading from /etc/system-image/channel.ini (quiet=True)
2022-01-18 13:22:48,976 - util.py[DEBUG]: Read 0 bytes from /etc/system-image/channel.ini
2022-01-18 13:22:48,976 - __init__.py[DEBUG]: Adding user centos
2022-01-18 13:22:48,976 - util.py[DEBUG]: Running hidden command to protect sensitive input/output logstring: ['useradd', 'centos', '--comment', 'Cloud User', '--groups', 'adm,systemd-journal,wheel', '--shell', '/bin/bash', '-m']
2022-01-18 13:22:49,010 - util.py[DEBUG]: Running command ['passwd', '-l', 'centos'] with allowed return codes [0] (shell=False, capture=True)
2022-01-18 13:22:49,035 - util.py[DEBUG]: Reading from /etc/sudoers (quiet=False)
2022-01-18 13:22:49,036 - util.py[DEBUG]: Read 3938 bytes from /etc/sudoers
2022-01-18 13:22:49,036 - util.py[DEBUG]: Restoring selinux mode for /etc/sudoers.d (recursive=False)
2022-01-18 13:22:49,037 - util.py[DEBUG]: Writing to /etc/sudoers.d/90-cloud-init-users - wb: [288] 123 bytes
2022-01-18 13:22:49,037 - util.py[DEBUG]: Restoring selinux mode for /etc/sudoers.d/90-cloud-init-users (recursive=False)
2022-01-18 13:22:49,038 - util.py[DEBUG]: Restoring selinux mode for /etc/sudoers.d/90-cloud-init-users (recursive=False)
2022-01-18 13:22:49,038 - handlers.py[DEBUG]: finish: init-network/config-users-groups: SUCCESS: config-users-groups ran successfully
2022-01-18 13:22:49,038 - stages.py[DEBUG]: Running module ssh (<module 'cloudinit.config.cc_ssh' from '/usr/lib/python2.7/site-packages/cloudinit/config/cc_ssh.pyc'>) with frequency once-per-instance
2022-01-18 13:22:49,038 - handlers.py[DEBUG]: start: init-network/config-ssh: running config-ssh with frequency once-per-instance
2022-01-18 13:22:49,039 - util.py[DEBUG]: Writing to /var/lib/cloud/instances/i-0c0853353402e1d0e/sem/config_ssh - wb: [420] 19 bytes
2022-01-18 13:22:49,039 - util.py[DEBUG]: Restoring selinux mode for /var/lib/cloud/instances/i-0c0853353402e1d0e/sem/config_ssh (recursive=False)
2022-01-18 13:22:49,040 - util.py[DEBUG]: Restoring selinux mode for /var/lib/cloud/instances/i-0c0853353402e1d0e/sem/config_ssh (recursive=False)
2022-01-18 13:22:49,040 - helpers.py[DEBUG]: Running config-ssh using lock (<FileLock using file '/var/lib/cloud/instances/i-0c0853353402e1d0e/sem/config_ssh'>)
2022-01-18 13:22:49,042 - util.py[DEBUG]: Restoring selinux mode for /home/centos (recursive=True)
2022-01-18 13:22:49,043 - util.py[DEBUG]: Restoring selinux mode for /home/centos/.ssh (recursive=False)
2022-01-18 13:22:49,043 - util.py[DEBUG]: Changing the ownership of /home/centos/.ssh to 1000:1000
2022-01-18 13:22:49,043 - util.py[DEBUG]: Reading from /etc/ssh/sshd_config (quiet=False)
2022-01-18 13:22:49,044 - util.py[DEBUG]: Read 3907 bytes from /etc/ssh/sshd_config
2022-01-18 13:22:49,044 - util.py[DEBUG]: Restoring selinux mode for /home/centos/.ssh (recursive=True)
2022-01-18 13:22:49,045 - util.py[DEBUG]: Restoring selinux mode for /home/centos/.ssh (recursive=False)
2022-01-18 13:22:49,045 - util.py[DEBUG]: Writing to /home/centos/.ssh/authorized_keys - wb: [384] 390 bytes
2022-01-18 13:22:49,045 - util.py[DEBUG]: Restoring selinux mode for /home/centos/.ssh/authorized_keys (recursive=False)
2022-01-18 13:22:49,045 - util.py[DEBUG]: Restoring selinux mode for /home/centos/.ssh/authorized_keys (recursive=False)
2022-01-18 13:22:49,046 - util.py[DEBUG]: Changing the ownership of /home/centos/.ssh/authorized_keys to 1000:1000
2022-01-18 13:22:49,046 - util.py[DEBUG]: Restoring selinux mode for /home/centos/.ssh (recursive=True)
2022-01-18 13:22:49,047 - util.py[DEBUG]: Restoring selinux mode for /root (recursive=True)
2022-01-18 13:22:49,049 - util.py[DEBUG]: Restoring selinux mode for /root/.ssh (recursive=False)
2022-01-18 13:22:49,049 - util.py[DEBUG]: Changing the ownership of /root/.ssh to 0:0
2022-01-18 13:22:49,049 - util.py[DEBUG]: Reading from /etc/ssh/sshd_config (quiet=False)
2022-01-18 13:22:49,049 - util.py[DEBUG]: Read 3907 bytes from /etc/ssh/sshd_config
2022-01-18 13:22:49,050 - util.py[DEBUG]: Restoring selinux mode for /root/.ssh (recursive=True)
2022-01-18 13:22:49,050 - util.py[DEBUG]: Restoring selinux mode for /root/.ssh (recursive=False)
2022-01-18 13:22:49,050 - util.py[DEBUG]: Writing to /root/.ssh/authorized_keys - wb: [384] 390 bytes
2022-01-18 13:22:49,050 - util.py[DEBUG]: Restoring selinux mode for /root/.ssh/authorized_keys (recursive=False)
2022-01-18 13:22:49,050 - util.py[DEBUG]: Restoring selinux mode for /root/.ssh/authorized_keys (recursive=False)
2022-01-18 13:22:49,051 - util.py[DEBUG]: Changing the ownership of /root/.ssh/authorized_keys to 0:0
2022-01-18 13:22:49,051 - util.py[DEBUG]: Restoring selinux mode for /root/.ssh (recursive=True)
2022-01-18 13:22:49,051 - handlers.py[DEBUG]: finish: init-network/config-ssh: SUCCESS: config-ssh ran successfully
2022-01-18 13:22:49,051 - main.py[DEBUG]: Ran 11 modules with 0 failures
2022-01-18 13:22:49,051 - util.py[DEBUG]: Reading from /proc/uptime (quiet=False)
2022-01-18 13:22:49,052 - util.py[DEBUG]: Read 12 bytes from /proc/uptime
2022-01-18 13:22:49,052 - util.py[DEBUG]: cloud-init mode 'init' took 0.811 seconds (0.81)
2022-01-18 13:22:49,052 - handlers.py[DEBUG]: finish: init-network: SUCCESS: searching for network datasources
2022-01-18 13:22:49,554 - util.py[DEBUG]: Cloud-init v. 0.7.9 running 'modules:config' at Tue, 18 Jan 2022 13:22:49 +0000. Up 11.76 seconds.
2022-01-18 13:22:49,585 - stages.py[DEBUG]: Using distro class <class 'cloudinit.distros.rhel.Distro'>
2022-01-18 13:22:49,586 - stages.py[DEBUG]: Running module mounts (<module 'cloudinit.config.cc_mounts' from '/usr/lib/python2.7/site-packages/cloudinit/config/cc_mounts.pyc'>) with frequency once-per-instance
2022-01-18 13:22:49,586 - handlers.py[DEBUG]: start: modules-config/config-mounts: running config-mounts with frequency once-per-instance
2022-01-18 13:22:49,586 - util.py[DEBUG]: Writing to /var/lib/cloud/instances/i-0c0853353402e1d0e/sem/config_mounts - wb: [420] 20 bytes
2022-01-18 13:22:49,587 - util.py[DEBUG]: Restoring selinux mode for /var/lib/cloud/instances/i-0c0853353402e1d0e/sem/config_mounts (recursive=False)
2022-01-18 13:22:49,588 - util.py[DEBUG]: Restoring selinux mode for /var/lib/cloud/instances/i-0c0853353402e1d0e/sem/config_mounts (recursive=False)
2022-01-18 13:22:49,589 - helpers.py[DEBUG]: Running config-mounts using lock (<FileLock using file '/var/lib/cloud/instances/i-0c0853353402e1d0e/sem/config_mounts'>)
2022-01-18 13:22:49,589 - cc_mounts.py[DEBUG]: mounts configuration is []
2022-01-18 13:22:49,589 - cc_mounts.py[DEBUG]: Attempting to determine the real name of ephemeral0
2022-01-18 13:22:49,589 - DataSourceEc2.py[DEBUG]: Unable to convert ephemeral0 to a device
2022-01-18 13:22:49,589 - cc_mounts.py[DEBUG]: Ignoring nonexistant default named mount ephemeral0
2022-01-18 13:22:49,590 - cc_mounts.py[DEBUG]: Attempting to determine the real name of swap
2022-01-18 13:22:49,590 - DataSourceEc2.py[DEBUG]: Unable to convert swap to a device
2022-01-18 13:22:49,590 - cc_mounts.py[DEBUG]: Ignoring nonexistant default named mount swap
2022-01-18 13:22:49,590 - cc_mounts.py[DEBUG]: no need to setup swap
2022-01-18 13:22:49,590 - cc_mounts.py[DEBUG]: No modifications to fstab needed.
2022-01-18 13:22:49,590 - handlers.py[DEBUG]: finish: modules-config/config-mounts: SUCCESS: config-mounts ran successfully
2022-01-18 13:22:49,590 - stages.py[DEBUG]: Running module locale (<module 'cloudinit.config.cc_locale' from '/usr/lib/python2.7/site-packages/cloudinit/config/cc_locale.pyc'>) with frequency once-per-instance
2022-01-18 13:22:49,590 - handlers.py[DEBUG]: start: modules-config/config-locale: running config-locale with frequency once-per-instance
2022-01-18 13:22:49,591 - util.py[DEBUG]: Writing to /var/lib/cloud/instances/i-0c0853353402e1d0e/sem/config_locale - wb: [420] 20 bytes
2022-01-18 13:22:49,592 - util.py[DEBUG]: Restoring selinux mode for /var/lib/cloud/instances/i-0c0853353402e1d0e/sem/config_locale (recursive=False)
2022-01-18 13:22:49,593 - util.py[DEBUG]: Restoring selinux mode for /var/lib/cloud/instances/i-0c0853353402e1d0e/sem/config_locale (recursive=False)
2022-01-18 13:22:49,593 - helpers.py[DEBUG]: Running config-locale using lock (<FileLock using file '/var/lib/cloud/instances/i-0c0853353402e1d0e/sem/config_locale'>)
2022-01-18 13:22:49,593 - cc_locale.py[DEBUG]: Setting locale to en_US.UTF-8
2022-01-18 13:22:49,593 - util.py[DEBUG]: Reading from /etc/locale.conf (quiet=False)
2022-01-18 13:22:49,593 - util.py[DEBUG]: Read 19 bytes from /etc/locale.conf
2022-01-18 13:22:49,594 - util.py[DEBUG]: Writing to /etc/locale.conf - wb: [420] 17 bytes
2022-01-18 13:22:49,594 - util.py[DEBUG]: Restoring selinux mode for /etc/locale.conf (recursive=False)
2022-01-18 13:22:49,595 - util.py[DEBUG]: Restoring selinux mode for /etc/locale.conf (recursive=False)
2022-01-18 13:22:49,595 - handlers.py[DEBUG]: finish: modules-config/config-locale: SUCCESS: config-locale ran successfully
2022-01-18 13:22:49,595 - stages.py[DEBUG]: Running module set-passwords (<module 'cloudinit.config.cc_set_passwords' from '/usr/lib/python2.7/site-packages/cloudinit/config/cc_set_passwords.pyc'>) with frequency once-per-instance
2022-01-18 13:22:49,595 - handlers.py[DEBUG]: start: modules-config/config-set-passwords: running config-set-passwords with frequency once-per-instance
2022-01-18 13:22:49,596 - util.py[DEBUG]: Writing to /var/lib/cloud/instances/i-0c0853353402e1d0e/sem/config_set_passwords - wb: [420] 19 bytes
2022-01-18 13:22:49,596 - util.py[DEBUG]: Restoring selinux mode for /var/lib/cloud/instances/i-0c0853353402e1d0e/sem/config_set_passwords (recursive=False)
2022-01-18 13:22:49,597 - util.py[DEBUG]: Restoring selinux mode for /var/lib/cloud/instances/i-0c0853353402e1d0e/sem/config_set_passwords (recursive=False)
2022-01-18 13:22:49,597 - helpers.py[DEBUG]: Running config-set-passwords using lock (<FileLock using file '/var/lib/cloud/instances/i-0c0853353402e1d0e/sem/config_set_passwords'>)
2022-01-18 13:22:49,597 - util.py[DEBUG]: Reading from /etc/ssh/sshd_config (quiet=False)
2022-01-18 13:22:49,597 - util.py[DEBUG]: Read 3907 bytes from /etc/ssh/sshd_config
2022-01-18 13:22:49,598 - cc_set_passwords.py[DEBUG]: Replacing auth line 65 with no
2022-01-18 13:22:49,598 - util.py[DEBUG]: Writing to /etc/ssh/sshd_config - wb: [384] 3905 bytes
2022-01-18 13:22:49,599 - util.py[DEBUG]: Restoring selinux mode for /etc/ssh/sshd_config (recursive=False)
2022-01-18 13:22:49,599 - util.py[DEBUG]: Restoring selinux mode for /etc/ssh/sshd_config (recursive=False)
2022-01-18 13:22:49,600 - util.py[DEBUG]: Running command ['service', 'sshd', 'restart'] with allowed return codes [0] (shell=False, capture=True)
2022-01-18 13:22:49,675 - cc_set_passwords.py[DEBUG]: Restarted the ssh daemon
2022-01-18 13:22:49,676 - handlers.py[DEBUG]: finish: modules-config/config-set-passwords: SUCCESS: config-set-passwords ran successfully
2022-01-18 13:22:49,676 - stages.py[DEBUG]: Running module rh_subscription (<module 'cloudinit.config.cc_rh_subscription' from '/usr/lib/python2.7/site-packages/cloudinit/config/cc_rh_subscription.pyc'>) with frequency once-per-instance
2022-01-18 13:22:49,676 - handlers.py[DEBUG]: start: modules-config/config-rh_subscription: running config-rh_subscription with frequency once-per-instance
2022-01-18 13:22:49,676 - util.py[DEBUG]: Writing to /var/lib/cloud/instances/i-0c0853353402e1d0e/sem/config_rh_subscription - wb: [420] 20 bytes
2022-01-18 13:22:49,677 - util.py[DEBUG]: Restoring selinux mode for /var/lib/cloud/instances/i-0c0853353402e1d0e/sem/config_rh_subscription (recursive=False)
2022-01-18 13:22:49,678 - util.py[DEBUG]: Restoring selinux mode for /var/lib/cloud/instances/i-0c0853353402e1d0e/sem/config_rh_subscription (recursive=False)
2022-01-18 13:22:49,678 - helpers.py[DEBUG]: Running config-rh_subscription using lock (<FileLock using file '/var/lib/cloud/instances/i-0c0853353402e1d0e/sem/config_rh_subscription'>)
2022-01-18 13:22:49,679 - cc_rh_subscription.py[DEBUG]: rh_subscription: module not configured.
2022-01-18 13:22:49,679 - handlers.py[DEBUG]: finish: modules-config/config-rh_subscription: SUCCESS: config-rh_subscription ran successfully
2022-01-18 13:22:49,679 - stages.py[DEBUG]: Running module yum-add-repo (<module 'cloudinit.config.cc_yum_add_repo' from '/usr/lib/python2.7/site-packages/cloudinit/config/cc_yum_add_repo.pyc'>) with frequency once-per-instance
2022-01-18 13:22:49,679 - handlers.py[DEBUG]: start: modules-config/config-yum-add-repo: running config-yum-add-repo with frequency once-per-instance
2022-01-18 13:22:49,679 - util.py[DEBUG]: Writing to /var/lib/cloud/instances/i-0c0853353402e1d0e/sem/config_yum_add_repo - wb: [420] 20 bytes
2022-01-18 13:22:49,680 - util.py[DEBUG]: Restoring selinux mode for /var/lib/cloud/instances/i-0c0853353402e1d0e/sem/config_yum_add_repo (recursive=False)
2022-01-18 13:22:49,681 - util.py[DEBUG]: Restoring selinux mode for /var/lib/cloud/instances/i-0c0853353402e1d0e/sem/config_yum_add_repo (recursive=False)
2022-01-18 13:22:49,681 - helpers.py[DEBUG]: Running config-yum-add-repo using lock (<FileLock using file '/var/lib/cloud/instances/i-0c0853353402e1d0e/sem/config_yum_add_repo'>)
2022-01-18 13:22:49,681 - cc_yum_add_repo.py[DEBUG]: Skipping module named yum-add-repo, no 'yum_repos' configuration found
2022-01-18 13:22:49,681 - handlers.py[DEBUG]: finish: modules-config/config-yum-add-repo: SUCCESS: config-yum-add-repo ran successfully
2022-01-18 13:22:49,681 - stages.py[DEBUG]: Running module package-update-upgrade-install (<module 'cloudinit.config.cc_package_update_upgrade_install' from '/usr/lib/python2.7/site-packages/cloudinit/config/cc_package_update_upgrade_install.pyc'>) with frequency once-per-instance
2022-01-18 13:22:49,682 - handlers.py[DEBUG]: start: modules-config/config-package-update-upgrade-install: running config-package-update-upgrade-install with frequency once-per-instance
2022-01-18 13:22:49,682 - util.py[DEBUG]: Writing to /var/lib/cloud/instances/i-0c0853353402e1d0e/sem/config_package_update_upgrade_install - wb: [420] 20 bytes
2022-01-18 13:22:49,683 - util.py[DEBUG]: Restoring selinux mode for /var/lib/cloud/instances/i-0c0853353402e1d0e/sem/config_package_update_upgrade_install (recursive=False)
2022-01-18 13:22:49,684 - util.py[DEBUG]: Restoring selinux mode for /var/lib/cloud/instances/i-0c0853353402e1d0e/sem/config_package_update_upgrade_install (recursive=False)
2022-01-18 13:22:49,684 - helpers.py[DEBUG]: Running config-package-update-upgrade-install using lock (<FileLock using file '/var/lib/cloud/instances/i-0c0853353402e1d0e/sem/config_package_update_upgrade_install'>)
2022-01-18 13:22:49,684 - handlers.py[DEBUG]: finish: modules-config/config-package-update-upgrade-install: SUCCESS: config-package-update-upgrade-install ran successfully
2022-01-18 13:22:49,684 - stages.py[DEBUG]: Running module timezone (<module 'cloudinit.config.cc_timezone' from '/usr/lib/python2.7/site-packages/cloudinit/config/cc_timezone.pyc'>) with frequency once-per-instance
2022-01-18 13:22:49,685 - handlers.py[DEBUG]: start: modules-config/config-timezone: running config-timezone with frequency once-per-instance
2022-01-18 13:22:49,685 - util.py[DEBUG]: Writing to /var/lib/cloud/instances/i-0c0853353402e1d0e/sem/config_timezone - wb: [420] 20 bytes
2022-01-18 13:22:49,685 - util.py[DEBUG]: Restoring selinux mode for /var/lib/cloud/instances/i-0c0853353402e1d0e/sem/config_timezone (recursive=False)
2022-01-18 13:22:49,686 - util.py[DEBUG]: Restoring selinux mode for /var/lib/cloud/instances/i-0c0853353402e1d0e/sem/config_timezone (recursive=False)
2022-01-18 13:22:49,686 - helpers.py[DEBUG]: Running config-timezone using lock (<FileLock using file '/var/lib/cloud/instances/i-0c0853353402e1d0e/sem/config_timezone'>)
2022-01-18 13:22:49,686 - cc_timezone.py[DEBUG]: Skipping module named timezone, no 'timezone' specified
2022-01-18 13:22:49,686 - handlers.py[DEBUG]: finish: modules-config/config-timezone: SUCCESS: config-timezone ran successfully
2022-01-18 13:22:49,686 - stages.py[DEBUG]: Running module puppet (<module 'cloudinit.config.cc_puppet' from '/usr/lib/python2.7/site-packages/cloudinit/config/cc_puppet.pyc'>) with frequency once-per-instance
2022-01-18 13:22:49,687 - handlers.py[DEBUG]: start: modules-config/config-puppet: running config-puppet with frequency once-per-instance
2022-01-18 13:22:49,687 - util.py[DEBUG]: Writing to /var/lib/cloud/instances/i-0c0853353402e1d0e/sem/config_puppet - wb: [420] 20 bytes
2022-01-18 13:22:49,687 - util.py[DEBUG]: Restoring selinux mode for /var/lib/cloud/instances/i-0c0853353402e1d0e/sem/config_puppet (recursive=False)
2022-01-18 13:22:49,688 - util.py[DEBUG]: Restoring selinux mode for /var/lib/cloud/instances/i-0c0853353402e1d0e/sem/config_puppet (recursive=False)
2022-01-18 13:22:49,689 - helpers.py[DEBUG]: Running config-puppet using lock (<FileLock using file '/var/lib/cloud/instances/i-0c0853353402e1d0e/sem/config_puppet'>)
2022-01-18 13:22:49,689 - cc_puppet.py[DEBUG]: Skipping module named puppet, no 'puppet' configuration found
2022-01-18 13:22:49,689 - handlers.py[DEBUG]: finish: modules-config/config-puppet: SUCCESS: config-puppet ran successfully
2022-01-18 13:22:49,689 - stages.py[DEBUG]: Running module chef (<module 'cloudinit.config.cc_chef' from '/usr/lib/python2.7/site-packages/cloudinit/config/cc_chef.pyc'>) with frequency once-per-instance
2022-01-18 13:22:49,689 - handlers.py[DEBUG]: start: modules-config/config-chef: running config-chef with frequency once-per-instance
2022-01-18 13:22:49,689 - util.py[DEBUG]: Writing to /var/lib/cloud/instances/i-0c0853353402e1d0e/sem/config_chef - wb: [420] 20 bytes
2022-01-18 13:22:49,690 - util.py[DEBUG]: Restoring selinux mode for /var/lib/cloud/instances/i-0c0853353402e1d0e/sem/config_chef (recursive=False)
2022-01-18 13:22:49,690 - util.py[DEBUG]: Restoring selinux mode for /var/lib/cloud/instances/i-0c0853353402e1d0e/sem/config_chef (recursive=False)
2022-01-18 13:22:49,691 - helpers.py[DEBUG]: Running config-chef using lock (<FileLock using file '/var/lib/cloud/instances/i-0c0853353402e1d0e/sem/config_chef'>)
2022-01-18 13:22:49,691 - cc_chef.py[DEBUG]: Skipping module named chef, no 'chef' key in configuration
2022-01-18 13:22:49,691 - handlers.py[DEBUG]: finish: modules-config/config-chef: SUCCESS: config-chef ran successfully
2022-01-18 13:22:49,691 - stages.py[DEBUG]: Running module salt-minion (<module 'cloudinit.config.cc_salt_minion' from '/usr/lib/python2.7/site-packages/cloudinit/config/cc_salt_minion.pyc'>) with frequency once-per-instance
2022-01-18 13:22:49,691 - handlers.py[DEBUG]: start: modules-config/config-salt-minion: running config-salt-minion with frequency once-per-instance
2022-01-18 13:22:49,692 - util.py[DEBUG]: Writing to /var/lib/cloud/instances/i-0c0853353402e1d0e/sem/config_salt_minion - wb: [420] 20 bytes
2022-01-18 13:22:49,692 - util.py[DEBUG]: Restoring selinux mode for /var/lib/cloud/instances/i-0c0853353402e1d0e/sem/config_salt_minion (recursive=False)
2022-01-18 13:22:49,693 - util.py[DEBUG]: Restoring selinux mode for /var/lib/cloud/instances/i-0c0853353402e1d0e/sem/config_salt_minion (recursive=False)
2022-01-18 13:22:49,693 - helpers.py[DEBUG]: Running config-salt-minion using lock (<FileLock using file '/var/lib/cloud/instances/i-0c0853353402e1d0e/sem/config_salt_minion'>)
2022-01-18 13:22:49,693 - cc_salt_minion.py[DEBUG]: Skipping module named salt-minion, no 'salt_minion' key in configuration
2022-01-18 13:22:49,693 - handlers.py[DEBUG]: finish: modules-config/config-salt-minion: SUCCESS: config-salt-minion ran successfully
2022-01-18 13:22:49,693 - stages.py[DEBUG]: Running module mcollective (<module 'cloudinit.config.cc_mcollective' from '/usr/lib/python2.7/site-packages/cloudinit/config/cc_mcollective.pyc'>) with frequency once-per-instance
2022-01-18 13:22:49,693 - handlers.py[DEBUG]: start: modules-config/config-mcollective: running config-mcollective with frequency once-per-instance
2022-01-18 13:22:49,694 - util.py[DEBUG]: Writing to /var/lib/cloud/instances/i-0c0853353402e1d0e/sem/config_mcollective - wb: [420] 20 bytes
2022-01-18 13:22:49,694 - util.py[DEBUG]: Restoring selinux mode for /var/lib/cloud/instances/i-0c0853353402e1d0e/sem/config_mcollective (recursive=False)
2022-01-18 13:22:49,695 - util.py[DEBUG]: Restoring selinux mode for /var/lib/cloud/instances/i-0c0853353402e1d0e/sem/config_mcollective (recursive=False)
2022-01-18 13:22:49,695 - helpers.py[DEBUG]: Running config-mcollective using lock (<FileLock using file '/var/lib/cloud/instances/i-0c0853353402e1d0e/sem/config_mcollective'>)
2022-01-18 13:22:49,695 - cc_mcollective.py[DEBUG]: Skipping module named mcollective, no 'mcollective' key in configuration
2022-01-18 13:22:49,695 - handlers.py[DEBUG]: finish: modules-config/config-mcollective: SUCCESS: config-mcollective ran successfully
2022-01-18 13:22:49,695 - stages.py[DEBUG]: Running module disable-ec2-metadata (<module 'cloudinit.config.cc_disable_ec2_metadata' from '/usr/lib/python2.7/site-packages/cloudinit/config/cc_disable_ec2_metadata.pyc'>) with frequency always
2022-01-18 13:22:49,696 - handlers.py[DEBUG]: start: modules-config/config-disable-ec2-metadata: running config-disable-ec2-metadata with frequency always
2022-01-18 13:22:49,696 - helpers.py[DEBUG]: Running config-disable-ec2-metadata using lock (<cloudinit.helpers.DummyLock object at 0x7f6c1774f550>)
2022-01-18 13:22:49,696 - cc_disable_ec2_metadata.py[DEBUG]: Skipping module named disable-ec2-metadata, disabling the ec2 route not enabled
2022-01-18 13:22:49,696 - handlers.py[DEBUG]: finish: modules-config/config-disable-ec2-metadata: SUCCESS: config-disable-ec2-metadata ran successfully
2022-01-18 13:22:49,696 - stages.py[DEBUG]: Running module runcmd (<module 'cloudinit.config.cc_runcmd' from '/usr/lib/python2.7/site-packages/cloudinit/config/cc_runcmd.pyc'>) with frequency once-per-instance
2022-01-18 13:22:49,696 - handlers.py[DEBUG]: start: modules-config/config-runcmd: running config-runcmd with frequency once-per-instance
2022-01-18 13:22:49,696 - util.py[DEBUG]: Writing to /var/lib/cloud/instances/i-0c0853353402e1d0e/sem/config_runcmd - wb: [420] 19 bytes
2022-01-18 13:22:49,697 - util.py[DEBUG]: Restoring selinux mode for /var/lib/cloud/instances/i-0c0853353402e1d0e/sem/config_runcmd (recursive=False)
2022-01-18 13:22:49,698 - util.py[DEBUG]: Restoring selinux mode for /var/lib/cloud/instances/i-0c0853353402e1d0e/sem/config_runcmd (recursive=False)
2022-01-18 13:22:49,698 - helpers.py[DEBUG]: Running config-runcmd using lock (<FileLock using file '/var/lib/cloud/instances/i-0c0853353402e1d0e/sem/config_runcmd'>)
2022-01-18 13:22:49,698 - cc_runcmd.py[DEBUG]: Skipping module named runcmd, no 'runcmd' key in configuration
2022-01-18 13:22:49,698 - handlers.py[DEBUG]: finish: modules-config/config-runcmd: SUCCESS: config-runcmd ran successfully
2022-01-18 13:22:49,698 - main.py[DEBUG]: Ran 13 modules with 0 failures
2022-01-18 13:22:49,699 - util.py[DEBUG]: Reading from /proc/uptime (quiet=False)
2022-01-18 13:22:49,699 - util.py[DEBUG]: Read 12 bytes from /proc/uptime
2022-01-18 13:22:49,699 - util.py[DEBUG]: cloud-init mode 'modules' took 0.236 seconds (0.24)
2022-01-18 13:22:49,699 - handlers.py[DEBUG]: finish: modules-config: SUCCESS: running modules for config
2022-01-18 13:22:50,031 - util.py[DEBUG]: Cloud-init v. 0.7.9 running 'modules:final' at Tue, 18 Jan 2022 13:22:49 +0000. Up 12.24 seconds.
2022-01-18 13:22:50,044 - stages.py[DEBUG]: Using distro class <class 'cloudinit.distros.rhel.Distro'>
2022-01-18 13:22:50,045 - stages.py[DEBUG]: Running module rightscale_userdata (<module 'cloudinit.config.cc_rightscale_userdata' from '/usr/lib/python2.7/site-packages/cloudinit/config/cc_rightscale_userdata.pyc'>) with frequency once-per-instance
2022-01-18 13:22:50,045 - handlers.py[DEBUG]: start: modules-final/config-rightscale_userdata: running config-rightscale_userdata with frequency once-per-instance
2022-01-18 13:22:50,045 - util.py[DEBUG]: Writing to /var/lib/cloud/instances/i-0c0853353402e1d0e/sem/config_rightscale_userdata - wb: [420] 20 bytes
2022-01-18 13:22:50,046 - util.py[DEBUG]: Restoring selinux mode for /var/lib/cloud/instances/i-0c0853353402e1d0e/sem/config_rightscale_userdata (recursive=False)
2022-01-18 13:22:50,047 - util.py[DEBUG]: Restoring selinux mode for /var/lib/cloud/instances/i-0c0853353402e1d0e/sem/config_rightscale_userdata (recursive=False)
2022-01-18 13:22:50,047 - helpers.py[DEBUG]: Running config-rightscale_userdata using lock (<FileLock using file '/var/lib/cloud/instances/i-0c0853353402e1d0e/sem/config_rightscale_userdata'>)
2022-01-18 13:22:50,047 - cc_rightscale_userdata.py[DEBUG]: Failed to get raw userdata in module rightscale_userdata
2022-01-18 13:22:50,048 - handlers.py[DEBUG]: finish: modules-final/config-rightscale_userdata: SUCCESS: config-rightscale_userdata ran successfully
2022-01-18 13:22:50,048 - stages.py[DEBUG]: Running module scripts-per-once (<module 'cloudinit.config.cc_scripts_per_once' from '/usr/lib/python2.7/site-packages/cloudinit/config/cc_scripts_per_once.pyc'>) with frequency once
2022-01-18 13:22:50,048 - handlers.py[DEBUG]: start: modules-final/config-scripts-per-once: running config-scripts-per-once with frequency once
2022-01-18 13:22:50,048 - util.py[DEBUG]: Writing to /var/lib/cloud/sem/config_scripts_per_once.once - wb: [420] 20 bytes
2022-01-18 13:22:50,049 - util.py[DEBUG]: Restoring selinux mode for /var/lib/cloud/sem/config_scripts_per_once.once (recursive=False)
2022-01-18 13:22:50,049 - util.py[DEBUG]: Restoring selinux mode for /var/lib/cloud/sem/config_scripts_per_once.once (recursive=False)
2022-01-18 13:22:50,050 - helpers.py[DEBUG]: Running config-scripts-per-once using lock (<FileLock using file '/var/lib/cloud/sem/config_scripts_per_once.once'>)
2022-01-18 13:22:50,050 - handlers.py[DEBUG]: finish: modules-final/config-scripts-per-once: SUCCESS: config-scripts-per-once ran successfully
2022-01-18 13:22:50,050 - stages.py[DEBUG]: Running module scripts-per-boot (<module 'cloudinit.config.cc_scripts_per_boot' from '/usr/lib/python2.7/site-packages/cloudinit/config/cc_scripts_per_boot.pyc'>) with frequency always
2022-01-18 13:22:50,050 - handlers.py[DEBUG]: start: modules-final/config-scripts-per-boot: running config-scripts-per-boot with frequency always
2022-01-18 13:22:50,050 - helpers.py[DEBUG]: Running config-scripts-per-boot using lock (<cloudinit.helpers.DummyLock object at 0x7fc49cd4e5d0>)
2022-01-18 13:22:50,051 - handlers.py[DEBUG]: finish: modules-final/config-scripts-per-boot: SUCCESS: config-scripts-per-boot ran successfully
2022-01-18 13:22:50,051 - stages.py[DEBUG]: Running module scripts-per-instance (<module 'cloudinit.config.cc_scripts_per_instance' from '/usr/lib/python2.7/site-packages/cloudinit/config/cc_scripts_per_instance.pyc'>) with frequency once-per-instance
2022-01-18 13:22:50,051 - handlers.py[DEBUG]: start: modules-final/config-scripts-per-instance: running config-scripts-per-instance with frequency once-per-instance
2022-01-18 13:22:50,051 - util.py[DEBUG]: Writing to /var/lib/cloud/instances/i-0c0853353402e1d0e/sem/config_scripts_per_instance - wb: [420] 20 bytes
2022-01-18 13:22:50,052 - util.py[DEBUG]: Restoring selinux mode for /var/lib/cloud/instances/i-0c0853353402e1d0e/sem/config_scripts_per_instance (recursive=False)
2022-01-18 13:22:50,052 - util.py[DEBUG]: Restoring selinux mode for /var/lib/cloud/instances/i-0c0853353402e1d0e/sem/config_scripts_per_instance (recursive=False)
2022-01-18 13:22:50,053 - helpers.py[DEBUG]: Running config-scripts-per-instance using lock (<FileLock using file '/var/lib/cloud/instances/i-0c0853353402e1d0e/sem/config_scripts_per_instance'>)
2022-01-18 13:22:50,053 - handlers.py[DEBUG]: finish: modules-final/config-scripts-per-instance: SUCCESS: config-scripts-per-instance ran successfully
2022-01-18 13:22:50,053 - stages.py[DEBUG]: Running module scripts-user (<module 'cloudinit.config.cc_scripts_user' from '/usr/lib/python2.7/site-packages/cloudinit/config/cc_scripts_user.pyc'>) with frequency once-per-instance
2022-01-18 13:22:50,053 - handlers.py[DEBUG]: start: modules-final/config-scripts-user: running config-scripts-user with frequency once-per-instance
2022-01-18 13:22:50,053 - util.py[DEBUG]: Writing to /var/lib/cloud/instances/i-0c0853353402e1d0e/sem/config_scripts_user - wb: [420] 20 bytes
2022-01-18 13:22:50,054 - util.py[DEBUG]: Restoring selinux mode for /var/lib/cloud/instances/i-0c0853353402e1d0e/sem/config_scripts_user (recursive=False)
2022-01-18 13:22:50,054 - util.py[DEBUG]: Restoring selinux mode for /var/lib/cloud/instances/i-0c0853353402e1d0e/sem/config_scripts_user (recursive=False)
2022-01-18 13:22:50,055 - helpers.py[DEBUG]: Running config-scripts-user using lock (<FileLock using file '/var/lib/cloud/instances/i-0c0853353402e1d0e/sem/config_scripts_user'>)
2022-01-18 13:22:50,055 - handlers.py[DEBUG]: finish: modules-final/config-scripts-user: SUCCESS: config-scripts-user ran successfully
2022-01-18 13:22:50,055 - stages.py[DEBUG]: Running module ssh-authkey-fingerprints (<module 'cloudinit.config.cc_ssh_authkey_fingerprints' from '/usr/lib/python2.7/site-packages/cloudinit/config/cc_ssh_authkey_fingerprints.pyc'>) with frequency once-per-instance
2022-01-18 13:22:50,055 - handlers.py[DEBUG]: start: modules-final/config-ssh-authkey-fingerprints: running config-ssh-authkey-fingerprints with frequency once-per-instance
2022-01-18 13:22:50,056 - util.py[DEBUG]: Writing to /var/lib/cloud/instances/i-0c0853353402e1d0e/sem/config_ssh_authkey_fingerprints - wb: [420] 20 bytes
2022-01-18 13:22:50,056 - util.py[DEBUG]: Restoring selinux mode for /var/lib/cloud/instances/i-0c0853353402e1d0e/sem/config_ssh_authkey_fingerprints (recursive=False)
2022-01-18 13:22:50,057 - util.py[DEBUG]: Restoring selinux mode for /var/lib/cloud/instances/i-0c0853353402e1d0e/sem/config_ssh_authkey_fingerprints (recursive=False)
2022-01-18 13:22:50,057 - helpers.py[DEBUG]: Running config-ssh-authkey-fingerprints using lock (<FileLock using file '/var/lib/cloud/instances/i-0c0853353402e1d0e/sem/config_ssh_authkey_fingerprints'>)
2022-01-18 13:22:50,058 - util.py[DEBUG]: Reading from /etc/ssh/sshd_config (quiet=False)
2022-01-18 13:22:50,058 - util.py[DEBUG]: Read 3905 bytes from /etc/ssh/sshd_config
2022-01-18 13:22:50,059 - util.py[DEBUG]: Restoring selinux mode for /home/centos/.ssh (recursive=True)
2022-01-18 13:22:50,059 - util.py[DEBUG]: Reading from /home/centos/.ssh/authorized_keys (quiet=False)
2022-01-18 13:22:50,060 - util.py[DEBUG]: Read 390 bytes from /home/centos/.ssh/authorized_keys
2022-01-18 13:22:50,087 - handlers.py[DEBUG]: finish: modules-final/config-ssh-authkey-fingerprints: SUCCESS: config-ssh-authkey-fingerprints ran successfully
2022-01-18 13:22:50,087 - stages.py[DEBUG]: Running module keys-to-console (<module 'cloudinit.config.cc_keys_to_console' from '/usr/lib/python2.7/site-packages/cloudinit/config/cc_keys_to_console.pyc'>) with frequency once-per-instance
2022-01-18 13:22:50,087 - handlers.py[DEBUG]: start: modules-final/config-keys-to-console: running config-keys-to-console with frequency once-per-instance
2022-01-18 13:22:50,088 - util.py[DEBUG]: Writing to /var/lib/cloud/instances/i-0c0853353402e1d0e/sem/config_keys_to_console - wb: [420] 20 bytes
2022-01-18 13:22:50,088 - util.py[DEBUG]: Restoring selinux mode for /var/lib/cloud/instances/i-0c0853353402e1d0e/sem/config_keys_to_console (recursive=False)
2022-01-18 13:22:50,089 - util.py[DEBUG]: Restoring selinux mode for /var/lib/cloud/instances/i-0c0853353402e1d0e/sem/config_keys_to_console (recursive=False)
2022-01-18 13:22:50,089 - helpers.py[DEBUG]: Running config-keys-to-console using lock (<FileLock using file '/var/lib/cloud/instances/i-0c0853353402e1d0e/sem/config_keys_to_console'>)
2022-01-18 13:22:50,090 - util.py[DEBUG]: Running command ['/usr/libexec/cloud-init/write-ssh-key-fingerprints', '', 'ssh-dss'] with allowed return codes [0] (shell=False, capture=True)
2022-01-18 13:22:50,160 - handlers.py[DEBUG]: finish: modules-final/config-keys-to-console: SUCCESS: config-keys-to-console ran successfully
2022-01-18 13:22:50,160 - stages.py[DEBUG]: Running module phone-home (<module 'cloudinit.config.cc_phone_home' from '/usr/lib/python2.7/site-packages/cloudinit/config/cc_phone_home.pyc'>) with frequency once-per-instance
2022-01-18 13:22:50,161 - handlers.py[DEBUG]: start: modules-final/config-phone-home: running config-phone-home with frequency once-per-instance
2022-01-18 13:22:50,161 - util.py[DEBUG]: Writing to /var/lib/cloud/instances/i-0c0853353402e1d0e/sem/config_phone_home - wb: [420] 20 bytes
2022-01-18 13:22:50,162 - util.py[DEBUG]: Restoring selinux mode for /var/lib/cloud/instances/i-0c0853353402e1d0e/sem/config_phone_home (recursive=False)
2022-01-18 13:22:50,163 - util.py[DEBUG]: Restoring selinux mode for /var/lib/cloud/instances/i-0c0853353402e1d0e/sem/config_phone_home (recursive=False)
2022-01-18 13:22:50,163 - helpers.py[DEBUG]: Running config-phone-home using lock (<FileLock using file '/var/lib/cloud/instances/i-0c0853353402e1d0e/sem/config_phone_home'>)
2022-01-18 13:22:50,163 - cc_phone_home.py[DEBUG]: Skipping module named phone-home, no 'phone_home' configuration found
2022-01-18 13:22:50,163 - handlers.py[DEBUG]: finish: modules-final/config-phone-home: SUCCESS: config-phone-home ran successfully
2022-01-18 13:22:50,163 - stages.py[DEBUG]: Running module final-message (<module 'cloudinit.config.cc_final_message' from '/usr/lib/python2.7/site-packages/cloudinit/config/cc_final_message.pyc'>) with frequency always
2022-01-18 13:22:50,164 - handlers.py[DEBUG]: start: modules-final/config-final-message: running config-final-message with frequency always
2022-01-18 13:22:50,164 - helpers.py[DEBUG]: Running config-final-message using lock (<cloudinit.helpers.DummyLock object at 0x7fc49cd55390>)
2022-01-18 13:22:50,164 - util.py[DEBUG]: Reading from /proc/uptime (quiet=False)
2022-01-18 13:22:50,164 - util.py[DEBUG]: Read 12 bytes from /proc/uptime
2022-01-18 13:22:50,169 - util.py[DEBUG]: Cloud-init v. 0.7.9 finished at Tue, 18 Jan 2022 13:22:50 +0000. Datasource DataSourceEc2.  Up 12.44 seconds
2022-01-18 13:22:50,169 - util.py[DEBUG]: Writing to /var/lib/cloud/instance/boot-finished - wb: [420] 51 bytes
2022-01-18 13:22:50,175 - util.py[DEBUG]: Restoring selinux mode for /var/lib/cloud/instances/i-0c0853353402e1d0e/boot-finished (recursive=False)
2022-01-18 13:22:50,176 - util.py[DEBUG]: Restoring selinux mode for /var/lib/cloud/instances/i-0c0853353402e1d0e/boot-finished (recursive=False)
2022-01-18 13:22:50,177 - handlers.py[DEBUG]: finish: modules-final/config-final-message: SUCCESS: config-final-message ran successfully
2022-01-18 13:22:50,177 - stages.py[DEBUG]: Running module power-state-change (<module 'cloudinit.config.cc_power_state_change' from '/usr/lib/python2.7/site-packages/cloudinit/config/cc_power_state_change.pyc'>) with frequency once-per-instance
2022-01-18 13:22:50,177 - handlers.py[DEBUG]: start: modules-final/config-power-state-change: running config-power-state-change with frequency once-per-instance
2022-01-18 13:22:50,177 - util.py[DEBUG]: Writing to /var/lib/cloud/instances/i-0c0853353402e1d0e/sem/config_power_state_change - wb: [420] 20 bytes
2022-01-18 13:22:50,178 - util.py[DEBUG]: Restoring selinux mode for /var/lib/cloud/instances/i-0c0853353402e1d0e/sem/config_power_state_change (recursive=False)
2022-01-18 13:22:50,178 - util.py[DEBUG]: Restoring selinux mode for /var/lib/cloud/instances/i-0c0853353402e1d0e/sem/config_power_state_change (recursive=False)
2022-01-18 13:22:50,179 - helpers.py[DEBUG]: Running config-power-state-change using lock (<FileLock using file '/var/lib/cloud/instances/i-0c0853353402e1d0e/sem/config_power_state_change'>)
2022-01-18 13:22:50,179 - cc_power_state_change.py[DEBUG]: no power_state provided. doing nothing
2022-01-18 13:22:50,179 - handlers.py[DEBUG]: finish: modules-final/config-power-state-change: SUCCESS: config-power-state-change ran successfully
2022-01-18 13:22:50,179 - main.py[DEBUG]: Ran 10 modules with 0 failures
2022-01-18 13:22:50,180 - util.py[DEBUG]: Creating symbolic link from '/run/cloud-init/result.json' => '../../var/lib/cloud/data/result.json'
2022-01-18 13:22:50,180 - util.py[DEBUG]: Reading from /proc/uptime (quiet=False)
2022-01-18 13:22:50,181 - util.py[DEBUG]: Read 12 bytes from /proc/uptime
2022-01-18 13:22:50,181 - util.py[DEBUG]: cloud-init mode 'modules' took 0.227 seconds (0.23)
2022-01-18 13:22:50,181 - handlers.py[DEBUG]: finish: modules-final: SUCCESS: running modules for final
